<mujoco model="assembly">
  <compiler angle="radian" meshdir="meshes/" />
  <asset>
    <mesh name="base_link" file="base_link.STL" />
    <mesh name="waist_yaw_Link" file="waist_yaw_Link.STL" />
    <mesh name="waist_pitch_Link" file="waist_pitch_Link.STL" />
    <mesh name="waist_roll_Link" file="waist_roll_Link.STL" />
    <mesh name="neck_Link" file="neck_Link.STL" />
    <mesh name="R_shoulder_pitch_Link" file="R_shoulder_pitch_Link.STL" />
    <mesh name="R_shoulder_roll_Link" file="R_shoulder_roll_Link.STL" />
    <mesh name="R_shoulder_yaw_Link" file="R_shoulder_yaw_Link.STL" />
    <mesh name="R_elbow_Link" file="R_elbow_Link.STL" />
    <mesh name="R_wrist_roll_Link" file="R_wrist_roll_Link.STL" />
    <mesh name="R_wrist_pitch_Link" file="R_wrist_pitch_Link.STL" />
    <mesh name="R_wrist_yaw_Link" file="R_wrist_yaw_Link.STL" />
    <mesh name="L_shoulder_pitch_Link" file="L_shoulder_pitch_Link.STL" />
    <mesh name="L_shoulder_roll_Link" file="L_shoulder_roll_Link.STL" />
    <mesh name="L_shoulder_yaw_Link" file="L_shoulder_yaw_Link.STL" />
    <mesh name="L_elbow_Link" file="L_elbow_Link.STL" />
    <mesh name="L_wrist_roll_Link" file="L_wrist_roll_Link.STL" />
    <mesh name="L_wrist_pitch_Link" file="L_wrist_pitch_Link.STL" />
    <mesh name="L_wrist_yaw_Link" file="L_wrist_yaw_Link.STL" />
    <mesh name="R_hip_pitch_Link" file="R_hip_pitch_Link.STL" />
    <mesh name="R_hip_roll_Link" file="R_hip_roll_Link.STL" />
    <mesh name="R_hip_yaw_Link" file="R_hip_yaw_Link.STL" />
    <mesh name="R_knee_Link" file="R_knee_Link.STL" />
    <mesh name="R_ankle_pitch_Link" file="R_ankle_pitch_Link.STL" />
    <mesh name="R_ankle_roll_Link" file="R_ankle_roll_Link.STL" />
    <mesh name="L_hip_pitch_Link" file="L_hip_pitch_Link.STL" />
    <mesh name="L_hip_roll_Link" file="L_hip_roll_Link.STL" />
    <mesh name="L_hip_yaw_Link" file="L_hip_yaw_Link.STL" />
    <mesh name="L_knee_Link" file="L_knee_Link.STL" />
    <mesh name="L_ankle_pitch_Link" file="L_ankle_pitch_Link.STL" />
    <mesh name="L_ankle_roll_Link" file="L_ankle_roll_Link.STL" />
    <mesh name="revo2_left_hand_left_base_link" file="revo2_left_hand/left_base_link.STL" />
    <mesh name="revo2_left_hand_left_base_visual_link" file="revo2_left_hand/left_base_visual_link.STL" />
    <mesh name="revo2_left_hand_left_thumb_metacarpal_link" file="revo2_left_hand/left_thumb_metacarpal_link.STL" />
    <mesh name="revo2_left_hand_left_thumb_proximal_link" file="revo2_left_hand/left_thumb_proximal_link.STL" />
    <mesh name="revo2_left_hand_left_thumb_proximal_visual_link" file="revo2_left_hand/left_thumb_proximal_visual_link.STL" />
    <mesh name="revo2_left_hand_left_thumb_distal_link" file="revo2_left_hand/left_thumb_distal_link.STL" />
    <mesh name="revo2_left_hand_left_thumb_touch_link" file="revo2_left_hand/left_thumb_touch_link.STL" />
    <mesh name="revo2_left_hand_left_index_proximal_link" file="revo2_left_hand/left_index_proximal_link.STL" />
    <mesh name="revo2_left_hand_left_index_distal_link" file="revo2_left_hand/left_index_distal_link.STL" />
    <mesh name="revo2_left_hand_left_index_touch_link" file="revo2_left_hand/left_index_touch_link.STL" />
    <mesh name="revo2_left_hand_left_middle_proximal_link" file="revo2_left_hand/left_middle_proximal_link.STL" />
    <mesh name="revo2_left_hand_left_middle_distal_link" file="revo2_left_hand/left_middle_distal_link.STL" />
    <mesh name="revo2_left_hand_left_middle_touch_link" file="revo2_left_hand/left_middle_touch_link.STL" />
    <mesh name="revo2_left_hand_left_ring_proximal_link" file="revo2_left_hand/left_ring_proximal_link.STL" />
    <mesh name="revo2_left_hand_left_ring_distal_link" file="revo2_left_hand/left_ring_distal_link.STL" />
    <mesh name="revo2_left_hand_left_ring_touch_link" file="revo2_left_hand/left_ring_touch_link.STL" />
    <mesh name="revo2_left_hand_left_pinky_proximal_link" file="revo2_left_hand/left_pinky_proximal_link.STL" />
    <mesh name="revo2_left_hand_left_pinky_distal_link" file="revo2_left_hand/left_pinky_distal_link.STL" />
    <mesh name="revo2_left_hand_left_pinky_touch_link" file="revo2_left_hand/left_pinky_touch_link.STL" />
    <mesh name="revo2_right_hand_right_base_link" file="revo2_right_hand/right_base_link.STL" />
    <mesh name="revo2_right_hand_right_base_visual_link" file="revo2_right_hand/right_base_visual_link.STL" />
    <mesh name="revo2_right_hand_right_thumb_metacarpal_link" file="revo2_right_hand/right_thumb_metacarpal_link.STL" />
    <mesh name="revo2_right_hand_right_thumb_proximal_visual_link" file="revo2_right_hand/right_thumb_proximal_visual_link.STL" />
    <mesh name="revo2_right_hand_right_thumb_proximal_link" file="revo2_right_hand/right_thumb_proximal_link.STL" />
    <mesh name="revo2_right_hand_right_thumb_distal_link" file="revo2_right_hand/right_thumb_distal_link.STL" />
    <mesh name="revo2_right_hand_right_thumb_touch_link" file="revo2_right_hand/right_thumb_touch_link.STL" />
    <mesh name="revo2_right_hand_right_index_proximal_link" file="revo2_right_hand/right_index_proximal_link.STL" />
    <mesh name="revo2_right_hand_right_index_distal_link" file="revo2_right_hand/right_index_distal_link.STL" />
    <mesh name="revo2_right_hand_right_index_touch_link" file="revo2_right_hand/right_index_touch_link.STL" />
    <mesh name="revo2_right_hand_right_middle_proximal_link" file="revo2_right_hand/right_middle_proximal_link.STL" />
    <mesh name="revo2_right_hand_right_middle_distal_link" file="revo2_right_hand/right_middle_distal_link.STL" />
    <mesh name="revo2_right_hand_right_middle_touch_link" file="revo2_right_hand/right_middle_touch_link.STL" />
    <mesh name="revo2_right_hand_right_ring_proximal_link" file="revo2_right_hand/right_ring_proximal_link.STL" />
    <mesh name="revo2_right_hand_right_ring_distal_link" file="revo2_right_hand/right_ring_distal_link.STL" />
    <mesh name="revo2_right_hand_right_ring_touch_link" file="revo2_right_hand/right_ring_touch_link.STL" />
    <mesh name="revo2_right_hand_right_pinky_proximal_link" file="revo2_right_hand/right_pinky_proximal_link.STL" />
    <mesh name="revo2_right_hand_right_pinky_distal_link" file="revo2_right_hand/right_pinky_distal_link.STL" />
    <mesh name="revo2_right_hand_right_pinky_touch_link" file="revo2_right_hand/right_pinky_touch_link.STL" />
    <material name="Z2_0_Lite_description_0429_1_mat" rgba="0.7922 0.8196 0.9294 1" specular="0" />
    <material name="Z2_0_Lite_description_0429_1_waist_yaw_Link_mat" rgba="0.7922 0.8196 0.9294 1" specular="0" />
    <material name="Z2_0_Lite_description_0429_1_waist_pitch_Link_mat" rgba="0.5882 0.5882 0.6275 1" specular="0" />
    <material name="Z2_0_Lite_description_0429_1_waist_roll_Link_mat" rgba="0.7922 0.8196 0.9294 1" specular="0" />
    <material name="Z2_0_Lite_description_0429_1_neck_Link_mat" rgba="0.7922 0.8196 0.9294 1" specular="0" />
    <material name="Z2_0_Lite_description_0429_1_R_shoulder_pitch_Link_mat" rgba="0.7922 0.8196 0.9294 1" specular="0" />
    <material name="Z2_0_Lite_description_0429_1_R_shoulder_roll_Link_mat" rgba="0.7922 0.8196 0.9294 1" specular="0" />
    <material name="Z2_0_Lite_description_0429_1_R_shoulder_yaw_Link_mat" rgba="0.7922 0.8196 0.9294 1" specular="0" />
    <material name="Z2_0_Lite_description_0429_1_R_elbow_Link_mat" rgba="0.7922 0.8196 0.9294 1" specular="0" />
    <material name="Z2_0_Lite_description_0429_1_R_wrist_roll_Link_mat" rgba="0.5882 0.5882 0.6275 1" specular="0" />
    <material name="Z2_0_Lite_description_0429_1_R_wrist_pitch_Link_mat" rgba="0.7922 0.8196 0.9294 1" specular="0" />
    <material name="Z2_0_Lite_description_0429_1_R_wrist_yaw_Link_mat" rgba="1 1 1 1" specular="0" />
    <material name="Z2_0_Lite_description_0429_1_L_shoulder_pitch_Link_mat" rgba="0.7922 0.8196 0.9294 1" specular="0" />
    <material name="Z2_0_Lite_description_0429_1_L_shoulder_roll_Link_mat" rgba="0.7922 0.8196 0.9294 1" specular="0" />
    <material name="Z2_0_Lite_description_0429_1_L_shoulder_yaw_Link_mat" rgba="0.7922 0.8196 0.9294 1" specular="0" />
    <material name="Z2_0_Lite_description_0429_1_L_elbow_Link_mat" rgba="0.7922 0.8196 0.9294 1" specular="0" />
    <material name="Z2_0_Lite_description_0429_1_L_wrist_roll_Link_mat" rgba="0.5882 0.5882 0.6275 1" specular="0" />
    <material name="Z2_0_Lite_description_0429_1_L_wrist_pitch_Link_mat" rgba="0.7922 0.8196 0.9294 1" specular="0" />
    <material name="Z2_0_Lite_description_0429_1_L_wrist_yaw_Link_mat" rgba="1 1 1 1" specular="0" />
    <material name="Z2_0_Lite_description_0429_1_R_hip_pitch_Link_mat" rgba="0.7922 0.8196 0.9294 1" specular="0" />
    <material name="Z2_0_Lite_description_0429_1_R_hip_roll_Link_mat" rgba="0.7922 0.8196 0.9294 1" specular="0" />
    <material name="Z2_0_Lite_description_0429_1_R_hip_yaw_Link_mat" rgba="0.7922 0.8196 0.9294 1" specular="0" />
    <material name="Z2_0_Lite_description_0429_1_R_knee_Link_mat" rgba="0.7922 0.8196 0.9294 1" specular="0" />
    <material name="Z2_0_Lite_description_0429_1_R_ankle_pitch_Link_mat" rgba="0.5882 0.5882 0.6275 1" specular="0" />
    <material name="Z2_0_Lite_description_0429_1_R_ankle_roll_Link_mat" rgba="0.7922 0.8196 0.9294 1" specular="0" />
    <material name="Z2_0_Lite_description_0429_1_L_hip_pitch_Link_mat" rgba="0.7922 0.8196 0.9294 1" specular="0" />
    <material name="Z2_0_Lite_description_0429_1_L_hip_roll_Link_mat" rgba="0.7922 0.8196 0.9294 1" specular="0" />
    <material name="Z2_0_Lite_description_0429_1_L_hip_yaw_Link_mat" rgba="0.7922 0.8196 0.9294 1" specular="0" />
    <material name="Z2_0_Lite_description_0429_1_L_knee_Link_mat" rgba="0.7922 0.8196 0.9294 1" specular="0" />
    <material name="Z2_0_Lite_description_0429_1_L_ankle_pitch_Link_mat" rgba="0.5882 0.5882 0.6275 1" specular="0" />
    <material name="Z2_0_Lite_description_0429_1_L_ankle_roll_Link_mat" rgba="0.7922 0.8196 0.9294 1" specular="0" />
    <material name="revo2_left_hand_mat" rgba="1 1 1 1" specular="0" />
    <material name="revo2_left_hand_mat_2" rgba="1 1 1 1" />
    <material name="revo2_left_hand_left_thumb_metacarpal_link_mat" rgba="1 1 1 1" specular="0" />
    <material name="revo2_left_hand_left_thumb_proximal_link_mat" rgba="1 1 1 1" specular="0" />
    <material name="revo2_left_hand_left_thumb_proximal_link_mat_2" rgba="1 1 1 1" />
    <material name="revo2_left_hand_left_thumb_distal_link_mat" rgba="1 1 1 1" specular="0" />
    <material name="revo2_left_hand_left_thumb_touch_link_mat" rgba="1 1 1 1" specular="0" />
    <material name="revo2_left_hand_left_index_proximal_link_mat" rgba="1 1 1 1" specular="0" />
    <material name="revo2_left_hand_left_index_distal_link_mat" rgba="1 1 1 1" specular="0" />
    <material name="revo2_left_hand_left_index_touch_link_mat" rgba="1 1 1 1" specular="0" />
    <material name="revo2_left_hand_left_middle_proximal_link_mat" rgba="1 1 1 1" specular="0" />
    <material name="revo2_left_hand_left_middle_distal_link_mat" rgba="1 1 1 1" specular="0" />
    <material name="revo2_left_hand_left_middle_touch_link_mat" rgba="1 1 1 1" specular="0" />
    <material name="revo2_left_hand_left_ring_proximal_link_mat" rgba="1 1 1 1" specular="0" />
    <material name="revo2_left_hand_left_ring_distal_link_mat" rgba="1 1 1 1" specular="0" />
    <material name="revo2_left_hand_left_ring_touch_link_mat" rgba="1 1 1 1" specular="0" />
    <material name="revo2_left_hand_left_pinky_proximal_link_mat" rgba="1 1 1 1" specular="0" />
    <material name="revo2_left_hand_left_pinky_distal_link_mat" rgba="1 1 1 1" specular="0" />
    <material name="revo2_left_hand_left_pinky_touch_link_mat" rgba="1 1 1 1" specular="0" />
    <material name="revo2_right_hand_mat" rgba="1 1 1 1" specular="0" />
    <material name="revo2_right_hand_mat_2" rgba="1 1 1 1" />
    <material name="revo2_right_hand_right_thumb_metacarpal_link_mat" rgba="1 1 1 1" specular="0" />
    <material name="revo2_right_hand_right_thumb_proximal_link_mat" rgba="1 1 1 1" specular="0" />
    <material name="revo2_right_hand_right_thumb_distal_link_mat" rgba="1 1 1 1" specular="0" />
    <material name="revo2_right_hand_right_thumb_touch_link_mat" rgba="1 1 1 1" specular="0" />
    <material name="revo2_right_hand_right_index_proximal_link_mat" rgba="1 1 1 1" specular="0" />
    <material name="revo2_right_hand_right_index_distal_link_mat" rgba="1 1 1 1" specular="0" />
    <material name="revo2_right_hand_right_index_touch_link_mat" rgba="1 1 1 1" specular="0" />
    <material name="revo2_right_hand_right_middle_proximal_link_mat" rgba="1 1 1 1" specular="0" />
    <material name="revo2_right_hand_right_middle_distal_link_mat" rgba="1 1 1 1" specular="0" />
    <material name="revo2_right_hand_right_middle_touch_link_mat" rgba="1 1 1 1" specular="0" />
    <material name="revo2_right_hand_right_ring_proximal_link_mat" rgba="1 1 1 1" specular="0" />
    <material name="revo2_right_hand_right_ring_distal_link_mat" rgba="1 1 1 1" specular="0" />
    <material name="revo2_right_hand_right_ring_touch_link_mat" rgba="1 1 1 1" specular="0" />
    <material name="revo2_right_hand_right_pinky_proximal_link_mat" rgba="1 1 1 1" specular="0" />
    <material name="revo2_right_hand_right_pinky_distal_link_mat" rgba="1 1 1 1" specular="0" />
    <material name="revo2_right_hand_right_pinky_touch_link_mat" rgba="1 1 1 1" specular="0" />
  </asset>

  <worldbody>
    <body name="Z2_0_Lite_description_0429_1" pos="0 0 0">
      <inertial pos="0.000026 0 0.015586" mass="3.6595" fullinertia="0.013371 0.010889 0.00862 0 -0.00000431 0"/>
      <geom pos="0 0 0" group="1" contype="0" conaffinity="0" material="Z2_0_Lite_description_0429_1_mat" type="mesh" mesh="base_link" />
      <geom pos="0 0 0" rgba="0.9373 0.2667 0.2667 1" group="3" contype="1" conaffinity="1" type="mesh" mesh="base_link" />
      <body name="Z2_0_Lite_description_0429_1_waist_yaw_Link" pos="0 0 0.0995">
        <joint name="Z2_0_Lite_description_0429_1_waist_yaw_joint" type="hinge" axis="0 0 1" limited="true" range="-3.14 3.14" damping="0" frictionloss="0"/>
        <inertial pos="0.0000986 0 0.010913" mass="0.19414" fullinertia="0.0001308 0.00011203 0.000183 0 -0.00000252 0"/>
        <geom pos="0 0 0" group="1" contype="0" conaffinity="0" material="Z2_0_Lite_description_0429_1_waist_yaw_Link_mat" type="mesh" mesh="waist_yaw_Link" />
        <geom pos="0 0 0" rgba="0.9373 0.2667 0.2667 1" group="3" contype="1" conaffinity="1" type="mesh" mesh="waist_yaw_Link" />
        <body name="Z2_0_Lite_description_0429_1_waist_pitch_Link" pos="0 0 0.0325">
          <joint name="Z2_0_Lite_description_0429_1_waist_pitch_joint" type="hinge" axis="0 1 0" limited="true" range="-0.26 0.43" damping="0" frictionloss="0"/>
          <inertial pos="0 0 0" mass="0.084721" diaginertia="0.00001554 0.00000872 0.00002237"/>
          <geom pos="0 0 0" group="1" contype="0" conaffinity="0" material="Z2_0_Lite_description_0429_1_waist_pitch_Link_mat" type="mesh" mesh="waist_pitch_Link" />
          <geom pos="0 0 0" rgba="0.9373 0.2667 0.2667 1" group="3" contype="1" conaffinity="1" type="mesh" mesh="waist_pitch_Link" />
          <body name="Z2_0_Lite_description_0429_1_waist_roll_Link" pos="0 0 0">
            <joint name="Z2_0_Lite_description_0429_1_waist_roll_joint" type="hinge" axis="1 0 0" limited="true" range="-0.52 0.52" damping="0" frictionloss="0"/>
            <inertial pos="0.00440484 -0.00006599 0.15286233" mass="11.22951" fullinertia="0.09031602 0.06346741 0.05915892 0.00000483 -0.00142947 0.00002369"/>
            <geom pos="0 0 0" group="1" contype="0" conaffinity="0" material="Z2_0_Lite_description_0429_1_waist_roll_Link_mat" type="mesh" mesh="waist_roll_Link" />
            <geom pos="0 0 0" rgba="0.9373 0.2667 0.2667 1" group="3" contype="1" conaffinity="1" type="mesh" mesh="waist_roll_Link" />
            <body name="Z2_0_Lite_description_0429_1_neck_Link" pos="0 0 0.329">
              <inertial pos="0.00361611 -0.00038273 0.06378993" mass="1.0284" fullinertia="0.00367063 0.00366270 0.00241872 0.00000140 0.00012567 0.00000084"/>
              <geom pos="0 0 0" group="1" contype="0" conaffinity="0" material="Z2_0_Lite_description_0429_1_neck_Link_mat" type="mesh" mesh="neck_Link" />
              <geom pos="0 0 0" rgba="0.9373 0.2667 0.2667 1" group="3" contype="1" conaffinity="1" type="mesh" mesh="neck_Link" />
            </body>
            <body name="Z2_0_Lite_description_0429_1_R_shoulder_pitch_Link" pos="0 -0.12262 0.22437" quat="0.9914448 -0.1305265 0 0">
              <joint name="Z2_0_Lite_description_0429_1_R_shoulder_pitch_joint" type="hinge" axis="0 1 0" limited="true" range="-3.14 3.14" damping="0" frictionloss="0"/>
              <inertial pos="0.0030433 -0.046415 -0.0078645" mass="0.61036" fullinertia="0.00048531 0.00040974 0.0004792 -0.00001031 -0.00000545 0.0000315"/>
              <geom pos="0 0 0" group="1" contype="0" conaffinity="0" material="Z2_0_Lite_description_0429_1_R_shoulder_pitch_Link_mat" type="mesh" mesh="R_shoulder_pitch_Link" />
              <geom pos="0 0 0" rgba="0.9373 0.2667 0.2667 1" group="3" contype="1" conaffinity="1" type="mesh" mesh="R_shoulder_pitch_Link" />
              <body name="Z2_0_Lite_description_0429_1_R_shoulder_roll_Link" pos="0 -0.052 -0.01" quat="0.9914448 0.1305265 0 0">
                <joint name="Z2_0_Lite_description_0429_1_R_shoulder_roll_joint" type="hinge" axis="1 0 0" limited="true" range="-2.09 0.26" damping="0" frictionloss="0"/>
                <inertial pos="0.0003492 -0.0028489 -0.038097" mass="0.22592" fullinertia="0.000288 0.00038122 0.0002448 0.00000022 -0.00000024 -0.00000063"/>
                <geom pos="0 0 0" group="1" contype="0" conaffinity="0" material="Z2_0_Lite_description_0429_1_R_shoulder_roll_Link_mat" type="mesh" mesh="R_shoulder_roll_Link" />
                <geom pos="0 0 0" rgba="0.9373 0.2667 0.2667 1" group="3" contype="1" conaffinity="1" type="mesh" mesh="R_shoulder_roll_Link" />
                <body name="Z2_0_Lite_description_0429_1_R_shoulder_yaw_Link" pos="0 0 -0.075">
                  <joint name="Z2_0_Lite_description_0429_1_R_shoulder_yaw_joint" type="hinge" axis="0 0 1" limited="true" range="-3.14 3.14" damping="0" frictionloss="0"/>
                  <inertial pos="0.0046034 -0.000625 -0.075726" mass="1.0841" fullinertia="0.0029008 0.0029286 0.00063068 -0.00000355 -0.00024388 0.00003169"/>
                  <geom pos="0 0 0" group="1" contype="0" conaffinity="0" material="Z2_0_Lite_description_0429_1_R_shoulder_yaw_Link_mat" type="mesh" mesh="R_shoulder_yaw_Link" />
                  <geom pos="0 0 0" rgba="0.9373 0.2667 0.2667 1" group="3" contype="1" conaffinity="1" type="mesh" mesh="R_shoulder_yaw_Link" />
                  <body name="Z2_0_Lite_description_0429_1_R_elbow_Link" pos="0.01 0 -0.123">
                    <joint name="Z2_0_Lite_description_0429_1_R_elbow_joint" type="hinge" axis="0 1 0" limited="true" range="-0.52 3.14" damping="0" frictionloss="0"/>
                    <inertial pos="0.063477 -0.0003999 0" mass="0.61836" fullinertia="0.00040537 0.0005948 0.00066201 0.00001576 0 0"/>
                    <geom pos="0 0 0" group="1" contype="0" conaffinity="0" material="Z2_0_Lite_description_0429_1_R_elbow_Link_mat" type="mesh" mesh="R_elbow_Link" />
                    <geom pos="0 0 0" rgba="0.9373 0.2667 0.2667 1" group="3" contype="1" conaffinity="1" type="mesh" mesh="R_elbow_Link" />
                    <body name="Z2_0_Lite_description_0429_1_R_wrist_roll_Link" pos="0.1 0 0">
                      <joint name="Z2_0_Lite_description_0429_1_R_wrist_roll_joint" type="hinge" axis="1 0 0" limited="true" range="-3.14 3.14" damping="0" frictionloss="0"/>
                      <inertial pos="0.015815 0.0015672 0" mass="0.07414" fullinertia="0.00005579 0.00003213 0.00005756 0.00000181 0 0"/>
                      <geom pos="0 0 0" group="1" contype="0" conaffinity="0" material="Z2_0_Lite_description_0429_1_R_wrist_roll_Link_mat" type="mesh" mesh="R_wrist_roll_Link" />
                      <geom pos="0 0 0" rgba="0.9373 0.2667 0.2667 1" group="3" contype="1" conaffinity="1" type="mesh" mesh="R_wrist_roll_Link" />
                      <body name="Z2_0_Lite_description_0429_1_R_wrist_pitch_Link" pos="0.035 0 0">
                        <joint name="Z2_0_Lite_description_0429_1_R_wrist_pitch_joint" type="hinge" axis="0 1 0" limited="true" range="-1.57 1.57" damping="0" frictionloss="0"/>
                        <inertial pos="0.023091 0.0008013 0.0007039" mass="0.47133" fullinertia="0.00018371 0.00041747 0.00041663 -0.00000867 0.00000757 -0.00000027"/>
                        <geom pos="0 0 0" group="1" contype="0" conaffinity="0" material="Z2_0_Lite_description_0429_1_R_wrist_pitch_Link_mat" type="mesh" mesh="R_wrist_pitch_Link" />
                        <geom pos="0 0 0" rgba="0.9373 0.2667 0.2667 1" group="3" contype="1" conaffinity="1" type="mesh" mesh="R_wrist_pitch_Link" />
                        <body name="Z2_0_Lite_description_0429_1_R_wrist_yaw_Link" pos="0.046 0 0">
                          <joint name="Z2_0_Lite_description_0429_1_R_wrist_yaw_joint" type="hinge" axis="0 0 1" limited="true" range="-1.57 1.57" damping="0" frictionloss="0"/>
                          <inertial pos="0.018433 0 -0.0005558" mass="0.05797" fullinertia="0.00004276 0.00004912 0.00002257 0 -0.00000005 0"/>
                          <geom pos="0 0 0" group="1" contype="0" conaffinity="0" material="Z2_0_Lite_description_0429_1_R_wrist_yaw_Link_mat" type="mesh" mesh="R_wrist_yaw_Link" />
                          <geom pos="0 0 0" rgba="0.9373 0.2667 0.2667 1" group="3" contype="1" conaffinity="1" type="mesh" mesh="R_wrist_yaw_Link" />
                          <body name="revo2_right_hand" pos="0.045 0 0" quat="0.5 0.5 0.5 0.5">
                            <inertial pos="-0.0052438 -0.0034038 0.0521267" mass="0.238" fullinertia="0.0000210912 0.0000144622 0.0000079981 0.0000000386 0.0000000936 -0.0000010958"/>
                            <geom pos="0 0 0" group="1" contype="0" conaffinity="0" material="revo2_right_hand_mat" type="mesh" mesh="revo2_right_hand_right_base_link" />
                            <geom pos="0 0 0" group="1" contype="0" conaffinity="0" material="revo2_right_hand_mat_2" type="mesh" mesh="revo2_right_hand_right_base_visual_link" />
                            <geom pos="0 0 0" rgba="0.9373 0.2667 0.2667 1" group="3" contype="1" conaffinity="1" type="mesh" mesh="revo2_right_hand_right_base_link" />
                            <body name="revo2_right_hand_right_thumb_metacarpal_link" pos="0.005619 0.019867 0.027825" quat="0.9964795 0 0 -0.0838365">
                              <joint name="revo2_right_hand_right_thumb_metacarpal_joint" type="hinge" axis="0 0 -1" limited="true" range="0 1.57" damping="0" frictionloss="0"/>
                              <inertial pos="0.0000151 0.0070724 -0.0042085" mass="0.01" fullinertia="0.0000001592 0.0000001609 0.0000000514 -0.0000000047 0.0000000005 -0.0000000148"/>
                              <geom pos="0 0 0" group="1" contype="0" conaffinity="0" material="revo2_right_hand_right_thumb_metacarpal_link_mat" type="mesh" mesh="revo2_right_hand_right_thumb_metacarpal_link" />
                              <geom pos="0 0 0" rgba="0.9373 0.2667 0.2667 1" group="3" contype="1" conaffinity="1" type="mesh" mesh="revo2_right_hand_right_thumb_metacarpal_link" />
                              <body name="revo2_right_hand_right_thumb_proximal_link" pos="0 0.014227 0" quat="0.9865567 0.0765206 0.1248038 0.0726253">
                                <joint name="revo2_right_hand_right_thumb_proximal_joint" type="hinge" axis="1 0 0" limited="true" range="0 1.03" damping="0" frictionloss="0"/>
                                <inertial pos="-0.0000005 0.0277015 -0.0020266" mass="0.05" fullinertia="0.0000024045 0.0000005123 0.0000025625 -0.0000000001 0 -0.0000000289"/>
                                <geom pos="0 0 0" group="1" contype="0" conaffinity="0" material="revo2_right_hand_right_thumb_proximal_link_mat" type="mesh" mesh="revo2_right_hand_right_thumb_proximal_visual_link" />
                                <geom pos="0 0 0" rgba="0.9373 0.2667 0.2667 1" group="3" contype="1" conaffinity="1" type="mesh" mesh="revo2_right_hand_right_thumb_proximal_link" />
                                <body name="revo2_right_hand_right_thumb_distal_link" pos="0 0.052 0">
                                  <joint name="revo2_right_hand_right_thumb_distal_joint" type="hinge" axis="1 0 0" limited="true" range="0 1.03" damping="0" frictionloss="0"/>
                                  <inertial pos="0 0.0117545 0.0000113" mass="0.01" fullinertia="0.0000001678 0.0000001154 0.0000002196 0 0 0.0000000125"/>
                                  <geom pos="0 0 0" group="1" contype="0" conaffinity="0" material="revo2_right_hand_right_thumb_distal_link_mat" type="mesh" mesh="revo2_right_hand_right_thumb_distal_link" />
                                  <geom pos="0 0 0" rgba="0.9373 0.2667 0.2667 1" group="3" contype="1" conaffinity="1" type="mesh" mesh="revo2_right_hand_right_thumb_distal_link" />
                                  <body name="revo2_right_hand_right_thumb_tip_link" pos="0 0.0265288 -0.0017734" quat="0.9994431 -0.033369 0 0">
                                  </body>
                                  <body name="revo2_right_hand_right_thumb_touch_link" pos="0 0.0137928 0.0076766" quat="0.9994431 -0.033369 0 0">
                                    <inertial pos="0 -0.0015225 -0.0077842" mass="0.002" fullinertia="0.0000001678 0.0000001142 0.0000002208 0 0 0.0000000055"/>
                                    <geom pos="0 0 0" group="1" contype="0" conaffinity="0" material="revo2_right_hand_right_thumb_touch_link_mat" type="mesh" mesh="revo2_right_hand_right_thumb_touch_link" />
                                    <geom pos="0 0 0" rgba="0.9373 0.2667 0.2667 1" group="3" contype="1" conaffinity="1" type="mesh" mesh="revo2_right_hand_right_thumb_touch_link" />
                                  </body>
                                </body>
                              </body>
                            </body>
                            <body name="revo2_right_hand_right_index_proximal_link" pos="-0.0021181 0.029568 0.080876" quat="0.9921471 -0.0522807 0.0783652 -0.0822789">
                              <joint name="revo2_right_hand_right_index_proximal_joint" type="hinge" axis="0 1 0" limited="true" range="0 1.41" damping="0" frictionloss="0"/>
                              <inertial pos="-0.002235 0.0000032 0.0176402" mass="0.009" fullinertia="0.0000002519 0.0000002364 0.000000093 0 -0.0000000064 0.0000000002"/>
                              <geom pos="0 0 0" group="1" contype="0" conaffinity="0" material="revo2_right_hand_right_index_proximal_link_mat" type="mesh" mesh="revo2_right_hand_right_index_proximal_link" />
                              <geom pos="0 0 0" rgba="0.9373 0.2667 0.2667 1" group="3" contype="1" conaffinity="1" type="mesh" mesh="revo2_right_hand_right_index_proximal_link" />
                              <body name="revo2_right_hand_right_index_distal_link" pos="0 0 0.032">
                                <joint name="revo2_right_hand_right_index_distal_joint" type="hinge" axis="0 1 0" limited="true" range="0 1.63" damping="0" frictionloss="0"/>
                                <inertial pos="0.0033017 0.0000002 0.0142077" mass="0.009" fullinertia="0.00000034 0.0000003622 0.000000091 0 -0.0000000875 0"/>
                                <geom pos="0 0 0" group="1" contype="0" conaffinity="0" material="revo2_right_hand_right_index_distal_link_mat" type="mesh" mesh="revo2_right_hand_right_index_distal_link" />
                                <geom pos="0 0 0" rgba="0.9373 0.2667 0.2667 1" group="3" contype="1" conaffinity="1" type="mesh" mesh="revo2_right_hand_right_index_distal_link" />
                                <body name="revo2_right_hand_right_index_tip_link" pos="0.011097 0 0.035739" quat="0.9718586 0 0.2355651 0">
                                </body>
                                <body name="revo2_right_hand_right_index_touch_link" pos="0.014497 0 0.023303" quat="0.6361 0.7347693 0.1541819 -0.1780979">
                                  <inertial pos="-0.0029991 0.0024974 -0.0003615" mass="0.002" fullinertia="0.0000000068 0.0000000032 0.0000000054 0.0000000015 -0.0000000002 0.0000000003"/>
                                  <geom pos="0 0 0" group="1" contype="0" conaffinity="0" material="revo2_right_hand_right_index_touch_link_mat" type="mesh" mesh="revo2_right_hand_right_index_touch_link" />
                                  <geom pos="0 0 0" rgba="0.9373 0.2667 0.2667 1" group="3" contype="1" conaffinity="1" type="mesh" mesh="revo2_right_hand_right_index_touch_link" />
                                </body>
                              </body>
                            </body>
                            <body name="revo2_right_hand_right_middle_proximal_link" pos="-0.0045767 0.010051 0.084993" quat="0.9966815 -0.0175235 0.0746069 -0.0274369">
                              <joint name="revo2_right_hand_right_middle_proximal_joint" type="hinge" axis="0 1 0" limited="true" range="0 1.41" damping="0" frictionloss="0"/>
                              <inertial pos="-0.0022251 0.0000053 0.0203008" mass="0.009" fullinertia="0.000000367 0.0000003526 0.0000001122 0 -0.0000000098 0.0000000003"/>
                              <geom pos="0 0 0" group="1" contype="0" conaffinity="0" material="revo2_right_hand_right_middle_proximal_link_mat" type="mesh" mesh="revo2_right_hand_right_middle_proximal_link" />
                              <geom pos="0 0 0" rgba="0.9373 0.2667 0.2667 1" group="3" contype="1" conaffinity="1" type="mesh" mesh="revo2_right_hand_right_middle_proximal_link" />
                              <body name="revo2_right_hand_right_middle_distal_link" pos="0 0 0.037">
                                <joint name="revo2_right_hand_right_middle_distal_joint" type="hinge" axis="0 1 0" limited="true" range="0 1.63" damping="0" frictionloss="0"/>
                                <inertial pos="0.0040082 0 0.0164974" mass="0.009" fullinertia="0.0000005126 0.0000005498 0.0000001236 0 -0.0000001366 0"/>
                                <geom pos="0 0 0" group="1" contype="0" conaffinity="0" material="revo2_right_hand_right_middle_distal_link_mat" type="mesh" mesh="revo2_right_hand_right_middle_distal_link" />
                                <geom pos="0 0 0" rgba="0.9373 0.2667 0.2667 1" group="3" contype="1" conaffinity="1" type="mesh" mesh="revo2_right_hand_right_middle_distal_link" />
                                <body name="revo2_right_hand_right_middle_tip_link" pos="0.012558 0 0.040442" quat="0.9718586 0 0.2355651 0">
                                </body>
                                <body name="revo2_right_hand_right_middle_touch_link" pos="0.0159759 0 0.0265894" quat="0.9718583 0 0.2355662 0">
                                  <inertial pos="-0.0031929 0 0.0029786" mass="0.002" fullinertia="0.00000001 0.0000000082 0.0000000044 0 0.0000000023 0"/>
                                  <geom pos="0 0 0" group="1" contype="0" conaffinity="0" material="revo2_right_hand_right_middle_touch_link_mat" type="mesh" mesh="revo2_right_hand_right_middle_touch_link" />
                                  <geom pos="0 0 0" rgba="0.9373 0.2667 0.2667 1" group="3" contype="1" conaffinity="1" type="mesh" mesh="revo2_right_hand_right_middle_touch_link" />
                                </body>
                              </body>
                            </body>
                            <body name="revo2_right_hand_right_ring_proximal_link" pos="-0.0046709 -0.010037 0.083982" quat="0.996722 0.0175386 0.0740633 0.0274276">
                              <joint name="revo2_right_hand_right_ring_proximal_joint" type="hinge" axis="0 1 0" limited="true" range="0 1.41" damping="0" frictionloss="0"/>
                              <inertial pos="-0.0023449 0.0000059 0.0191774" mass="0.009" fullinertia="0.0000003142 0.0000002976 0.0000001021 0 -0.0000000078 0.0000000002"/>
                              <geom pos="0 0 0" group="1" contype="0" conaffinity="0" material="revo2_right_hand_right_ring_proximal_link_mat" type="mesh" mesh="revo2_right_hand_right_ring_proximal_link" />
                              <geom pos="0 0 0" rgba="0.9373 0.2667 0.2667 1" group="3" contype="1" conaffinity="1" type="mesh" mesh="revo2_right_hand_right_ring_proximal_link" />
                              <body name="revo2_right_hand_right_ring_distal_link" pos="0 0 0.035">
                                <joint name="revo2_right_hand_right_ring_distal_joint" type="hinge" axis="0 1 0" limited="true" range="0 1.63" damping="0" frictionloss="0"/>
                                <inertial pos="0.0038246 0.0000001 0.0160344" mass="0.009" fullinertia="0.0000004718 0.0000005061 0.0000001158 0 -0.0000001269 0"/>
                                <geom pos="0 0 0" group="1" contype="0" conaffinity="0" material="revo2_right_hand_right_ring_distal_link_mat" type="mesh" mesh="revo2_right_hand_right_ring_distal_link" />
                                <geom pos="0 0 0" rgba="0.9373 0.2667 0.2667 1" group="3" contype="1" conaffinity="1" type="mesh" mesh="revo2_right_hand_right_ring_distal_link" />
                                <body name="revo2_right_hand_right_ring_tip_link" pos="0.012266 0 0.039501" quat="0.9718586 0 0.2355651 0">
                                </body>
                                <body name="revo2_right_hand_right_ring_touch_link" pos="0.0154392 0 0.0260561" quat="0.9718583 0 0.2355662 0">
                                  <inertial pos="-0.0030235 0 0.0030408" mass="0.002" fullinertia="0.0000000082 0.0000000066 0.0000000036 0 0.0000000018 0"/>
                                  <geom pos="0 0 0" group="1" contype="0" conaffinity="0" material="revo2_right_hand_right_ring_touch_link_mat" type="mesh" mesh="revo2_right_hand_right_ring_touch_link" />
                                  <geom pos="0 0 0" rgba="0.9373 0.2667 0.2667 1" group="3" contype="1" conaffinity="1" type="mesh" mesh="revo2_right_hand_right_ring_touch_link" />
                                </body>
                              </body>
                            </body>
                            <body name="revo2_right_hand_right_pinky_proximal_link" pos="-0.0023566 -0.029366 0.078694" quat="0.9922455 0.052387 0.0771065 0.0822136">
                              <joint name="revo2_right_hand_right_pinky_proximal_joint" type="hinge" axis="0 1 0" limited="true" range="0 1.41" damping="0" frictionloss="0"/>
                              <inertial pos="-0.0021321 0.0000078 0.0160672" mass="0.009" fullinertia="0.0000001976 0.000000182 0.0000000822 0 -0.0000000046 0.0000000001"/>
                              <geom pos="0 0 0" group="1" contype="0" conaffinity="0" material="revo2_right_hand_right_pinky_proximal_link_mat" type="mesh" mesh="revo2_right_hand_right_pinky_proximal_link" />
                              <geom pos="0 0 0" rgba="0.9373 0.2667 0.2667 1" group="3" contype="1" conaffinity="1" type="mesh" mesh="revo2_right_hand_right_pinky_proximal_link" />
                              <body name="revo2_right_hand_right_pinky_distal_link" pos="0 0 0.029">
                                <joint name="revo2_right_hand_right_pinky_distal_joint" type="hinge" axis="0 1 0" limited="true" range="0 1.63" damping="0" frictionloss="0"/>
                                <inertial pos="0.0030797 -0.0000002 0.0130247" mass="0.009" fullinertia="0.0000002701 0.0000002853 0.0000000791 0 -0.0000000671 0"/>
                                <geom pos="0 0 0" group="1" contype="0" conaffinity="0" material="revo2_right_hand_right_pinky_distal_link_mat" type="mesh" mesh="revo2_right_hand_right_pinky_distal_link" />
                                <geom pos="0 0 0" rgba="0.9373 0.2667 0.2667 1" group="3" contype="1" conaffinity="1" type="mesh" mesh="revo2_right_hand_right_pinky_distal_link" />
                                <body name="revo2_right_hand_right_pinky_tip_link" pos="0.010221 0 0.032918" quat="0.9718586 0 0.2355651 0">
                                </body>
                                <body name="revo2_right_hand_right_pinky_touch_link" pos="0.01401 0 0.021124" quat="0.9718586 0 0.2355651 0">
                                  <inertial pos="-0.0028914 -0.0000002 0.0016539" mass="0.002" fullinertia="0.0000000069 0.0000000053 0.0000000033 0 0.0000000014 0"/>
                                  <geom pos="0 0 0" group="1" contype="0" conaffinity="0" material="revo2_right_hand_right_pinky_touch_link_mat" type="mesh" mesh="revo2_right_hand_right_pinky_touch_link" />
                                  <geom pos="0 0 0" rgba="0.9373 0.2667 0.2667 1" group="3" contype="1" conaffinity="1" type="mesh" mesh="revo2_right_hand_right_pinky_touch_link" />
                                </body>
                              </body>
                            </body>
                          </body>
                        </body>
                      </body>
                    </body>
                  </body>
                </body>
              </body>
            </body>
            <body name="Z2_0_Lite_description_0429_1_L_shoulder_pitch_Link" pos="0 0.12262 0.22437" quat="0.9914448 0.1305265 0 0">
              <joint name="Z2_0_Lite_description_0429_1_L_shoulder_pitch_joint" type="hinge" axis="0 1 0" limited="true" range="-3.14 3.14" damping="0" frictionloss="0"/>
              <inertial pos="0.0030433 0.046415 -0.0078645" mass="0.61036" fullinertia="0.00048532 0.00040975 0.0004792 0.00001031 -0.00000545 -0.0000315"/>
              <geom pos="0 0 0" group="1" contype="0" conaffinity="0" material="Z2_0_Lite_description_0429_1_L_shoulder_pitch_Link_mat" type="mesh" mesh="L_shoulder_pitch_Link" />
              <geom pos="0 0 0" rgba="0.9373 0.2667 0.2667 1" group="3" contype="1" conaffinity="1" type="mesh" mesh="L_shoulder_pitch_Link" />
              <body name="Z2_0_Lite_description_0429_1_L_shoulder_roll_Link" pos="0 0.052 -0.01" quat="0.9914448 -0.1305265 0 0">
                <joint name="Z2_0_Lite_description_0429_1_L_shoulder_roll_joint" type="hinge" axis="1 0 0" limited="true" range="-0.26 2.09" damping="0" frictionloss="0"/>
                <inertial pos="0.0003486 0.0028486 -0.038097" mass="0.22592" fullinertia="0.000288 0.00038122 0.0002448 -0.00000023 -0.00000024 0.00000063"/>
                <geom pos="0 0 0" group="1" contype="0" conaffinity="0" material="Z2_0_Lite_description_0429_1_L_shoulder_roll_Link_mat" type="mesh" mesh="L_shoulder_roll_Link" />
                <geom pos="0 0 0" rgba="0.9373 0.2667 0.2667 1" group="3" contype="1" conaffinity="1" type="mesh" mesh="L_shoulder_roll_Link" />
                <body name="Z2_0_Lite_description_0429_1_L_shoulder_yaw_Link" pos="0 0 -0.075">
                  <joint name="Z2_0_Lite_description_0429_1_L_shoulder_yaw_joint" type="hinge" axis="0 0 1" limited="true" range="-3.14 3.14" damping="0" frictionloss="0"/>
                  <inertial pos="0.0045614 0.0005825 -0.075662" mass="1.08409" fullinertia="0.0029011 0.0029291 0.00062926 0.00000235 -0.00024236 -0.0000298"/>
                  <geom pos="0 0 0" group="1" contype="0" conaffinity="0" material="Z2_0_Lite_description_0429_1_L_shoulder_yaw_Link_mat" type="mesh" mesh="L_shoulder_yaw_Link" />
                  <geom pos="0 0 0" rgba="0.9373 0.2667 0.2667 1" group="3" contype="1" conaffinity="1" type="mesh" mesh="L_shoulder_yaw_Link" />
                  <body name="Z2_0_Lite_description_0429_1_L_elbow_Link" pos="0.01 0 -0.123">
                    <joint name="Z2_0_Lite_description_0429_1_L_elbow_joint" type="hinge" axis="0 1 0" limited="true" range="-0.52 3.14" damping="0" frictionloss="0"/>
                    <inertial pos="0.063477 0.0003999 0" mass="0.61836" fullinertia="0.00040537 0.0005948 0.00066201 -0.00001576 0 0"/>
                    <geom pos="0 0 0" group="1" contype="0" conaffinity="0" material="Z2_0_Lite_description_0429_1_L_elbow_Link_mat" type="mesh" mesh="L_elbow_Link" />
                    <geom pos="0 0 0" rgba="0.9373 0.2667 0.2667 1" group="3" contype="1" conaffinity="1" type="mesh" mesh="L_elbow_Link" />
                    <body name="Z2_0_Lite_description_0429_1_L_wrist_roll_Link" pos="0.1 0 0">
                      <joint name="Z2_0_Lite_description_0429_1_L_wrist_roll_joint" type="hinge" axis="1 0 0" limited="true" range="-3.14 3.14" damping="0" frictionloss="0"/>
                      <inertial pos="0.015815 -0.0015672 0" mass="0.07414" fullinertia="0.00005579 0.00003213 0.00005756 -0.00000181 0 0"/>
                      <geom pos="0 0 0" group="1" contype="0" conaffinity="0" material="Z2_0_Lite_description_0429_1_L_wrist_roll_Link_mat" type="mesh" mesh="L_wrist_roll_Link" />
                      <geom pos="0 0 0" rgba="0.9373 0.2667 0.2667 1" group="3" contype="1" conaffinity="1" type="mesh" mesh="L_wrist_roll_Link" />
                      <body name="Z2_0_Lite_description_0429_1_L_wrist_pitch_Link" pos="0.035 0 0">
                        <joint name="Z2_0_Lite_description_0429_1_L_wrist_pitch_joint" type="hinge" axis="0 1 0" limited="true" range="-1.57 1.57" damping="0" frictionloss="0"/>
                        <inertial pos="0.023083 -0.0007916 0.0007035" mass="0.47133" fullinertia="0.00018383 0.00041747 0.00041664 0.00000858 0.00000757 0.00000026"/>
                        <geom pos="0 0 0" group="1" contype="0" conaffinity="0" material="Z2_0_Lite_description_0429_1_L_wrist_pitch_Link_mat" type="mesh" mesh="L_wrist_pitch_Link" />
                        <geom pos="0 0 0" rgba="0.9373 0.2667 0.2667 1" group="3" contype="1" conaffinity="1" type="mesh" mesh="L_wrist_pitch_Link" />
                        <body name="Z2_0_Lite_description_0429_1_L_wrist_yaw_Link" pos="0.046 0 0">
                          <joint name="Z2_0_Lite_description_0429_1_L_wrist_yaw_joint" type="hinge" axis="0 0 1" limited="true" range="-1.57 1.57" damping="0" frictionloss="0"/>
                          <inertial pos="0.018433 0 -0.0005558" mass="0.05797" fullinertia="0.00004276 0.00004912 0.00002257 0 -0.00000005 0"/>
                          <geom pos="0 0 0" group="1" contype="0" conaffinity="0" material="Z2_0_Lite_description_0429_1_L_wrist_yaw_Link_mat" type="mesh" mesh="L_wrist_yaw_Link" />
                          <geom pos="0 0 0" rgba="0.9373 0.2667 0.2667 1" group="3" contype="1" conaffinity="1" type="mesh" mesh="L_wrist_yaw_Link" />
                          <body name="revo2_left_hand" pos="0.045 0 0" quat="0.5 -0.5 0.5 -0.5">
                            <inertial pos="-0.0052625 0.0033926 0.0521379" mass="0.238" fullinertia="0.0000210902 0.0000144592 0.0000079978 -0.0000000391 0.0000000921 0.0000011"/>
                            <geom pos="0 0 0" group="1" contype="0" conaffinity="0" material="revo2_left_hand_mat" type="mesh" mesh="revo2_left_hand_left_base_link" />
                            <geom pos="0 0 0" group="1" contype="0" conaffinity="0" material="revo2_left_hand_mat_2" type="mesh" mesh="revo2_left_hand_left_base_visual_link" />
                            <geom pos="0 0 0" rgba="0.9373 0.2667 0.2667 1" group="3" contype="1" conaffinity="1" type="mesh" mesh="revo2_left_hand_left_base_link" />
                            <body name="revo2_left_hand_left_thumb_metacarpal_link" pos="0.0045 -0.019 0.027825" quat="0.9964795 0 0 0.0838365">
                              <joint name="revo2_left_hand_left_thumb_metacarpal_joint" type="hinge" axis="0 0 1" limited="true" range="0 1.57" damping="0" frictionloss="0"/>
                              <inertial pos="0.0000152 -0.0070724 -0.0042084" mass="0.01" fullinertia="0.0000001592 0.0000001609 0.0000000514 0.0000000047 0.0000000005 0.0000000148"/>
                              <geom pos="0 0 0" group="1" contype="0" conaffinity="0" material="revo2_left_hand_left_thumb_metacarpal_link_mat" type="mesh" mesh="revo2_left_hand_left_thumb_metacarpal_link" />
                              <geom pos="0 0 0" rgba="0.9373 0.2667 0.2667 1" group="3" contype="1" conaffinity="1" type="mesh" mesh="revo2_left_hand_left_thumb_metacarpal_link" />
                              <body name="revo2_left_hand_left_thumb_proximal_link" pos="0 -0.014227 0" quat="0.9865567 -0.0765206 0.1248038 -0.0726253">
                                <joint name="revo2_left_hand_left_thumb_proximal_joint" type="hinge" axis="-1 0 0" limited="true" range="0 1.03" damping="0" frictionloss="0"/>
                                <inertial pos="-0.0000004 -0.0277016 -0.0020267" mass="0.05" fullinertia="0.0000024045 0.0000005123 0.0000025626 0.0000000002 0 0.0000000289"/>
                                <geom pos="0 0 0" group="1" contype="0" conaffinity="0" material="revo2_left_hand_left_thumb_proximal_link_mat" type="mesh" mesh="revo2_left_hand_left_thumb_proximal_link" />
                                <geom pos="0 0 0" group="1" contype="0" conaffinity="0" material="revo2_left_hand_left_thumb_proximal_link_mat_2" type="mesh" mesh="revo2_left_hand_left_thumb_proximal_visual_link" />
                                <geom pos="0 0 0" rgba="0.9373 0.2667 0.2667 1" group="3" contype="1" conaffinity="1" type="mesh" mesh="revo2_left_hand_left_thumb_proximal_link" />
                                <body name="revo2_left_hand_left_thumb_distal_link" pos="0 -0.052 0">
                                  <joint name="revo2_left_hand_left_thumb_distal_joint" type="hinge" axis="-1 0 0" limited="true" range="0 1.03" damping="0" frictionloss="0"/>
                                  <inertial pos="0.0000002 -0.0117551 0.0000114" mass="0.01" fullinertia="0.0000001678 0.0000001154 0.0000002196 0 0 -0.0000000125"/>
                                  <geom pos="0 0 0" group="1" contype="0" conaffinity="0" material="revo2_left_hand_left_thumb_distal_link_mat" type="mesh" mesh="revo2_left_hand_left_thumb_distal_link" />
                                  <geom pos="0 0 0" rgba="0.9373 0.2667 0.2667 1" group="3" contype="1" conaffinity="1" type="mesh" mesh="revo2_left_hand_left_thumb_distal_link" />
                                  <body name="revo2_left_hand_left_thumb_tip_link" pos="0 -0.026529 -0.0017734" quat="0.9994431 0.0333688 0 0">
                                  </body>
                                  <body name="revo2_left_hand_left_thumb_touch_link" pos="0 -0.013836 0.0076686" quat="0.9961796 0.0873286 0 0">
                                    <inertial pos="0.0000001 0.0007172 -0.0079025" mass="0.002" fullinertia="0.0000001678 0.0000001142 0.0000002207 0 0 0.0000000061"/>
                                    <geom pos="0 0 0" group="1" contype="0" conaffinity="0" material="revo2_left_hand_left_thumb_touch_link_mat" type="mesh" mesh="revo2_left_hand_left_thumb_touch_link" />
                                    <geom pos="0 0 0" rgba="0.9373 0.2667 0.2667 1" group="3" contype="1" conaffinity="1" type="mesh" mesh="revo2_left_hand_left_thumb_touch_link" />
                                  </body>
                                </body>
                              </body>
                            </body>
                            <body name="revo2_left_hand_left_index_proximal_link" pos="-0.0021349 -0.029578 0.080876" quat="0.9921471 0.0522807 0.0783652 0.0822789">
                              <joint name="revo2_left_hand_left_index_proximal_joint" type="hinge" axis="0 1 0" limited="true" range="0 1.41" damping="0" frictionloss="0"/>
                              <inertial pos="-0.0022354 -0.0000038 0.0176439" mass="0.009" fullinertia="0.0000002519 0.0000002363 0.000000093 0 -0.0000000064 -0.0000000002"/>
                              <geom pos="0 0 0" group="1" contype="0" conaffinity="0" material="revo2_left_hand_left_index_proximal_link_mat" type="mesh" mesh="revo2_left_hand_left_index_proximal_link" />
                              <geom pos="0 0 0" rgba="0.9373 0.2667 0.2667 1" group="3" contype="1" conaffinity="1" type="mesh" mesh="revo2_left_hand_left_index_proximal_link" />
                              <body name="revo2_left_hand_left_index_distal_link" pos="0 0 0.032">
                                <joint name="revo2_left_hand_left_index_distal_joint" type="hinge" axis="0 1 0" limited="true" range="0 1.63" damping="0" frictionloss="0"/>
                                <inertial pos="0.0033017 0.0000001 0.0142076" mass="0.009" fullinertia="0.00000034 0.0000003622 0.000000091 0 -0.0000000875 0"/>
                                <geom pos="0 0 0" group="1" contype="0" conaffinity="0" material="revo2_left_hand_left_index_distal_link_mat" type="mesh" mesh="revo2_left_hand_left_index_distal_link" />
                                <geom pos="0 0 0" rgba="0.9373 0.2667 0.2667 1" group="3" contype="1" conaffinity="1" type="mesh" mesh="revo2_left_hand_left_index_distal_link" />
                                <body name="revo2_left_hand_left_index_tip_link" pos="0.011097 0 0.035739" quat="0.9704723 0 0.2412125 0">
                                </body>
                                <body name="revo2_left_hand_left_index_touch_link" pos="0.014497 0 0.023303" quat="0.9718586 0 0.2355651 0">
                                  <inertial pos="-0.0029992 0 0.0025237" mass="0.002" fullinertia="0.0000000068 0.0000000054 0.0000000032 0 0.0000000015 0"/>
                                  <geom pos="0 0 0" group="1" contype="0" conaffinity="0" material="revo2_left_hand_left_index_touch_link_mat" type="mesh" mesh="revo2_left_hand_left_index_touch_link" />
                                  <geom pos="0 0 0" rgba="0.9373 0.2667 0.2667 1" group="3" contype="1" conaffinity="1" type="mesh" mesh="revo2_left_hand_left_index_touch_link" />
                                </body>
                              </body>
                            </body>
                            <body name="revo2_left_hand_left_middle_proximal_link" pos="-0.0045935 -0.010061 0.084993" quat="0.9966815 0.0175235 0.0746069 0.0274369">
                              <joint name="revo2_left_hand_left_middle_proximal_joint" type="hinge" axis="0 1 0" limited="true" range="0 1.41" damping="0" frictionloss="0"/>
                              <inertial pos="-0.0022242 -0.0000036 0.020305" mass="0.009" fullinertia="0.0000003669 0.0000003525 0.0000001122 0 -0.0000000098 -0.0000000003"/>
                              <geom pos="0 0 0" group="1" contype="0" conaffinity="0" material="revo2_left_hand_left_middle_proximal_link_mat" type="mesh" mesh="revo2_left_hand_left_middle_proximal_link" />
                              <geom pos="0 0 0" rgba="0.9373 0.2667 0.2667 1" group="3" contype="1" conaffinity="1" type="mesh" mesh="revo2_left_hand_left_middle_proximal_link" />
                              <body name="revo2_left_hand_left_middle_distal_link" pos="0 0 0.037" quat="0.9979991 0 0.0632278 0">
                                <joint name="revo2_left_hand_left_middle_distal_joint" type="hinge" axis="0 1 0" limited="true" range="0 1.63" damping="0" frictionloss="0"/>
                                <inertial pos="0.0018942 0 0.0168711" mass="0.009" fullinertia="0.0000005405 0.0000005498 0.0000000956 0 -0.0000000835 0"/>
                                <geom pos="0 0 0" group="1" contype="0" conaffinity="0" material="revo2_left_hand_left_middle_distal_link_mat" type="mesh" mesh="revo2_left_hand_left_middle_distal_link" />
                                <geom pos="0 0 0" rgba="0.9373 0.2667 0.2667 1" group="3" contype="1" conaffinity="1" type="mesh" mesh="revo2_left_hand_left_middle_distal_link" />
                                <body name="revo2_left_hand_left_middle_tip_link" pos="0.0073534 0 0.041703" quat="0.9848074 0 0.1736502 0">
                                </body>
                                <body name="revo2_left_hand_left_middle_touch_link" pos="0.012493 0 0.028393" quat="0.9848074 0 0.1736502 0">
                                  <inertial pos="-0.0031929 0 0.0029786" mass="0.002" fullinertia="0.00000001 0.0000000082 0.0000000044 0 0.0000000023 0"/>
                                  <geom pos="0 0 0" group="1" contype="0" conaffinity="0" material="revo2_left_hand_left_middle_touch_link_mat" type="mesh" mesh="revo2_left_hand_left_middle_touch_link" />
                                  <geom pos="0 0 0" rgba="0.9373 0.2667 0.2667 1" group="3" contype="1" conaffinity="1" type="mesh" mesh="revo2_left_hand_left_middle_touch_link" />
                                </body>
                              </body>
                            </body>
                            <body name="revo2_left_hand_left_ring_proximal_link" pos="-0.0046877 0.010026 0.083982" quat="0.996722 -0.0175386 0.0740633 -0.0274276">
                              <joint name="revo2_left_hand_left_ring_proximal_joint" type="hinge" axis="0 1 0" limited="true" range="0 1.41" damping="0" frictionloss="0"/>
                              <inertial pos="-0.0023446 -0.0000053 0.0191786" mass="0.009" fullinertia="0.0000003142 0.0000002976 0.0000001021 0 -0.0000000078 -0.0000000002"/>
                              <geom pos="0 0 0" group="1" contype="0" conaffinity="0" material="revo2_left_hand_left_ring_proximal_link_mat" type="mesh" mesh="revo2_left_hand_left_ring_proximal_link" />
                              <geom pos="0 0 0" rgba="0.9373 0.2667 0.2667 1" group="3" contype="1" conaffinity="1" type="mesh" mesh="revo2_left_hand_left_ring_proximal_link" />
                              <body name="revo2_left_hand_left_ring_distal_link" pos="0 0 0.035" quat="0.9979991 0 0.0632278 0">
                                <joint name="revo2_left_hand_left_ring_distal_joint" type="hinge" axis="0 1 0" limited="true" range="0 1.63" damping="0" frictionloss="0"/>
                                <inertial pos="0.0017705 0.0000001 0.016389" mass="0.009" fullinertia="0.0000004979 0.0000005061 0.0000000896 0 -0.0000000783 0"/>
                                <geom pos="0 0 0" group="1" contype="0" conaffinity="0" material="revo2_left_hand_left_ring_distal_link_mat" type="mesh" mesh="revo2_left_hand_left_ring_distal_link" />
                                <geom pos="0 0 0" rgba="0.9373 0.2667 0.2667 1" group="3" contype="1" conaffinity="1" type="mesh" mesh="revo2_left_hand_left_ring_distal_link" />
                                <body name="revo2_left_hand_left_ring_tip_link" pos="0.0071824 0 0.040734" quat="0.9848074 0 0.1736502 0">
                                </body>
                                <body name="revo2_left_hand_left_ring_touch_link" pos="0.012028 0 0.027796" quat="0.9848074 0 0.1736502 0">
                                  <inertial pos="-0.0030235 0 0.0030408" mass="0.002" fullinertia="0.0000000082 0.0000000066 0.0000000036 0 0.0000000018 0"/>
                                  <geom pos="0 0 0" group="1" contype="0" conaffinity="0" material="revo2_left_hand_left_ring_touch_link_mat" type="mesh" mesh="revo2_left_hand_left_ring_touch_link" />
                                  <geom pos="0 0 0" rgba="0.9373 0.2667 0.2667 1" group="3" contype="1" conaffinity="1" type="mesh" mesh="revo2_left_hand_left_ring_touch_link" />
                                </body>
                              </body>
                            </body>
                            <body name="revo2_left_hand_left_pinky_proximal_link" pos="-0.0023733 0.029356 0.078694" quat="0.9922455 -0.052387 0.0771065 -0.0822136">
                              <joint name="revo2_left_hand_left_pinky_proximal_joint" type="hinge" axis="0 1 0" limited="true" range="0 1.41" damping="0" frictionloss="0"/>
                              <inertial pos="-0.0021327 -0.000007 0.016068" mass="0.009" fullinertia="0.0000001976 0.000000182 0.0000000822 0 -0.0000000046 -0.0000000001"/>
                              <geom pos="0 0 0" group="1" contype="0" conaffinity="0" material="revo2_left_hand_left_pinky_proximal_link_mat" type="mesh" mesh="revo2_left_hand_left_pinky_proximal_link" />
                              <geom pos="0 0 0" rgba="0.9373 0.2667 0.2667 1" group="3" contype="1" conaffinity="1" type="mesh" mesh="revo2_left_hand_left_pinky_proximal_link" />
                              <body name="revo2_left_hand_left_pinky_distal_link" pos="0 0 0.029">
                                <joint name="revo2_left_hand_left_pinky_distal_joint" type="hinge" axis="0 1 0" limited="true" range="0 1.63" damping="0" frictionloss="0"/>
                                <inertial pos="0.0030795 -0.0000001 0.0130239" mass="0.009" fullinertia="0.00000027 0.0000002852 0.0000000791 0 -0.0000000671 0"/>
                                <geom pos="0 0 0" group="1" contype="0" conaffinity="0" material="revo2_left_hand_left_pinky_distal_link_mat" type="mesh" mesh="revo2_left_hand_left_pinky_distal_link" />
                                <geom pos="0 0 0" rgba="0.9373 0.2667 0.2667 1" group="3" contype="1" conaffinity="1" type="mesh" mesh="revo2_left_hand_left_pinky_distal_link" />
                                <body name="revo2_left_hand_left_pinky_tip_link" pos="0.010221 0 0.032918" quat="0.9718586 0 0.2355651 0">
                                </body>
                                <body name="revo2_left_hand_left_pinky_touch_link" pos="0.01401 0 0.021124" quat="0.9718586 0 0.2355651 0">
                                  <inertial pos="-0.0028914 -0.0000002 0.0016539" mass="0.002" fullinertia="0.0000000069 0.0000000053 0.0000000033 0 0.0000000014 0"/>
                                  <geom pos="0 0 0" group="1" contype="0" conaffinity="0" material="revo2_left_hand_left_pinky_touch_link_mat" type="mesh" mesh="revo2_left_hand_left_pinky_touch_link" />
                                  <geom pos="0 0 0" rgba="0.9373 0.2667 0.2667 1" group="3" contype="1" conaffinity="1" type="mesh" mesh="revo2_left_hand_left_pinky_touch_link" />
                                </body>
                              </body>
                            </body>
                          </body>
                        </body>
                      </body>
                    </body>
                  </body>
                </body>
              </body>
            </body>
          </body>
        </body>
      </body>
      <body name="Z2_0_Lite_description_0429_1_R_hip_pitch_Link" pos="0 -0.067132 -0.017988" quat="0.9914448 0.1305265 0 0">
        <joint name="Z2_0_Lite_description_0429_1_R_hip_pitch_joint" type="hinge" axis="0 1 0" limited="true" range="-2.35 2.35" damping="0" frictionloss="0"/>
        <inertial pos="-0.0067414 -0.049854 -0.027824" mass="1.5226" fullinertia="0.002466 0.0021744 0.0018245 0.00003494 0.00005185 0.00025613"/>
        <geom pos="0 0 0" group="1" contype="0" conaffinity="0" material="Z2_0_Lite_description_0429_1_R_hip_pitch_Link_mat" type="mesh" mesh="R_hip_pitch_Link" />
        <geom pos="0 0 0" rgba="0.9373 0.2667 0.2667 1" group="3" contype="1" conaffinity="1" type="mesh" mesh="R_hip_pitch_Link" />
        <body name="Z2_0_Lite_description_0429_1_R_hip_roll_Link" pos="0 -0.053575 -0.034315" quat="0.9914448 -0.1305265 0 0">
          <joint name="Z2_0_Lite_description_0429_1_R_hip_roll_joint" type="hinge" axis="1 0 0" limited="true" range="-1.74 0.52" damping="0" frictionloss="0"/>
          <inertial pos="0.0059886 0 -0.081347" mass="1.4044" fullinertia="0.0027006 0.0027879 0.0018432 0 0.00058691 0"/>
          <geom pos="0 0 0" group="1" contype="0" conaffinity="0" material="Z2_0_Lite_description_0429_1_R_hip_roll_Link_mat" type="mesh" mesh="R_hip_roll_Link" />
          <geom pos="0 0 0" rgba="0.9373 0.2667 0.2667 1" group="3" contype="1" conaffinity="1" type="mesh" mesh="R_hip_roll_Link" />
          <body name="Z2_0_Lite_description_0429_1_R_hip_yaw_Link" pos="0 0 -0.124">
            <joint name="Z2_0_Lite_description_0429_1_R_hip_yaw_joint" type="hinge" axis="0 0 1" limited="true" range="-3.14 3.14" damping="0" frictionloss="0"/>
            <inertial pos="-0.0050752 -0.0080176 -0.11921" mass="1.7683" fullinertia="0.0062873 0.0070322 0.0022775 0.00003384 0.00037656 0.00034527"/>
            <geom pos="0 0 0" group="1" contype="0" conaffinity="0" material="Z2_0_Lite_description_0429_1_R_hip_yaw_Link_mat" type="mesh" mesh="R_hip_yaw_Link" />
            <geom pos="0 0 0" rgba="0.9373 0.2667 0.2667 1" group="3" contype="1" conaffinity="1" type="mesh" mesh="R_hip_yaw_Link" />
            <body name="Z2_0_Lite_description_0429_1_R_knee_Link" pos="-0.008 0 -0.146">
              <joint name="Z2_0_Lite_description_0429_1_R_knee_joint" type="hinge" axis="0 1 0" limited="true" range="-0.5236 2.1817" damping="0" frictionloss="0"/>
              <inertial pos="0.0058511 0.0036171 -0.12267" mass="2.2355" fullinertia="0.012108 0.012381 0.0020857 -0.00005328 -0.00006593 0.00097143"/>
              <geom pos="0 0 0" group="1" contype="0" conaffinity="0" material="Z2_0_Lite_description_0429_1_R_knee_Link_mat" type="mesh" mesh="R_knee_Link" />
              <geom pos="0 0 0" rgba="0.9373 0.2667 0.2667 1" group="3" contype="1" conaffinity="1" type="mesh" mesh="R_knee_Link" />
              <body name="Z2_0_Lite_description_0429_1_R_ankle_pitch_Link" pos="0 0 -0.32">
                <joint name="Z2_0_Lite_description_0429_1_R_ankle_pitch_joint" type="hinge" axis="0 1 0" limited="true" range="-0.78 0.29" damping="0" frictionloss="0"/>
                <inertial pos="0 0 0" mass="0.07638" diaginertia="0.00000724 0.000009 0.00001458"/>
                <geom pos="0 0 0" group="1" contype="0" conaffinity="0" material="Z2_0_Lite_description_0429_1_R_ankle_pitch_Link_mat" type="mesh" mesh="R_ankle_pitch_Link" />
                <geom pos="0 0 0" rgba="0.9373 0.2667 0.2667 1" group="3" contype="1" conaffinity="1" type="mesh" mesh="R_ankle_pitch_Link" />
                <body name="Z2_0_Lite_description_0429_1_R_ankle_roll_Link" pos="0 0 0">
                  <joint name="Z2_0_Lite_description_0429_1_R_ankle_roll_joint" type="hinge" axis="1 0 0" limited="true" range="-0.36 0.36" damping="0" frictionloss="0"/>
                  <inertial pos="0.034219 -0.0000157 -0.026454" mass="0.54579" fullinertia="0.00029693 0.0020607 0.0021807 -0.00000003 -0.00007894 -0.00000027"/>
                  <geom pos="0 0 0" group="1" contype="0" conaffinity="0" material="Z2_0_Lite_description_0429_1_R_ankle_roll_Link_mat" type="mesh" mesh="R_ankle_roll_Link" />
                  <geom pos="0 0 0" rgba="0.9373 0.2667 0.2667 1" group="3" contype="1" conaffinity="1" type="mesh" mesh="R_ankle_roll_Link" />
                  <geom name="right_foot_contact_0" type="capsule" pos="0.04 -0.03 -0.035" quat="0.707107 0 -0.707107 0" size="0.0065 0.07" group="4" contype="0" conaffinity="1" condim="3" priority="1" friction="0.6 0.005 0.0001" rgba="0.2 0.6 0.2 0.3" />
                  <geom name="right_foot_contact_1" type="capsule" pos="0.04 0 -0.035" quat="0.707107 0 -0.707107 0" size="0.0065 0.10" group="4" contype="0" conaffinity="1" condim="3" priority="1" friction="0.6 0.005 0.0001" rgba="0.2 0.6 0.2 0.3" />
                  <geom name="right_foot_contact_2" type="capsule" pos="0.04 0.03 -0.035" quat="0.707107 0 -0.707107 0" size="0.0065 0.07" group="4" contype="0" conaffinity="1" condim="3" priority="1" friction="0.6 0.005 0.0001" rgba="0.2 0.6 0.2 0.3" />
                </body>
              </body>
            </body>
          </body>
        </body>
      </body>
      <body name="Z2_0_Lite_description_0429_1_L_hip_pitch_Link" pos="0 0.067132 -0.017988" quat="0.9914448 -0.1305265 0 0">
        <joint name="Z2_0_Lite_description_0429_1_L_hip_pitch_joint" type="hinge" axis="0 1 0" limited="true" range="-2.35 2.35" damping="0" frictionloss="0"/>
        <inertial pos="-0.0067102 0.049727 -0.027898" mass="1.5226" fullinertia="0.0024686 0.002182 0.0018186 -0.00003096 0.00005223 -0.00024336"/>
        <geom pos="0 0 0" group="1" contype="0" conaffinity="0" material="Z2_0_Lite_description_0429_1_L_hip_pitch_Link_mat" type="mesh" mesh="L_hip_pitch_Link" />
        <geom pos="0 0 0" rgba="0.9373 0.2667 0.2667 1" group="3" contype="1" conaffinity="1" type="mesh" mesh="L_hip_pitch_Link" />
        <body name="Z2_0_Lite_description_0429_1_L_hip_roll_Link" pos="0 0.053575 -0.034315" quat="0.9914448 0.1305265 0 0">
          <joint name="Z2_0_Lite_description_0429_1_L_hip_roll_joint" type="hinge" axis="1 0 0" limited="true" range="-0.52 1.74" damping="0" frictionloss="0"/>
          <inertial pos="0.0059886 0 -0.081347" mass="1.4044" fullinertia="0.0027006 0.0027879 0.0018432 0 0.00058691 0"/>
          <geom pos="0 0 0" group="1" contype="0" conaffinity="0" material="Z2_0_Lite_description_0429_1_L_hip_roll_Link_mat" type="mesh" mesh="L_hip_roll_Link" />
          <geom pos="0 0 0" rgba="0.9373 0.2667 0.2667 1" group="3" contype="1" conaffinity="1" type="mesh" mesh="L_hip_roll_Link" />
          <body name="Z2_0_Lite_description_0429_1_L_hip_yaw_Link" pos="0 0 -0.124">
            <joint name="Z2_0_Lite_description_0429_1_L_hip_yaw_joint" type="hinge" axis="0 0 1" limited="true" range="-3.14 3.14" damping="0" frictionloss="0"/>
            <inertial pos="-0.0051001 0.0080164 -0.11922" mass="1.7683" fullinertia="0.0062869 0.0070336 0.0022792 -0.00003521 0.00037662 -0.000346"/>
            <geom pos="0 0 0" group="1" contype="0" conaffinity="0" material="Z2_0_Lite_description_0429_1_L_hip_yaw_Link_mat" type="mesh" mesh="L_hip_yaw_Link" />
            <geom pos="0 0 0" rgba="0.9373 0.2667 0.2667 1" group="3" contype="1" conaffinity="1" type="mesh" mesh="L_hip_yaw_Link" />
            <body name="Z2_0_Lite_description_0429_1_L_knee_Link" pos="-0.008 0 -0.146">
              <joint name="Z2_0_Lite_description_0429_1_L_knee_joint" type="hinge" axis="0 1 0" limited="true" range="-0.5236 2.1817" damping="0" frictionloss="0"/>
              <inertial pos="0.0058894 -0.0036117 -0.12257" mass="2.23548" fullinertia="0.01211973 0.012393 0.0020867 0.00005351 -0.00006149 -0.00097107"/>
              <geom pos="0 0 0" group="1" contype="0" conaffinity="0" material="Z2_0_Lite_description_0429_1_L_knee_Link_mat" type="mesh" mesh="L_knee_Link" />
              <geom pos="0 0 0" rgba="0.9373 0.2667 0.2667 1" group="3" contype="1" conaffinity="1" type="mesh" mesh="L_knee_Link" />
              <body name="Z2_0_Lite_description_0429_1_L_ankle_pitch_Link" pos="0 0 -0.32">
                <joint name="Z2_0_Lite_description_0429_1_L_ankle_pitch_joint" type="hinge" axis="0 1 0" limited="true" range="-0.78 0.29" damping="0" frictionloss="0"/>
                <inertial pos="0 0 0" mass="0.07638" diaginertia="0.00000724 0.000009 0.00001458"/>
                <geom pos="0 0 0" group="1" contype="0" conaffinity="0" material="Z2_0_Lite_description_0429_1_L_ankle_pitch_Link_mat" type="mesh" mesh="L_ankle_pitch_Link" />
                <geom pos="0 0 0" rgba="0.9373 0.2667 0.2667 1" group="3" contype="1" conaffinity="1" type="mesh" mesh="L_ankle_pitch_Link" />
                <body name="Z2_0_Lite_description_0429_1_L_ankle_roll_Link" pos="0 0 0">
                  <joint name="Z2_0_Lite_description_0429_1_L_ankle_roll_joint" type="hinge" axis="1 0 0" limited="true" range="-0.36 0.36" damping="0" frictionloss="0"/>
                  <inertial pos="0.034219 -0.0000157 -0.026454" mass="0.54579" fullinertia="0.00029693 0.0020607 0.0021807 -0.00000003 -0.00007894 -0.00000027"/>
                  <geom pos="0 0 0" group="1" contype="0" conaffinity="0" material="Z2_0_Lite_description_0429_1_L_ankle_roll_Link_mat" type="mesh" mesh="L_ankle_roll_Link" />
                  <geom pos="0 0 0" rgba="0.9373 0.2667 0.2667 1" group="3" contype="1" conaffinity="1" type="mesh" mesh="L_ankle_roll_Link" />
                  <geom name="left_foot_contact_0" type="capsule" pos="0.04 -0.03 -0.035" quat="0.707107 0 -0.707107 0" size="0.0065 0.07" group="4" contype="0" conaffinity="1" condim="3" priority="1" friction="0.6 0.005 0.0001" rgba="0.2 0.6 0.2 0.3" />
                  <geom name="left_foot_contact_1" type="capsule" pos="0.04 0 -0.035" quat="0.707107 0 -0.707107 0" size="0.0065 0.10" group="4" contype="0" conaffinity="1" condim="3" priority="1" friction="0.6 0.005 0.0001" rgba="0.2 0.6 0.2 0.3" />
                  <geom name="left_foot_contact_2" type="capsule" pos="0.04 0.03 -0.035" quat="0.707107 0 -0.707107 0" size="0.0065 0.07" group="4" contype="0" conaffinity="1" condim="3" priority="1" friction="0.6 0.005 0.0001" rgba="0.2 0.6 0.2 0.3" />
                </body>
              </body>
            </body>
          </body>
        </body>
      </body>
    </body>
  </worldbody>
  <equality>
    <joint name="revo2_left_hand_left_thumb_distal_joint_mimic" joint1="revo2_left_hand_left_thumb_distal_joint" joint2="revo2_left_hand_left_thumb_proximal_joint" polycoef="0 1 0 0 0" />
    <joint name="revo2_left_hand_left_index_distal_joint_mimic" joint1="revo2_left_hand_left_index_distal_joint" joint2="revo2_left_hand_left_index_proximal_joint" polycoef="0 1.155 0 0 0" />
    <joint name="revo2_left_hand_left_middle_distal_joint_mimic" joint1="revo2_left_hand_left_middle_distal_joint" joint2="revo2_left_hand_left_middle_proximal_joint" polycoef="0 1.155 0 0 0" />
    <joint name="revo2_left_hand_left_ring_distal_joint_mimic" joint1="revo2_left_hand_left_ring_distal_joint" joint2="revo2_left_hand_left_ring_proximal_joint" polycoef="0 1.155 0 0 0" />
    <joint name="revo2_left_hand_left_pinky_distal_joint_mimic" joint1="revo2_left_hand_left_pinky_distal_joint" joint2="revo2_left_hand_left_pinky_proximal_joint" polycoef="0 1.155 0 0 0" />
    <joint name="revo2_right_hand_right_thumb_distal_joint_mimic" joint1="revo2_right_hand_right_thumb_distal_joint" joint2="revo2_right_hand_right_thumb_proximal_joint" polycoef="0 1 0 0 0" />
    <joint name="revo2_right_hand_right_index_distal_joint_mimic" joint1="revo2_right_hand_right_index_distal_joint" joint2="revo2_right_hand_right_index_proximal_joint" polycoef="0 1.155 0 0 0" />
    <joint name="revo2_right_hand_right_middle_distal_joint_mimic" joint1="revo2_right_hand_right_middle_distal_joint" joint2="revo2_right_hand_right_middle_proximal_joint" polycoef="0 1.155 0 0 0" />
    <joint name="revo2_right_hand_right_ring_distal_joint_mimic" joint1="revo2_right_hand_right_ring_distal_joint" joint2="revo2_right_hand_right_ring_proximal_joint" polycoef="0 1.155 0 0 0" />
    <joint name="revo2_right_hand_right_pinky_distal_joint_mimic" joint1="revo2_right_hand_right_pinky_distal_joint" joint2="revo2_right_hand_right_pinky_proximal_joint" polycoef="0 1.155 0 0 0" />
  </equality>
  <actuator>
    <position name="Z2_0_Lite_description_0429_1_waist_yaw_joint_servo" joint="Z2_0_Lite_description_0429_1_waist_yaw_joint" kp="100" />
    <position name="Z2_0_Lite_description_0429_1_waist_pitch_joint_servo" joint="Z2_0_Lite_description_0429_1_waist_pitch_joint" kp="100" />
    <position name="Z2_0_Lite_description_0429_1_waist_roll_joint_servo" joint="Z2_0_Lite_description_0429_1_waist_roll_joint" kp="100" />
    <position name="Z2_0_Lite_description_0429_1_R_shoulder_pitch_joint_servo" joint="Z2_0_Lite_description_0429_1_R_shoulder_pitch_joint" kp="100" />
    <position name="Z2_0_Lite_description_0429_1_R_shoulder_roll_joint_servo" joint="Z2_0_Lite_description_0429_1_R_shoulder_roll_joint" kp="100" />
    <position name="Z2_0_Lite_description_0429_1_R_shoulder_yaw_joint_servo" joint="Z2_0_Lite_description_0429_1_R_shoulder_yaw_joint" kp="100" />
    <position name="Z2_0_Lite_description_0429_1_R_elbow_joint_servo" joint="Z2_0_Lite_description_0429_1_R_elbow_joint" kp="100" />
    <position name="Z2_0_Lite_description_0429_1_R_wrist_roll_joint_servo" joint="Z2_0_Lite_description_0429_1_R_wrist_roll_joint" kp="100" />
    <position name="Z2_0_Lite_description_0429_1_R_wrist_pitch_joint_servo" joint="Z2_0_Lite_description_0429_1_R_wrist_pitch_joint" kp="100" />
    <position name="Z2_0_Lite_description_0429_1_R_wrist_yaw_joint_servo" joint="Z2_0_Lite_description_0429_1_R_wrist_yaw_joint" kp="100" />
    <position name="Z2_0_Lite_description_0429_1_L_shoulder_pitch_joint_servo" joint="Z2_0_Lite_description_0429_1_L_shoulder_pitch_joint" kp="100" />
    <position name="Z2_0_Lite_description_0429_1_L_shoulder_roll_joint_servo" joint="Z2_0_Lite_description_0429_1_L_shoulder_roll_joint" kp="100" />
    <position name="Z2_0_Lite_description_0429_1_L_shoulder_yaw_joint_servo" joint="Z2_0_Lite_description_0429_1_L_shoulder_yaw_joint" kp="100" />
    <position name="Z2_0_Lite_description_0429_1_L_elbow_joint_servo" joint="Z2_0_Lite_description_0429_1_L_elbow_joint" kp="100" />
    <position name="Z2_0_Lite_description_0429_1_L_wrist_roll_joint_servo" joint="Z2_0_Lite_description_0429_1_L_wrist_roll_joint" kp="100" />
    <position name="Z2_0_Lite_description_0429_1_L_wrist_pitch_joint_servo" joint="Z2_0_Lite_description_0429_1_L_wrist_pitch_joint" kp="100" />
    <position name="Z2_0_Lite_description_0429_1_L_wrist_yaw_joint_servo" joint="Z2_0_Lite_description_0429_1_L_wrist_yaw_joint" kp="100" />
    <position name="Z2_0_Lite_description_0429_1_R_hip_pitch_joint_servo" joint="Z2_0_Lite_description_0429_1_R_hip_pitch_joint" kp="100" />
    <position name="Z2_0_Lite_description_0429_1_R_hip_roll_joint_servo" joint="Z2_0_Lite_description_0429_1_R_hip_roll_joint" kp="100" />
    <position name="Z2_0_Lite_description_0429_1_R_hip_yaw_joint_servo" joint="Z2_0_Lite_description_0429_1_R_hip_yaw_joint" kp="100" />
    <position name="Z2_0_Lite_description_0429_1_R_knee_joint_servo" joint="Z2_0_Lite_description_0429_1_R_knee_joint" kp="100" />
    <position name="Z2_0_Lite_description_0429_1_R_ankle_pitch_joint_servo" joint="Z2_0_Lite_description_0429_1_R_ankle_pitch_joint" kp="100" />
    <position name="Z2_0_Lite_description_0429_1_R_ankle_roll_joint_servo" joint="Z2_0_Lite_description_0429_1_R_ankle_roll_joint" kp="100" />
    <position name="Z2_0_Lite_description_0429_1_L_hip_pitch_joint_servo" joint="Z2_0_Lite_description_0429_1_L_hip_pitch_joint" kp="100" />
    <position name="Z2_0_Lite_description_0429_1_L_hip_roll_joint_servo" joint="Z2_0_Lite_description_0429_1_L_hip_roll_joint" kp="100" />
    <position name="Z2_0_Lite_description_0429_1_L_hip_yaw_joint_servo" joint="Z2_0_Lite_description_0429_1_L_hip_yaw_joint" kp="100" />
    <position name="Z2_0_Lite_description_0429_1_L_knee_joint_servo" joint="Z2_0_Lite_description_0429_1_L_knee_joint" kp="100" />
    <position name="Z2_0_Lite_description_0429_1_L_ankle_pitch_joint_servo" joint="Z2_0_Lite_description_0429_1_L_ankle_pitch_joint" kp="100" />
    <position name="Z2_0_Lite_description_0429_1_L_ankle_roll_joint_servo" joint="Z2_0_Lite_description_0429_1_L_ankle_roll_joint" kp="100" />
    <position name="revo2_left_hand_left_thumb_metacarpal_joint_servo" joint="revo2_left_hand_left_thumb_metacarpal_joint" kp="0.25" forcelimited="true" forcerange="-0.5 0.5" />
    <position name="revo2_left_hand_left_thumb_proximal_joint_servo" joint="revo2_left_hand_left_thumb_proximal_joint" kp="0.55" forcelimited="true" forcerange="-1.1 1.1" />
    <position name="revo2_left_hand_left_thumb_distal_joint_servo" joint="revo2_left_hand_left_thumb_distal_joint" kp="0.55" forcelimited="true" forcerange="-1.1 1.1" />
    <position name="revo2_left_hand_left_index_proximal_joint_servo" joint="revo2_left_hand_left_index_proximal_joint" kp="1" forcelimited="true" forcerange="-2 2" />
    <position name="revo2_left_hand_left_index_distal_joint_servo" joint="revo2_left_hand_left_index_distal_joint" kp="1" forcelimited="true" forcerange="-2 2" />
    <position name="revo2_left_hand_left_middle_proximal_joint_servo" joint="revo2_left_hand_left_middle_proximal_joint" kp="1" forcelimited="true" forcerange="-2 2" />
    <position name="revo2_left_hand_left_middle_distal_joint_servo" joint="revo2_left_hand_left_middle_distal_joint" kp="1" forcelimited="true" forcerange="-2 2" />
    <position name="revo2_left_hand_left_ring_proximal_joint_servo" joint="revo2_left_hand_left_ring_proximal_joint" kp="1" forcelimited="true" forcerange="-2 2" />
    <position name="revo2_left_hand_left_ring_distal_joint_servo" joint="revo2_left_hand_left_ring_distal_joint" kp="1" forcelimited="true" forcerange="-2 2" />
    <position name="revo2_left_hand_left_pinky_proximal_joint_servo" joint="revo2_left_hand_left_pinky_proximal_joint" kp="1" forcelimited="true" forcerange="-2 2" />
    <position name="revo2_left_hand_left_pinky_distal_joint_servo" joint="revo2_left_hand_left_pinky_distal_joint" kp="1" forcelimited="true" forcerange="-2 2" />
    <position name="revo2_right_hand_right_thumb_metacarpal_joint_servo" joint="revo2_right_hand_right_thumb_metacarpal_joint" kp="0.25" forcelimited="true" forcerange="-0.5 0.5" />
    <position name="revo2_right_hand_right_thumb_proximal_joint_servo" joint="revo2_right_hand_right_thumb_proximal_joint" kp="0.55" forcelimited="true" forcerange="-1.1 1.1" />
    <position name="revo2_right_hand_right_thumb_distal_joint_servo" joint="revo2_right_hand_right_thumb_distal_joint" kp="0.55" forcelimited="true" forcerange="-1.1 1.1" />
    <position name="revo2_right_hand_right_index_proximal_joint_servo" joint="revo2_right_hand_right_index_proximal_joint" kp="1" forcelimited="true" forcerange="-2 2" />
    <position name="revo2_right_hand_right_index_distal_joint_servo" joint="revo2_right_hand_right_index_distal_joint" kp="1" forcelimited="true" forcerange="-2 2" />
    <position name="revo2_right_hand_right_middle_proximal_joint_servo" joint="revo2_right_hand_right_middle_proximal_joint" kp="1" forcelimited="true" forcerange="-2 2" />
    <position name="revo2_right_hand_right_middle_distal_joint_servo" joint="revo2_right_hand_right_middle_distal_joint" kp="1" forcelimited="true" forcerange="-2 2" />
    <position name="revo2_right_hand_right_ring_proximal_joint_servo" joint="revo2_right_hand_right_ring_proximal_joint" kp="1" forcelimited="true" forcerange="-2 2" />
    <position name="revo2_right_hand_right_ring_distal_joint_servo" joint="revo2_right_hand_right_ring_distal_joint" kp="1" forcelimited="true" forcerange="-2 2" />
    <position name="revo2_right_hand_right_pinky_proximal_joint_servo" joint="revo2_right_hand_right_pinky_proximal_joint" kp="1" forcelimited="true" forcerange="-2 2" />
    <position name="revo2_right_hand_right_pinky_distal_joint_servo" joint="revo2_right_hand_right_pinky_distal_joint" kp="1" forcelimited="true" forcerange="-2 2" />
  </actuator>
</mujoco>
