<mujoco model="assembly">
  <compiler angle="radian" meshdir="meshes/" />
  <size nkey="1" />
  <statistic extent="2.8" />
  <asset>
    <material name="Z2_0_Lite_description_0429_1_mat" specular="0" rgba="0.7922 0.8196 0.9294 1" />
    <material name="Z2_0_Lite_description_0429_1_waist_yaw_Link_mat" specular="0" rgba="0.7922 0.8196 0.9294 1" />
    <material name="Z2_0_Lite_description_0429_1_waist_pitch_Link_mat" specular="0" rgba="0.5882 0.5882 0.6275 1" />
    <material name="Z2_0_Lite_description_0429_1_waist_roll_Link_mat" specular="0" rgba="0.7922 0.8196 0.9294 1" />
    <material name="Z2_0_Lite_description_0429_1_neck_Link_mat" specular="0" rgba="0.7922 0.8196 0.9294 1" />
    <material name="Z2_0_Lite_description_0429_1_R_shoulder_pitch_Link_mat" specular="0" rgba="0.7922 0.8196 0.9294 1" />
    <material name="Z2_0_Lite_description_0429_1_R_shoulder_roll_Link_mat" specular="0" rgba="0.7922 0.8196 0.9294 1" />
    <material name="Z2_0_Lite_description_0429_1_R_shoulder_yaw_Link_mat" specular="0" rgba="0.7922 0.8196 0.9294 1" />
    <material name="Z2_0_Lite_description_0429_1_R_elbow_Link_mat" specular="0" rgba="0.7922 0.8196 0.9294 1" />
    <material name="Z2_0_Lite_description_0429_1_R_wrist_roll_Link_mat" specular="0" rgba="0.5882 0.5882 0.6275 1" />
    <material name="Z2_0_Lite_description_0429_1_R_wrist_pitch_Link_mat" specular="0" rgba="0.7922 0.8196 0.9294 1" />
    <material name="Z2_0_Lite_description_0429_1_R_wrist_yaw_Link_mat" specular="0" />
    <material name="Z2_0_Lite_description_0429_1_L_shoulder_pitch_Link_mat" specular="0" rgba="0.7922 0.8196 0.9294 1" />
    <material name="Z2_0_Lite_description_0429_1_L_shoulder_roll_Link_mat" specular="0" rgba="0.7922 0.8196 0.9294 1" />
    <material name="Z2_0_Lite_description_0429_1_L_shoulder_yaw_Link_mat" specular="0" rgba="0.7922 0.8196 0.9294 1" />
    <material name="Z2_0_Lite_description_0429_1_L_elbow_Link_mat" specular="0" rgba="0.7922 0.8196 0.9294 1" />
    <material name="Z2_0_Lite_description_0429_1_L_wrist_roll_Link_mat" specular="0" rgba="0.5882 0.5882 0.6275 1" />
    <material name="Z2_0_Lite_description_0429_1_L_wrist_pitch_Link_mat" specular="0" rgba="0.7922 0.8196 0.9294 1" />
    <material name="Z2_0_Lite_description_0429_1_L_wrist_yaw_Link_mat" specular="0" />
    <material name="Z2_0_Lite_description_0429_1_R_hip_pitch_Link_mat" specular="0" rgba="0.7922 0.8196 0.9294 1" />
    <material name="Z2_0_Lite_description_0429_1_R_hip_roll_Link_mat" specular="0" rgba="0.7922 0.8196 0.9294 1" />
    <material name="Z2_0_Lite_description_0429_1_R_hip_yaw_Link_mat" specular="0" rgba="0.7922 0.8196 0.9294 1" />
    <material name="Z2_0_Lite_description_0429_1_R_knee_Link_mat" specular="0" rgba="0.7922 0.8196 0.9294 1" />
    <material name="Z2_0_Lite_description_0429_1_R_ankle_pitch_Link_mat" specular="0" rgba="0.5882 0.5882 0.6275 1" />
    <material name="Z2_0_Lite_description_0429_1_R_ankle_roll_Link_mat" specular="0" rgba="0.7922 0.8196 0.9294 1" />
    <material name="Z2_0_Lite_description_0429_1_L_hip_pitch_Link_mat" specular="0" rgba="0.7922 0.8196 0.9294 1" />
    <material name="Z2_0_Lite_description_0429_1_L_hip_roll_Link_mat" specular="0" rgba="0.7922 0.8196 0.9294 1" />
    <material name="Z2_0_Lite_description_0429_1_L_hip_yaw_Link_mat" specular="0" rgba="0.7922 0.8196 0.9294 1" />
    <material name="Z2_0_Lite_description_0429_1_L_knee_Link_mat" specular="0" rgba="0.7922 0.8196 0.9294 1" />
    <material name="Z2_0_Lite_description_0429_1_L_ankle_pitch_Link_mat" specular="0" rgba="0.5882 0.5882 0.6275 1" />
    <material name="Z2_0_Lite_description_0429_1_L_ankle_roll_Link_mat" specular="0" rgba="0.7922 0.8196 0.9294 1" />
    <material name="revo2_left_hand_mat" specular="0" />
    <material name="revo2_left_hand_mat_2" />
    <material name="revo2_left_hand_left_thumb_metacarpal_link_mat" specular="0" />
    <material name="revo2_left_hand_left_thumb_proximal_link_mat" specular="0" />
    <material name="revo2_left_hand_left_thumb_proximal_link_mat_2" />
    <material name="revo2_left_hand_left_thumb_distal_link_mat" specular="0" />
    <material name="revo2_left_hand_left_thumb_touch_link_mat" specular="0" />
    <material name="revo2_left_hand_left_index_proximal_link_mat" specular="0" />
    <material name="revo2_left_hand_left_index_distal_link_mat" specular="0" />
    <material name="revo2_left_hand_left_index_touch_link_mat" specular="0" />
    <material name="revo2_left_hand_left_middle_proximal_link_mat" specular="0" />
    <material name="revo2_left_hand_left_middle_distal_link_mat" specular="0" />
    <material name="revo2_left_hand_left_middle_touch_link_mat" specular="0" />
    <material name="revo2_left_hand_left_ring_proximal_link_mat" specular="0" />
    <material name="revo2_left_hand_left_ring_distal_link_mat" specular="0" />
    <material name="revo2_left_hand_left_ring_touch_link_mat" specular="0" />
    <material name="revo2_left_hand_left_pinky_proximal_link_mat" specular="0" />
    <material name="revo2_left_hand_left_pinky_distal_link_mat" specular="0" />
    <material name="revo2_left_hand_left_pinky_touch_link_mat" specular="0" />
    <material name="revo2_right_hand_mat" specular="0" />
    <material name="revo2_right_hand_mat_2" />
    <material name="revo2_right_hand_right_thumb_metacarpal_link_mat" specular="0" />
    <material name="revo2_right_hand_right_thumb_proximal_link_mat" specular="0" />
    <material name="revo2_right_hand_right_thumb_distal_link_mat" specular="0" />
    <material name="revo2_right_hand_right_thumb_touch_link_mat" specular="0" />
    <material name="revo2_right_hand_right_index_proximal_link_mat" specular="0" />
    <material name="revo2_right_hand_right_index_distal_link_mat" specular="0" />
    <material name="revo2_right_hand_right_index_touch_link_mat" specular="0" />
    <material name="revo2_right_hand_right_middle_proximal_link_mat" specular="0" />
    <material name="revo2_right_hand_right_middle_distal_link_mat" specular="0" />
    <material name="revo2_right_hand_right_middle_touch_link_mat" specular="0" />
    <material name="revo2_right_hand_right_ring_proximal_link_mat" specular="0" />
    <material name="revo2_right_hand_right_ring_distal_link_mat" specular="0" />
    <material name="revo2_right_hand_right_ring_touch_link_mat" specular="0" />
    <material name="revo2_right_hand_right_pinky_proximal_link_mat" specular="0" />
    <material name="revo2_right_hand_right_pinky_distal_link_mat" specular="0" />
    <material name="revo2_right_hand_right_pinky_touch_link_mat" specular="0" />
    <mesh name="base_link" content_type="model/stl" file="base_link.STL" />
    <mesh name="waist_yaw_Link" content_type="model/stl" file="waist_yaw_Link.STL" />
    <mesh name="waist_pitch_Link" content_type="model/stl" file="waist_pitch_Link.STL" />
    <mesh name="waist_roll_Link" content_type="model/stl" file="waist_roll_Link.STL" />
    <mesh name="neck_Link" content_type="model/stl" file="neck_Link.STL" />
    <mesh name="R_shoulder_pitch_Link" content_type="model/stl" file="R_shoulder_pitch_Link.STL" />
    <mesh name="R_shoulder_roll_Link" content_type="model/stl" file="R_shoulder_roll_Link.STL" />
    <mesh name="R_shoulder_yaw_Link" content_type="model/stl" file="R_shoulder_yaw_Link.STL" />
    <mesh name="R_elbow_Link" content_type="model/stl" file="R_elbow_Link.STL" />
    <mesh name="R_wrist_roll_Link" content_type="model/stl" file="R_wrist_roll_Link.STL" />
    <mesh name="R_wrist_pitch_Link" content_type="model/stl" file="R_wrist_pitch_Link.STL" />
    <mesh name="R_wrist_yaw_Link" content_type="model/stl" file="R_wrist_yaw_Link.STL" />
    <mesh name="L_shoulder_pitch_Link" content_type="model/stl" file="L_shoulder_pitch_Link.STL" />
    <mesh name="L_shoulder_roll_Link" content_type="model/stl" file="L_shoulder_roll_Link.STL" />
    <mesh name="L_shoulder_yaw_Link" content_type="model/stl" file="L_shoulder_yaw_Link.STL" />
    <mesh name="L_elbow_Link" content_type="model/stl" file="L_elbow_Link.STL" />
    <mesh name="L_wrist_roll_Link" content_type="model/stl" file="L_wrist_roll_Link.STL" />
    <mesh name="L_wrist_pitch_Link" content_type="model/stl" file="L_wrist_pitch_Link.STL" />
    <mesh name="L_wrist_yaw_Link" content_type="model/stl" file="L_wrist_yaw_Link.STL" />
    <mesh name="R_hip_pitch_Link" content_type="model/stl" file="R_hip_pitch_Link.STL" />
    <mesh name="R_hip_roll_Link" content_type="model/stl" file="R_hip_roll_Link.STL" />
    <mesh name="R_hip_yaw_Link" content_type="model/stl" file="R_hip_yaw_Link.STL" />
    <mesh name="R_knee_Link" content_type="model/stl" file="R_knee_Link.STL" />
    <mesh name="R_ankle_pitch_Link" content_type="model/stl" file="R_ankle_pitch_Link.STL" />
    <mesh name="R_ankle_roll_Link" content_type="model/stl" file="R_ankle_roll_Link.STL" />
    <mesh name="L_hip_pitch_Link" content_type="model/stl" file="L_hip_pitch_Link.STL" />
    <mesh name="L_hip_roll_Link" content_type="model/stl" file="L_hip_roll_Link.STL" />
    <mesh name="L_hip_yaw_Link" content_type="model/stl" file="L_hip_yaw_Link.STL" />
    <mesh name="L_knee_Link" content_type="model/stl" file="L_knee_Link.STL" />
    <mesh name="L_ankle_pitch_Link" content_type="model/stl" file="L_ankle_pitch_Link.STL" />
    <mesh name="L_ankle_roll_Link" content_type="model/stl" file="L_ankle_roll_Link.STL" />
    <mesh name="revo2_left_hand_left_base_link" content_type="model/stl" file="revo2_left_hand/left_base_link.STL" />
    <mesh name="revo2_left_hand_left_base_visual_link" content_type="model/stl" file="revo2_left_hand/left_base_visual_link.STL" />
    <mesh name="revo2_left_hand_left_thumb_metacarpal_link" content_type="model/stl" file="revo2_left_hand/left_thumb_metacarpal_link.STL" />
    <mesh name="revo2_left_hand_left_thumb_proximal_link" content_type="model/stl" file="revo2_left_hand/left_thumb_proximal_link.STL" />
    <mesh name="revo2_left_hand_left_thumb_proximal_visual_link" content_type="model/stl" file="revo2_left_hand/left_thumb_proximal_visual_link.STL" />
    <mesh name="revo2_left_hand_left_thumb_distal_link" content_type="model/stl" file="revo2_left_hand/left_thumb_distal_link.STL" />
    <mesh name="revo2_left_hand_left_thumb_touch_link" content_type="model/stl" file="revo2_left_hand/left_thumb_touch_link.STL" />
    <mesh name="revo2_left_hand_left_index_proximal_link" content_type="model/stl" file="revo2_left_hand/left_index_proximal_link.STL" />
    <mesh name="revo2_left_hand_left_index_distal_link" content_type="model/stl" file="revo2_left_hand/left_index_distal_link.STL" />
    <mesh name="revo2_left_hand_left_index_touch_link" content_type="model/stl" file="revo2_left_hand/left_index_touch_link.STL" />
    <mesh name="revo2_left_hand_left_middle_proximal_link" content_type="model/stl" file="revo2_left_hand/left_middle_proximal_link.STL" />
    <mesh name="revo2_left_hand_left_middle_distal_link" content_type="model/stl" file="revo2_left_hand/left_middle_distal_link.STL" />
    <mesh name="revo2_left_hand_left_middle_touch_link" content_type="model/stl" file="revo2_left_hand/left_middle_touch_link.STL" />
    <mesh name="revo2_left_hand_left_ring_proximal_link" content_type="model/stl" file="revo2_left_hand/left_ring_proximal_link.STL" />
    <mesh name="revo2_left_hand_left_ring_distal_link" content_type="model/stl" file="revo2_left_hand/left_ring_distal_link.STL" />
    <mesh name="revo2_left_hand_left_ring_touch_link" content_type="model/stl" file="revo2_left_hand/left_ring_touch_link.STL" />
    <mesh name="revo2_left_hand_left_pinky_proximal_link" content_type="model/stl" file="revo2_left_hand/left_pinky_proximal_link.STL" />
    <mesh name="revo2_left_hand_left_pinky_distal_link" content_type="model/stl" file="revo2_left_hand/left_pinky_distal_link.STL" />
    <mesh name="revo2_left_hand_left_pinky_touch_link" content_type="model/stl" file="revo2_left_hand/left_pinky_touch_link.STL" />
    <mesh name="revo2_right_hand_right_base_link" content_type="model/stl" file="revo2_right_hand/right_base_link.STL" />
    <mesh name="revo2_right_hand_right_base_visual_link" content_type="model/stl" file="revo2_right_hand/right_base_visual_link.STL" />
    <mesh name="revo2_right_hand_right_thumb_metacarpal_link" content_type="model/stl" file="revo2_right_hand/right_thumb_metacarpal_link.STL" />
    <mesh name="revo2_right_hand_right_thumb_proximal_visual_link" content_type="model/stl" file="revo2_right_hand/right_thumb_proximal_visual_link.STL" />
    <mesh name="revo2_right_hand_right_thumb_proximal_link" content_type="model/stl" file="revo2_right_hand/right_thumb_proximal_link.STL" />
    <mesh name="revo2_right_hand_right_thumb_distal_link" content_type="model/stl" file="revo2_right_hand/right_thumb_distal_link.STL" />
    <mesh name="revo2_right_hand_right_thumb_touch_link" content_type="model/stl" file="revo2_right_hand/right_thumb_touch_link.STL" />
    <mesh name="revo2_right_hand_right_index_proximal_link" content_type="model/stl" file="revo2_right_hand/right_index_proximal_link.STL" />
    <mesh name="revo2_right_hand_right_index_distal_link" content_type="model/stl" file="revo2_right_hand/right_index_distal_link.STL" />
    <mesh name="revo2_right_hand_right_index_touch_link" content_type="model/stl" file="revo2_right_hand/right_index_touch_link.STL" />
    <mesh name="revo2_right_hand_right_middle_proximal_link" content_type="model/stl" file="revo2_right_hand/right_middle_proximal_link.STL" />
    <mesh name="revo2_right_hand_right_middle_distal_link" content_type="model/stl" file="revo2_right_hand/right_middle_distal_link.STL" />
    <mesh name="revo2_right_hand_right_middle_touch_link" content_type="model/stl" file="revo2_right_hand/right_middle_touch_link.STL" />
    <mesh name="revo2_right_hand_right_ring_proximal_link" content_type="model/stl" file="revo2_right_hand/right_ring_proximal_link.STL" />
    <mesh name="revo2_right_hand_right_ring_distal_link" content_type="model/stl" file="revo2_right_hand/right_ring_distal_link.STL" />
    <mesh name="revo2_right_hand_right_ring_touch_link" content_type="model/stl" file="revo2_right_hand/right_ring_touch_link.STL" />
    <mesh name="revo2_right_hand_right_pinky_proximal_link" content_type="model/stl" file="revo2_right_hand/right_pinky_proximal_link.STL" />
    <mesh name="revo2_right_hand_right_pinky_distal_link" content_type="model/stl" file="revo2_right_hand/right_pinky_distal_link.STL" />
    <mesh name="revo2_right_hand_right_pinky_touch_link" content_type="model/stl" file="revo2_right_hand/right_pinky_touch_link.STL" />
  </asset>
  <worldbody>
    <geom name="ground" size="0 0 0.01" type="plane" rgba="0.8 0.8 0.8 1" />
    <body name="Z2_0_Lite_description_0429_1" pos="0.227371 -0.0999644 0.712366" quat="0.0872396 0.0101844 0.0221467 0.995889">
      <inertial pos="2.6e-05 0 0.015586" quat="1 0 0.000453588 0" mass="3.6595" diaginertia="0.013371 0.010889 0.00862" />
      <joint name="floating_base_joint" type="free" />
      <geom name="z2_geom_0" type="mesh" contype="0" conaffinity="0" group="1" material="Z2_0_Lite_description_0429_1_mat" mesh="base_link" />
      <geom name="Z2_0_Lite_description_0429_1_collision_0" type="mesh" contype="0" conaffinity="0" group="3" rgba="0.9373 0.2667 0.2667 1" mesh="base_link" />
      <site name="imu_in_base" pos="0 0 0" />
      <body name="Z2_0_Lite_description_0429_1_waist_yaw_Link" pos="0 0 0.0995">
        <inertial pos="9.86e-05 0 0.010913" quat="0.487825 0.487825 -0.511886 0.511886" mass="0.19414" diaginertia="0.000183121 0.000130679 0.00011203" />
        <joint name="Z2_0_Lite_description_0429_1_waist_yaw_joint" pos="0 0 0" axis="0 0 1" ref="-0.176373" limited="true" range="-3.14 3.14" armature="0.0101775" />
        <geom name="z2_geom_2" type="mesh" contype="0" conaffinity="0" group="1" material="Z2_0_Lite_description_0429_1_waist_yaw_Link_mat" mesh="waist_yaw_Link" />
        <geom name="waist_yaw_Link_collision_0" type="mesh" contype="0" conaffinity="0" group="3" rgba="0.9373 0.2667 0.2667 1" mesh="waist_yaw_Link" />
        <body name="Z2_0_Lite_description_0429_1_waist_pitch_Link" pos="0 0 0.0325">
          <inertial pos="0 0 0" mass="0.084721" diaginertia="1.554e-05 8.72e-06 2.237e-05" />
          <joint name="Z2_0_Lite_description_0429_1_waist_pitch_joint" pos="0 0 0" axis="0 1 0" ref="0.00113681" limited="true" range="-0.26 0.43" armature="0.00721945" />
          <geom name="z2_geom_4" type="mesh" contype="0" conaffinity="0" group="1" material="Z2_0_Lite_description_0429_1_waist_pitch_Link_mat" mesh="waist_pitch_Link" />
          <geom name="waist_pitch_Link_collision_0" type="mesh" contype="0" conaffinity="0" group="3" rgba="0.9373 0.2667 0.2667 1" mesh="waist_pitch_Link" />
          <body name="Z2_0_Lite_description_0429_1_waist_roll_Link">
            <inertial pos="0.00440484 -6.599e-05 0.152862" quat="0.999735 0.00273127 0.0228734 7.03459e-06" mass="11.2295" diaginertia="0.0903815 0.0634675 0.0590933" />
            <joint name="Z2_0_Lite_description_0429_1_waist_roll_joint" pos="0 0 0" axis="1 0 0" ref="-0.0662709" limited="true" range="-0.52 0.52" armature="0.00721945" />
            <geom name="z2_geom_6" type="mesh" contype="0" conaffinity="0" group="1" material="Z2_0_Lite_description_0429_1_waist_roll_Link_mat" mesh="waist_roll_Link" />
            <geom name="waist_roll_Link_collision_0" type="mesh" contype="0" conaffinity="0" group="3" rgba="0.9373 0.2667 0.2667 1" mesh="waist_roll_Link" />
            <body name="Z2_0_Lite_description_0429_1_neck_Link" pos="0 0 0.329">
              <inertial pos="0.00361611 -0.00038273 0.0637899" quat="0.99813 -0.00149993 -0.0494903 0.0358587" mass="1.0284" diaginertia="0.00368323 0.00366259 0.00240623" />
              <geom name="z2_geom_8" type="mesh" contype="0" conaffinity="0" group="1" material="Z2_0_Lite_description_0429_1_neck_Link_mat" mesh="neck_Link" />
              <geom name="neck_Link_collision_0" type="mesh" contype="0" conaffinity="0" group="3" rgba="0.9373 0.2667 0.2667 1" mesh="neck_Link" />
            </body>
            <body name="Z2_0_Lite_description_0429_1_R_shoulder_pitch_Link" pos="0 -0.12262 0.22437" quat="0.991445 -0.130527 0 0">
              <inertial pos="0.0030433 -0.046415 -0.0078645" quat="0.391968 0.223894 -0.52375 0.722439" mass="0.61036" diaginertia="0.000497837 0.0004795 0.000396913" />
              <joint name="Z2_0_Lite_description_0429_1_R_shoulder_pitch_joint" pos="0 0 0" axis="0 1 0" ref="0.048231" limited="true" range="-3.14 3.14" armature="0.00360972" />
              <geom name="z2_geom_10" type="mesh" contype="0" conaffinity="0" group="1" material="Z2_0_Lite_description_0429_1_R_shoulder_pitch_Link_mat" mesh="R_shoulder_pitch_Link" />
              <geom name="R_shoulder_pitch_Link_collision_0" type="mesh" contype="0" conaffinity="0" group="3" rgba="0.9373 0.2667 0.2667 1" mesh="R_shoulder_pitch_Link" />
              <body name="Z2_0_Lite_description_0429_1_R_shoulder_roll_Link" pos="0 -0.052 -0.01" quat="0.991445 0.130527 0 0">
                <inertial pos="0.0003492 -0.0028489 -0.038097" quat="0.707945 0.000321853 0.00358553 0.706259" mass="0.22592" diaginertia="0.000381223 0.000288001 0.000244796" />
                <joint name="Z2_0_Lite_description_0429_1_R_shoulder_roll_joint" pos="0 0 0" axis="1 0 0" ref="-0.20345" limited="true" range="-2.09 0.26" armature="0.00360972" />
                <geom name="z2_geom_12" type="mesh" contype="0" conaffinity="0" group="1" material="Z2_0_Lite_description_0429_1_R_shoulder_roll_Link_mat" mesh="R_shoulder_roll_Link" />
                <geom name="R_shoulder_roll_Link_collision_0" type="mesh" contype="0" conaffinity="0" group="3" rgba="0.9373 0.2667 0.2667 1" mesh="R_shoulder_roll_Link" />
                <body name="Z2_0_Lite_description_0429_1_R_shoulder_yaw_Link" pos="0 0 -0.075">
                  <inertial pos="0.0046034 -0.000625 -0.075726" quat="0.420541 0.0507711 0.0161789 0.905707" mass="1.0841" diaginertia="0.00293483 0.00292089 0.000604358" />
                  <joint name="Z2_0_Lite_description_0429_1_R_shoulder_yaw_joint" pos="0 0 0" axis="0 0 1" ref="0.317077" limited="true" range="-3.14 3.14" armature="0.00360972" />
                  <geom name="z2_geom_14" type="mesh" contype="0" conaffinity="0" group="1" material="Z2_0_Lite_description_0429_1_R_shoulder_yaw_Link_mat" mesh="R_shoulder_yaw_Link" />
                  <geom name="R_shoulder_yaw_Link_collision_0" type="mesh" contype="0" conaffinity="0" group="3" rgba="0.9373 0.2667 0.2667 1" mesh="R_shoulder_yaw_Link" />
                  <body name="Z2_0_Lite_description_0429_1_R_elbow_Link" pos="0.01 0 -0.123">
                    <inertial pos="0.063477 -0.0003999 0" quat="0.0291393 0.706506 -0.0291393 0.706506" mass="0.61836" diaginertia="0.00066201 0.000596102 0.000404068" />
                    <joint name="Z2_0_Lite_description_0429_1_R_elbow_joint" pos="0 0 0" axis="0 1 0" ref="1.0567" limited="true" range="-0.52 3.14" armature="0.00360972" />
                    <geom name="z2_geom_16" type="mesh" contype="0" conaffinity="0" group="1" material="Z2_0_Lite_description_0429_1_R_elbow_Link_mat" mesh="R_elbow_Link" />
                    <geom name="R_elbow_Link_collision_0" type="mesh" contype="0" conaffinity="0" group="3" rgba="0.9373 0.2667 0.2667 1" mesh="R_elbow_Link" />
                    <body name="Z2_0_Lite_description_0429_1_R_wrist_roll_Link" pos="0.1 0 0">
                      <inertial pos="0.015815 0.0015672 0" quat="0.480667 0.518613 -0.480667 0.518613" mass="0.07414" diaginertia="5.756e-05 5.59277e-05 3.19923e-05" />
                      <joint name="Z2_0_Lite_description_0429_1_R_wrist_roll_joint" pos="0 0 0" axis="1 0 0" ref="-0.470866" limited="true" range="-3.14 3.14" armature="0.00360972" />
                      <geom name="z2_geom_18" type="mesh" contype="0" conaffinity="0" group="1" material="Z2_0_Lite_description_0429_1_R_wrist_roll_Link_mat" mesh="R_wrist_roll_Link" />
                      <geom name="R_wrist_roll_Link_collision_0" type="mesh" contype="0" conaffinity="0" group="3" rgba="0.9373 0.2667 0.2667 1" mesh="R_wrist_roll_Link" />
                      <body name="Z2_0_Lite_description_0429_1_R_wrist_pitch_Link" pos="0.035 0 0">
                        <inertial pos="0.023091 0.0008013 0.0007039" quat="0.579943 0.374283 0.613256 0.384052" mass="0.47133" diaginertia="0.000418049 0.000416617 0.000183144" />
                        <joint name="Z2_0_Lite_description_0429_1_R_wrist_pitch_joint" pos="0 0 0" axis="0 1 0" ref="0.180394" limited="true" range="-1.57 1.57" armature="0.00425" />
                        <geom name="z2_geom_20" type="mesh" contype="0" conaffinity="0" group="1" material="Z2_0_Lite_description_0429_1_R_wrist_pitch_Link_mat" mesh="R_wrist_pitch_Link" />
                        <geom name="R_wrist_pitch_Link_collision_0" type="mesh" contype="0" conaffinity="0" group="3" rgba="0.9373 0.2667 0.2667 1" mesh="R_wrist_pitch_Link" />
                        <body name="Z2_0_Lite_description_0429_1_R_wrist_yaw_Link" pos="0.046 0 0">
                          <inertial pos="0.018433 0 -0.0005558" quat="0.707106 0.000875558 0.000875558 0.707106" mass="0.05797" diaginertia="4.912e-05 4.27601e-05 2.25699e-05" />
                          <joint name="Z2_0_Lite_description_0429_1_R_wrist_yaw_joint" pos="0 0 0" axis="0 0 1" ref="0.121869" limited="true" range="-1.57 1.57" armature="0.00425" />
                          <geom name="z2_geom_22" type="mesh" contype="0" conaffinity="0" group="1" material="Z2_0_Lite_description_0429_1_R_wrist_yaw_Link_mat" mesh="R_wrist_yaw_Link" />
                          <geom name="R_wrist_yaw_Link_collision_0" type="mesh" contype="0" conaffinity="0" group="3" rgba="0.9373 0.2667 0.2667 1" mesh="R_wrist_yaw_Link" />
                          <body name="revo2_right_hand" pos="0.045 0 0" quat="0.5 0.5 0.5 0.5">
                            <inertial pos="-0.0052438 -0.0034038 0.0521267" quat="0.996653 -0.0816472 -0.00355804 0.00206923" mass="0.238" diaginertia="2.1092e-05 1.46428e-05 7.81666e-06" />
                            <geom name="z2_geom_24" type="mesh" contype="0" conaffinity="0" group="1" material="revo2_right_hand_mat" mesh="revo2_right_hand_right_base_link" />
                            <geom name="z2_geom_25" type="mesh" contype="0" conaffinity="0" group="1" material="revo2_right_hand_mat_2" mesh="revo2_right_hand_right_base_visual_link" />
                            <geom name="revo2_right_hand_collision_0" type="mesh" contype="0" conaffinity="0" group="3" rgba="0.9373 0.2667 0.2667 1" mesh="revo2_right_hand_right_base_link" />
                            <body name="revo2_right_hand_right_thumb_metacarpal_link" pos="0.005619 0.019867 0.027825" quat="0.99648 0 0 -0.0838365">
                              <inertial pos="1.51e-05 0.0070724 -0.0042085" quat="0.465398 -0.0302755 0.0586241 0.882639" mass="0.01" diaginertia="1.661e-07 1.55965e-07 4.94348e-08" />
                              <joint name="revo2_right_hand_right_thumb_metacarpal_joint" pos="0 0 0" axis="0 0 -1" limited="true" range="0 1.57" />
                              <geom name="z2_geom_27" type="mesh" contype="0" conaffinity="0" group="1" material="revo2_right_hand_right_thumb_metacarpal_link_mat" mesh="revo2_right_hand_right_thumb_metacarpal_link" />
                              <geom name="revo2_right_hand_right_thumb_metacarpal_link_collision_0" type="mesh" contype="0" conaffinity="0" group="3" rgba="0.9373 0.2667 0.2667 1" mesh="revo2_right_hand_right_thumb_metacarpal_link" />
                              <body name="revo2_right_hand_right_thumb_proximal_link" pos="0 0.014227 0" quat="0.986557 0.0765206 0.124804 0.0726253">
                                <inertial pos="-5e-07 0.0277015 -0.0020266" quat="0.49648 0.5035 -0.503522 0.496449" mass="0.05" diaginertia="2.56291e-06 2.4045e-06 5.11893e-07" />
                                <joint name="revo2_right_hand_right_thumb_proximal_joint" pos="0 0 0" axis="1 0 0" limited="true" range="0 1.03" />
                                <geom name="z2_geom_29" type="mesh" contype="0" conaffinity="0" group="1" material="revo2_right_hand_right_thumb_proximal_link_mat" mesh="revo2_right_hand_right_thumb_proximal_visual_link" />
                                <geom name="revo2_right_hand_right_thumb_proximal_link_collision_0" type="mesh" contype="0" conaffinity="0" group="3" rgba="0.9373 0.2667 0.2667 1" mesh="revo2_right_hand_right_thumb_proximal_link" />
                                <body name="revo2_right_hand_right_thumb_distal_link" pos="0 0.052 0">
                                  <inertial pos="0 0.0117545 1.13e-05" quat="0.528551 0.469717 -0.469717 0.528551" mass="0.01" diaginertia="2.21079e-07 1.678e-07 1.13921e-07" />
                                  <joint name="revo2_right_hand_right_thumb_distal_joint" pos="0 0 0" axis="1 0 0" limited="true" range="0 1.03" />
                                  <geom name="z2_geom_31" type="mesh" contype="0" conaffinity="0" group="1" material="revo2_right_hand_right_thumb_distal_link_mat" mesh="revo2_right_hand_right_thumb_distal_link" />
                                  <geom name="revo2_right_hand_right_thumb_distal_link_collision_0" type="mesh" contype="0" conaffinity="0" group="3" rgba="0.9373 0.2667 0.2667 1" mesh="revo2_right_hand_right_thumb_distal_link" />
                                  <body name="revo2_right_hand_right_thumb_tip_link" pos="0 0.0265288 -0.0017734" quat="0.999443 -0.033369 0 0" />
                                  <body name="revo2_right_hand_right_thumb_touch_link" pos="0 0.0137928 0.0076766" quat="0.999443 -0.033369 0 0">
                                    <inertial pos="0 -0.0015225 -0.0077842" quat="0.512687 0.486983 -0.486983 0.512687" mass="0.002" diaginertia="2.21083e-07 1.678e-07 1.13917e-07" />
                                    <geom name="z2_geom_33" type="mesh" contype="0" conaffinity="0" group="1" material="revo2_right_hand_right_thumb_touch_link_mat" mesh="revo2_right_hand_right_thumb_touch_link" />
                                    <geom name="revo2_right_hand_right_thumb_touch_link_collision_0" type="mesh" contype="0" conaffinity="0" group="3" rgba="0.9373 0.2667 0.2667 1" mesh="revo2_right_hand_right_thumb_touch_link" />
                                  </body>
                                </body>
                              </body>
                            </body>
                            <body name="revo2_right_hand_right_index_proximal_link" pos="-0.0021181 0.029568 0.080876" quat="0.992147 -0.0522807 0.0783652 -0.0822789">
                              <inertial pos="-0.002235 3.2e-06 0.0176402" quat="0.999798 0.000690273 0.0200939 -0.000268916" mass="0.009" diaginertia="2.52157e-07 2.364e-07 9.27424e-08" />
                              <joint name="revo2_right_hand_right_index_proximal_joint" pos="0 0 0" axis="0 1 0" limited="true" range="0 1.41" />
                              <geom name="z2_geom_35" type="mesh" contype="0" conaffinity="0" group="1" material="revo2_right_hand_right_index_proximal_link_mat" mesh="revo2_right_hand_right_index_proximal_link" />
                              <geom name="revo2_right_hand_right_index_proximal_link_collision_0" type="mesh" contype="0" conaffinity="0" group="3" rgba="0.9373 0.2667 0.2667 1" mesh="revo2_right_hand_right_index_proximal_link" />
                              <body name="revo2_right_hand_right_index_distal_link" pos="0 0 0.032">
                                <inertial pos="0.0033017 2e-07 0.0142077" quat="0.988295 0 0.152555 0" mass="0.009" diaginertia="3.67673e-07 3.622e-07 6.33274e-08" />
                                <joint name="revo2_right_hand_right_index_distal_joint" pos="0 0 0" axis="0 1 0" limited="true" range="0 1.63" />
                                <geom name="z2_geom_37" type="mesh" contype="0" conaffinity="0" group="1" material="revo2_right_hand_right_index_distal_link_mat" mesh="revo2_right_hand_right_index_distal_link" />
                                <geom name="revo2_right_hand_right_index_distal_link_collision_0" type="mesh" contype="0" conaffinity="0" group="3" rgba="0.9373 0.2667 0.2667 1" mesh="revo2_right_hand_right_index_distal_link" />
                                <body name="revo2_right_hand_right_index_tip_link" pos="0.011097 0 0.035739" quat="0.971859 0 0.235565 0" />
                                <body name="revo2_right_hand_right_index_touch_link" pos="0.014497 0 0.023303" quat="0.6361 0.734769 0.154182 -0.178098">
                                  <inertial pos="-0.0029991 0.0024974 -0.0003615" quat="0.741174 0.648762 0.129722 0.113757" mass="0.002" diaginertia="7.34692e-09 5.44018e-09 2.61291e-09" />
                                  <geom name="z2_geom_39" type="mesh" contype="0" conaffinity="0" group="1" material="revo2_right_hand_right_index_touch_link_mat" mesh="revo2_right_hand_right_index_touch_link" />
                                  <geom name="revo2_right_hand_right_index_touch_link_collision_0" type="mesh" contype="0" conaffinity="0" group="3" rgba="0.9373 0.2667 0.2667 1" mesh="revo2_right_hand_right_index_touch_link" />
                                </body>
                              </body>
                            </body>
                            <body name="revo2_right_hand_right_middle_proximal_link" pos="-0.0045767 0.010051 0.084993" quat="0.996681 -0.0175235 0.0746069 -0.0274369">
                              <inertial pos="-0.0022251 5.3e-06 0.0203008" quat="0.999816 0.000614933 0.019192 -0.000401458" mass="0.009" diaginertia="3.67376e-07 3.526e-07 1.11823e-07" />
                              <joint name="revo2_right_hand_right_middle_proximal_joint" pos="0 0 0" axis="0 1 0" limited="true" range="0 1.41" />
                              <geom name="z2_geom_41" type="mesh" contype="0" conaffinity="0" group="1" material="revo2_right_hand_right_middle_proximal_link_mat" mesh="revo2_right_hand_right_middle_proximal_link" />
                              <geom name="revo2_right_hand_right_middle_proximal_link_collision_0" type="mesh" contype="0" conaffinity="0" group="3" rgba="0.9373 0.2667 0.2667 1" mesh="revo2_right_hand_right_middle_proximal_link" />
                              <body name="revo2_right_hand_right_middle_distal_link" pos="0 0 0.037">
                                <inertial pos="0.0040082 0 0.0164974" quat="0.988308 0 0.152472 0" mass="0.009" diaginertia="5.55776e-07 5.498e-07 8.04241e-08" />
                                <joint name="revo2_right_hand_right_middle_distal_joint" pos="0 0 0" axis="0 1 0" limited="true" range="0 1.63" />
                                <geom name="z2_geom_43" type="mesh" contype="0" conaffinity="0" group="1" material="revo2_right_hand_right_middle_distal_link_mat" mesh="revo2_right_hand_right_middle_distal_link" />
                                <geom name="revo2_right_hand_right_middle_distal_link_collision_0" type="mesh" contype="0" conaffinity="0" group="3" rgba="0.9373 0.2667 0.2667 1" mesh="revo2_right_hand_right_middle_distal_link" />
                                <body name="revo2_right_hand_right_middle_tip_link" pos="0.012558 0 0.040442" quat="0.971859 0 0.235565 0" />
                                <body name="revo2_right_hand_right_middle_touch_link" pos="0.0159759 0 0.0265894" quat="0.971858 0 0.235566 0">
                                  <inertial pos="-0.0031929 0 0.0029786" quat="0.985258 0 -0.171072 0" mass="0.002" diaginertia="1.08235e-08 8.2e-09 3.57647e-09" />
                                  <geom name="z2_geom_45" type="mesh" contype="0" conaffinity="0" group="1" material="revo2_right_hand_right_middle_touch_link_mat" mesh="revo2_right_hand_right_middle_touch_link" />
                                  <geom name="revo2_right_hand_right_middle_touch_link_collision_0" type="mesh" contype="0" conaffinity="0" group="3" rgba="0.9373 0.2667 0.2667 1" mesh="revo2_right_hand_right_middle_touch_link" />
                                </body>
                              </body>
                            </body>
                            <body name="revo2_right_hand_right_ring_proximal_link" pos="-0.0046709 -0.010037 0.083982" quat="0.996722 0.0175386 0.0740633 0.0274276">
                              <inertial pos="-0.0023449 5.9e-06 0.0191774" quat="0.999831 0.000506341 0.0183536 -0.000226672" mass="0.009" diaginertia="3.14486e-07 2.976e-07 1.01813e-07" />
                              <joint name="revo2_right_hand_right_ring_proximal_joint" pos="0 0 0" axis="0 1 0" limited="true" range="0 1.41" />
                              <geom name="z2_geom_47" type="mesh" contype="0" conaffinity="0" group="1" material="revo2_right_hand_right_ring_proximal_link_mat" mesh="revo2_right_hand_right_ring_proximal_link" />
                              <geom name="revo2_right_hand_right_ring_proximal_link_collision_0" type="mesh" contype="0" conaffinity="0" group="3" rgba="0.9373 0.2667 0.2667 1" mesh="revo2_right_hand_right_ring_proximal_link" />
                              <body name="revo2_right_hand_right_ring_distal_link" pos="0 0 0.035">
                                <inertial pos="0.0038246 1e-07 0.0160344" quat="0.988037 0 0.154218 0" mass="0.009" diaginertia="5.12404e-07 5.061e-07 7.51962e-08" />
                                <joint name="revo2_right_hand_right_ring_distal_joint" pos="0 0 0" axis="0 1 0" limited="true" range="0 1.63" />
                                <geom name="z2_geom_49" type="mesh" contype="0" conaffinity="0" group="1" material="revo2_right_hand_right_ring_distal_link_mat" mesh="revo2_right_hand_right_ring_distal_link" />
                                <geom name="revo2_right_hand_right_ring_distal_link_collision_0" type="mesh" contype="0" conaffinity="0" group="3" rgba="0.9373 0.2667 0.2667 1" mesh="revo2_right_hand_right_ring_distal_link" />
                                <body name="revo2_right_hand_right_ring_tip_link" pos="0.012266 0 0.039501" quat="0.971859 0 0.235565 0" />
                                <body name="revo2_right_hand_right_ring_touch_link" pos="0.0154392 0 0.0260561" quat="0.971858 0 0.235566 0">
                                  <inertial pos="-0.0030235 0 0.0030408" quat="0.986252 0 -0.16525 0" mass="0.002" diaginertia="8.82062e-09 6.6e-09 2.97938e-09" />
                                  <geom name="z2_geom_51" type="mesh" contype="0" conaffinity="0" group="1" material="revo2_right_hand_right_ring_touch_link_mat" mesh="revo2_right_hand_right_ring_touch_link" />
                                  <geom name="revo2_right_hand_right_ring_touch_link_collision_0" type="mesh" contype="0" conaffinity="0" group="3" rgba="0.9373 0.2667 0.2667 1" mesh="revo2_right_hand_right_ring_touch_link" />
                                </body>
                              </body>
                            </body>
                            <body name="revo2_right_hand_right_pinky_proximal_link" pos="-0.0023566 -0.029366 0.078694" quat="0.992245 0.052387 0.0771065 0.0822136">
                              <inertial pos="-0.0021321 7.8e-06 0.0160672" quat="0.999802 0.000497084 0.0198874 -0.000135892" mass="0.009" diaginertia="1.97783e-07 1.82e-07 8.20168e-08" />
                              <joint name="revo2_right_hand_right_pinky_proximal_joint" pos="0 0 0" axis="0 1 0" limited="true" range="0 1.41" />
                              <geom name="z2_geom_53" type="mesh" contype="0" conaffinity="0" group="1" material="revo2_right_hand_right_pinky_proximal_link_mat" mesh="revo2_right_hand_right_pinky_proximal_link" />
                              <geom name="revo2_right_hand_right_pinky_proximal_link_collision_0" type="mesh" contype="0" conaffinity="0" group="3" rgba="0.9373 0.2667 0.2667 1" mesh="revo2_right_hand_right_pinky_proximal_link" />
                              <body name="revo2_right_hand_right_pinky_distal_link" pos="0 0 0.029">
                                <inertial pos="0.0030797 -2e-07 0.0130247" quat="0.9883 0 0.152523 0" mass="0.009" diaginertia="2.91316e-07 2.853e-07 5.78838e-08" />
                                <joint name="revo2_right_hand_right_pinky_distal_joint" pos="0 0 0" axis="0 1 0" limited="true" range="0 1.63" />
                                <geom name="z2_geom_55" type="mesh" contype="0" conaffinity="0" group="1" material="revo2_right_hand_right_pinky_distal_link_mat" mesh="revo2_right_hand_right_pinky_distal_link" />
                                <geom name="revo2_right_hand_right_pinky_distal_link_collision_0" type="mesh" contype="0" conaffinity="0" group="3" rgba="0.9373 0.2667 0.2667 1" mesh="revo2_right_hand_right_pinky_distal_link" />
                                <body name="revo2_right_hand_right_pinky_tip_link" pos="0.010221 0 0.032918" quat="0.971859 0 0.235565 0" />
                                <body name="revo2_right_hand_right_pinky_touch_link" pos="0.01401 0 0.021124" quat="0.971859 0 0.235565 0">
                                  <inertial pos="-0.0028914 -2e-07 0.0016539" quat="0.986375 0 -0.16451 0" mass="0.002" diaginertia="7.38035e-09 5.3e-09 2.81965e-09" />
                                  <geom name="z2_geom_57" type="mesh" contype="0" conaffinity="0" group="1" material="revo2_right_hand_right_pinky_touch_link_mat" mesh="revo2_right_hand_right_pinky_touch_link" />
                                  <geom name="revo2_right_hand_right_pinky_touch_link_collision_0" type="mesh" contype="0" conaffinity="0" group="3" rgba="0.9373 0.2667 0.2667 1" mesh="revo2_right_hand_right_pinky_touch_link" />
                                </body>
                              </body>
                            </body>
                          </body>
                        </body>
                      </body>
                    </body>
                  </body>
                </body>
              </body>
            </body>
            <body name="Z2_0_Lite_description_0429_1_L_shoulder_pitch_Link" pos="0 0.12262 0.22437" quat="0.991445 0.130527 0 0">
              <inertial pos="0.0030433 0.046415 -0.0078645" quat="0.223829 0.391888 -0.722494 0.523762" mass="0.61036" diaginertia="0.000497842 0.000479506 0.000396922" />
              <joint name="Z2_0_Lite_description_0429_1_L_shoulder_pitch_joint" pos="0 0 0" axis="0 1 0" ref="0.106209" limited="true" range="-3.14 3.14" armature="0.00360972" />
              <geom name="z2_geom_59" type="mesh" contype="0" conaffinity="0" group="1" material="Z2_0_Lite_description_0429_1_L_shoulder_pitch_Link_mat" mesh="L_shoulder_pitch_Link" />
              <geom name="L_shoulder_pitch_Link_collision_0" type="mesh" contype="0" conaffinity="0" group="3" rgba="0.9373 0.2667 0.2667 1" mesh="L_shoulder_pitch_Link" />
              <body name="Z2_0_Lite_description_0429_1_L_shoulder_roll_Link" pos="0 0.052 -0.01" quat="0.991445 -0.130527 0 0">
                <inertial pos="0.0003486 0.0028486 -0.038097" quat="0.706221 0.00358502 0.000321426 0.707983" mass="0.22592" diaginertia="0.000381223 0.000288001 0.000244796" />
                <joint name="Z2_0_Lite_description_0429_1_L_shoulder_roll_joint" pos="0 0 0" axis="1 0 0" ref="0.216886" limited="true" range="-0.26 2.09" armature="0.00360972" />
                <geom name="z2_geom_61" type="mesh" contype="0" conaffinity="0" group="1" material="Z2_0_Lite_description_0429_1_L_shoulder_roll_Link_mat" mesh="L_shoulder_roll_Link" />
                <geom name="L_shoulder_roll_Link_collision_0" type="mesh" contype="0" conaffinity="0" group="3" rgba="0.9373 0.2667 0.2667 1" mesh="L_shoulder_roll_Link" />
                <body name="Z2_0_Lite_description_0429_1_L_shoulder_yaw_Link" pos="0 0 -0.075">
                  <inertial pos="0.0045614 0.0005825 -0.075662" quat="0.896636 0.0174351 0.0499332 0.439599" mass="1.08409" diaginertia="0.00293371 0.00292243 0.000603321" />
                  <joint name="Z2_0_Lite_description_0429_1_L_shoulder_yaw_joint" pos="0 0 0" axis="0 0 1" ref="-0.334502" limited="true" range="-3.14 3.14" armature="0.00360972" />
                  <geom name="z2_geom_63" type="mesh" contype="0" conaffinity="0" group="1" material="Z2_0_Lite_description_0429_1_L_shoulder_yaw_Link_mat" mesh="L_shoulder_yaw_Link" />
                  <geom name="L_shoulder_yaw_Link_collision_0" type="mesh" contype="0" conaffinity="0" group="3" rgba="0.9373 0.2667 0.2667 1" mesh="L_shoulder_yaw_Link" />
                  <body name="Z2_0_Lite_description_0429_1_L_elbow_Link" pos="0.01 0 -0.123">
                    <inertial pos="0.063477 0.0003999 0" quat="-0.0291393 0.706506 0.0291393 0.706506" mass="0.61836" diaginertia="0.00066201 0.000596102 0.000404068" />
                    <joint name="Z2_0_Lite_description_0429_1_L_elbow_joint" pos="0 0 0" axis="0 1 0" ref="0.965831" limited="true" range="-0.52 3.14" armature="0.00360972" />
                    <geom name="z2_geom_65" type="mesh" contype="0" conaffinity="0" group="1" material="Z2_0_Lite_description_0429_1_L_elbow_Link_mat" mesh="L_elbow_Link" />
                    <geom name="L_elbow_Link_collision_0" type="mesh" contype="0" conaffinity="0" group="3" rgba="0.9373 0.2667 0.2667 1" mesh="L_elbow_Link" />
                    <body name="Z2_0_Lite_description_0429_1_L_wrist_roll_Link" pos="0.1 0 0">
                      <inertial pos="0.015815 -0.0015672 0" quat="0.518613 0.480667 -0.518613 0.480667" mass="0.07414" diaginertia="5.756e-05 5.59277e-05 3.19923e-05" />
                      <joint name="Z2_0_Lite_description_0429_1_L_wrist_roll_joint" pos="0 0 0" axis="1 0 0" ref="0.422764" limited="true" range="-3.14 3.14" armature="0.00360972" />
                      <geom name="z2_geom_67" type="mesh" contype="0" conaffinity="0" group="1" material="Z2_0_Lite_description_0429_1_L_wrist_roll_Link_mat" mesh="L_wrist_roll_Link" />
                      <geom name="L_wrist_roll_Link_collision_0" type="mesh" contype="0" conaffinity="0" group="3" rgba="0.9373 0.2667 0.2667 1" mesh="L_wrist_roll_Link" />
                      <body name="Z2_0_Lite_description_0429_1_L_wrist_pitch_Link" pos="0.035 0 0">
                        <inertial pos="0.023083 -0.0007916 0.0007035" quat="0.38431 0.612956 0.374786 0.579764" mass="0.47133" diaginertia="0.000418035 0.000416634 0.000183271" />
                        <joint name="Z2_0_Lite_description_0429_1_L_wrist_pitch_joint" pos="0 0 0" axis="0 1 0" ref="0.0946755" limited="true" range="-1.57 1.57" armature="0.00425" />
                        <geom name="z2_geom_69" type="mesh" contype="0" conaffinity="0" group="1" material="Z2_0_Lite_description_0429_1_L_wrist_pitch_Link_mat" mesh="L_wrist_pitch_Link" />
                        <geom name="L_wrist_pitch_Link_collision_0" type="mesh" contype="0" conaffinity="0" group="3" rgba="0.9373 0.2667 0.2667 1" mesh="L_wrist_pitch_Link" />
                        <body name="Z2_0_Lite_description_0429_1_L_wrist_yaw_Link" pos="0.046 0 0">
                          <inertial pos="0.018433 0 -0.0005558" quat="0.707106 0.000875558 0.000875558 0.707106" mass="0.05797" diaginertia="4.912e-05 4.27601e-05 2.25699e-05" />
                          <joint name="Z2_0_Lite_description_0429_1_L_wrist_yaw_joint" pos="0 0 0" axis="0 0 1" ref="-0.0687684" limited="true" range="-1.57 1.57" armature="0.00425" />
                          <geom name="z2_geom_71" type="mesh" contype="0" conaffinity="0" group="1" material="Z2_0_Lite_description_0429_1_L_wrist_yaw_Link_mat" mesh="L_wrist_yaw_Link" />
                          <geom name="L_wrist_yaw_Link_collision_0" type="mesh" contype="0" conaffinity="0" group="3" rgba="0.9373 0.2667 0.2667 1" mesh="L_wrist_yaw_Link" />
                          <body name="revo2_left_hand" pos="0.045 0 0" quat="0.5 -0.5 0.5 -0.5">
                            <inertial pos="-0.0052625 0.0033926 0.0521379" quat="0.996626 0.0819695 -0.00350097 -0.00211806" mass="0.238" diaginertia="2.1091e-05 1.46412e-05 7.81496e-06" />
                            <geom name="z2_geom_73" type="mesh" contype="0" conaffinity="0" group="1" material="revo2_left_hand_mat" mesh="revo2_left_hand_left_base_link" />
                            <geom name="z2_geom_74" type="mesh" contype="0" conaffinity="0" group="1" material="revo2_left_hand_mat_2" mesh="revo2_left_hand_left_base_visual_link" />
                            <geom name="revo2_left_hand_collision_0" type="mesh" contype="0" conaffinity="0" group="3" rgba="0.9373 0.2667 0.2667 1" mesh="revo2_left_hand_left_base_link" />
                            <body name="revo2_left_hand_left_thumb_metacarpal_link" pos="0.0045 -0.019 0.027825" quat="0.99648 0 0 0.0838365">
                              <inertial pos="1.52e-05 -0.0070724 -0.0042084" quat="0.882639 0.0586241 -0.0302755 0.465398" mass="0.01" diaginertia="1.661e-07 1.55965e-07 4.94348e-08" />
                              <joint name="revo2_left_hand_left_thumb_metacarpal_joint" pos="0 0 0" axis="0 0 1" limited="true" range="0 1.57" />
                              <geom name="z2_geom_76" type="mesh" contype="0" conaffinity="0" group="1" material="revo2_left_hand_left_thumb_metacarpal_link_mat" mesh="revo2_left_hand_left_thumb_metacarpal_link" />
                              <geom name="revo2_left_hand_left_thumb_metacarpal_link_collision_0" type="mesh" contype="0" conaffinity="0" group="3" rgba="0.9373 0.2667 0.2667 1" mesh="revo2_left_hand_left_thumb_metacarpal_link" />
                              <body name="revo2_left_hand_left_thumb_proximal_link" pos="0 -0.014227 0" quat="0.986557 -0.0765206 0.124804 -0.0726253">
                                <inertial pos="-4e-07 -0.0277016 -0.0020267" quat="0.503489 0.496496 -0.496434 0.503532" mass="0.05" diaginertia="2.56301e-06 2.4045e-06 5.11893e-07" />
                                <joint name="revo2_left_hand_left_thumb_proximal_joint" pos="0 0 0" axis="-1 0 0" limited="true" range="0 1.03" />
                                <geom name="z2_geom_78" type="mesh" contype="0" conaffinity="0" group="1" material="revo2_left_hand_left_thumb_proximal_link_mat" mesh="revo2_left_hand_left_thumb_proximal_link" />
                                <geom name="z2_geom_79" type="mesh" contype="0" conaffinity="0" group="1" material="revo2_left_hand_left_thumb_proximal_link_mat_2" mesh="revo2_left_hand_left_thumb_proximal_visual_link" />
                                <geom name="revo2_left_hand_left_thumb_proximal_link_collision_0" type="mesh" contype="0" conaffinity="0" group="3" rgba="0.9373 0.2667 0.2667 1" mesh="revo2_left_hand_left_thumb_proximal_link" />
                                <body name="revo2_left_hand_left_thumb_distal_link" pos="0 -0.052 0">
                                  <inertial pos="2e-07 -0.0117551 1.14e-05" quat="0.469717 0.528551 -0.528551 0.469717" mass="0.01" diaginertia="2.21079e-07 1.678e-07 1.13921e-07" />
                                  <joint name="revo2_left_hand_left_thumb_distal_joint" pos="0 0 0" axis="-1 0 0" limited="true" range="0 1.03" />
                                  <geom name="z2_geom_81" type="mesh" contype="0" conaffinity="0" group="1" material="revo2_left_hand_left_thumb_distal_link_mat" mesh="revo2_left_hand_left_thumb_distal_link" />
                                  <geom name="revo2_left_hand_left_thumb_distal_link_collision_0" type="mesh" contype="0" conaffinity="0" group="3" rgba="0.9373 0.2667 0.2667 1" mesh="revo2_left_hand_left_thumb_distal_link" />
                                  <body name="revo2_left_hand_left_thumb_tip_link" pos="0 -0.026529 -0.0017734" quat="0.999443 0.0333688 0 0" />
                                  <body name="revo2_left_hand_left_thumb_touch_link" pos="0 -0.013836 0.0076686" quat="0.99618 0.0873286 0 0">
                                    <inertial pos="1e-07 0.0007172 -0.0079025" quat="0.514052 0.485542 -0.485542 0.514052" mass="0.002" diaginertia="2.21048e-07 1.678e-07 1.13852e-07" />
                                    <geom name="z2_geom_83" type="mesh" contype="0" conaffinity="0" group="1" material="revo2_left_hand_left_thumb_touch_link_mat" mesh="revo2_left_hand_left_thumb_touch_link" />
                                    <geom name="revo2_left_hand_left_thumb_touch_link_collision_0" type="mesh" contype="0" conaffinity="0" group="3" rgba="0.9373 0.2667 0.2667 1" mesh="revo2_left_hand_left_thumb_touch_link" />
                                  </body>
                                </body>
                              </body>
                            </body>
                            <body name="revo2_left_hand_left_index_proximal_link" pos="-0.0021349 -0.029578 0.080876" quat="0.992147 0.0522807 0.0783652 0.0822789">
                              <inertial pos="-0.0022354 -3.8e-06 0.0176439" quat="0.999798 -0.000690789 0.0200939 0.000267318" mass="0.009" diaginertia="2.52157e-07 2.363e-07 9.27424e-08" />
                              <joint name="revo2_left_hand_left_index_proximal_joint" pos="0 0 0" axis="0 1 0" limited="true" range="0 1.41" />
                              <geom name="z2_geom_85" type="mesh" contype="0" conaffinity="0" group="1" material="revo2_left_hand_left_index_proximal_link_mat" mesh="revo2_left_hand_left_index_proximal_link" />
                              <geom name="revo2_left_hand_left_index_proximal_link_collision_0" type="mesh" contype="0" conaffinity="0" group="3" rgba="0.9373 0.2667 0.2667 1" mesh="revo2_left_hand_left_index_proximal_link" />
                              <body name="revo2_left_hand_left_index_distal_link" pos="0 0 0.032">
                                <inertial pos="0.0033017 1e-07 0.0142076" quat="0.988295 0 0.152555 0" mass="0.009" diaginertia="3.67673e-07 3.622e-07 6.33274e-08" />
                                <joint name="revo2_left_hand_left_index_distal_joint" pos="0 0 0" axis="0 1 0" limited="true" range="0 1.63" />
                                <geom name="z2_geom_87" type="mesh" contype="0" conaffinity="0" group="1" material="revo2_left_hand_left_index_distal_link_mat" mesh="revo2_left_hand_left_index_distal_link" />
                                <geom name="revo2_left_hand_left_index_distal_link_collision_0" type="mesh" contype="0" conaffinity="0" group="3" rgba="0.9373 0.2667 0.2667 1" mesh="revo2_left_hand_left_index_distal_link" />
                                <body name="revo2_left_hand_left_index_tip_link" pos="0.011097 0 0.035739" quat="0.970472 0 0.241213 0" />
                                <body name="revo2_left_hand_left_index_touch_link" pos="0.014497 0 0.023303" quat="0.971859 0 0.235565 0">
                                  <inertial pos="-0.0029992 0 0.0025237" quat="0.984955 0 -0.172813 0" mass="0.002" diaginertia="7.34307e-09 5.4e-09 2.65693e-09" />
                                  <geom name="z2_geom_89" type="mesh" contype="0" conaffinity="0" group="1" material="revo2_left_hand_left_index_touch_link_mat" mesh="revo2_left_hand_left_index_touch_link" />
                                  <geom name="revo2_left_hand_left_index_touch_link_collision_0" type="mesh" contype="0" conaffinity="0" group="3" rgba="0.9373 0.2667 0.2667 1" mesh="revo2_left_hand_left_index_touch_link" />
                                </body>
                              </body>
                            </body>
                            <body name="revo2_left_hand_left_middle_proximal_link" pos="-0.0045935 -0.010061 0.084993" quat="0.996681 0.0175235 0.0746069 0.0274369">
                              <inertial pos="-0.0022242 -3.6e-06 0.020305" quat="0.999815 -0.000615185 0.0191995 0.000401616" mass="0.009" diaginertia="3.67277e-07 3.525e-07 1.11823e-07" />
                              <joint name="revo2_left_hand_left_middle_proximal_joint" pos="0 0 0" axis="0 1 0" limited="true" range="0 1.41" />
                              <geom name="z2_geom_91" type="mesh" contype="0" conaffinity="0" group="1" material="revo2_left_hand_left_middle_proximal_link_mat" mesh="revo2_left_hand_left_middle_proximal_link" />
                              <geom name="revo2_left_hand_left_middle_proximal_link_collision_0" type="mesh" contype="0" conaffinity="0" group="3" rgba="0.9373 0.2667 0.2667 1" mesh="revo2_left_hand_left_middle_proximal_link" />
                              <body name="revo2_left_hand_left_middle_distal_link" pos="0 0 0.037" quat="0.997999 0 0.0632278 0">
                                <inertial pos="0.0018942 0 0.0168711" quat="0.995973 0 0.0896522 0" mass="0.009" diaginertia="5.55655e-07 5.498e-07 8.04448e-08" />
                                <joint name="revo2_left_hand_left_middle_distal_joint" pos="0 0 0" axis="0 1 0" limited="true" range="0 1.63" />
                                <geom name="z2_geom_93" type="mesh" contype="0" conaffinity="0" group="1" material="revo2_left_hand_left_middle_distal_link_mat" mesh="revo2_left_hand_left_middle_distal_link" />
                                <geom name="revo2_left_hand_left_middle_distal_link_collision_0" type="mesh" contype="0" conaffinity="0" group="3" rgba="0.9373 0.2667 0.2667 1" mesh="revo2_left_hand_left_middle_distal_link" />
                                <body name="revo2_left_hand_left_middle_tip_link" pos="0.0073534 0 0.041703" quat="0.984807 0 0.17365 0" />
                                <body name="revo2_left_hand_left_middle_touch_link" pos="0.012493 0 0.028393" quat="0.984807 0 0.17365 0">
                                  <inertial pos="-0.0031929 0 0.0029786" quat="0.985258 0 -0.171072 0" mass="0.002" diaginertia="1.08235e-08 8.2e-09 3.57647e-09" />
                                  <geom name="z2_geom_95" type="mesh" contype="0" conaffinity="0" group="1" material="revo2_left_hand_left_middle_touch_link_mat" mesh="revo2_left_hand_left_middle_touch_link" />
                                  <geom name="revo2_left_hand_left_middle_touch_link_collision_0" type="mesh" contype="0" conaffinity="0" group="3" rgba="0.9373 0.2667 0.2667 1" mesh="revo2_left_hand_left_middle_touch_link" />
                                </body>
                              </body>
                            </body>
                            <body name="revo2_left_hand_left_ring_proximal_link" pos="-0.0046877 0.010026 0.083982" quat="0.996722 -0.0175386 0.0740633 -0.0274276">
                              <inertial pos="-0.0023446 -5.3e-06 0.0191786" quat="0.999831 -0.000506341 0.0183536 0.000226672" mass="0.009" diaginertia="3.14486e-07 2.976e-07 1.01813e-07" />
                              <joint name="revo2_left_hand_left_ring_proximal_joint" pos="0 0 0" axis="0 1 0" limited="true" range="0 1.41" />
                              <geom name="z2_geom_97" type="mesh" contype="0" conaffinity="0" group="1" material="revo2_left_hand_left_ring_proximal_link_mat" mesh="revo2_left_hand_left_ring_proximal_link" />
                              <geom name="revo2_left_hand_left_ring_proximal_link_collision_0" type="mesh" contype="0" conaffinity="0" group="3" rgba="0.9373 0.2667 0.2667 1" mesh="revo2_left_hand_left_ring_proximal_link" />
                              <body name="revo2_left_hand_left_ring_distal_link" pos="0 0 0.035" quat="0.997999 0 0.0632278 0">
                                <inertial pos="0.0017705 1e-07 0.016389" quat="0.995811 0 0.0914316 0" mass="0.009" diaginertia="5.12401e-07 5.061e-07 7.50993e-08" />
                                <joint name="revo2_left_hand_left_ring_distal_joint" pos="0 0 0" axis="0 1 0" limited="true" range="0 1.63" />
                                <geom name="z2_geom_99" type="mesh" contype="0" conaffinity="0" group="1" material="revo2_left_hand_left_ring_distal_link_mat" mesh="revo2_left_hand_left_ring_distal_link" />
                                <geom name="revo2_left_hand_left_ring_distal_link_collision_0" type="mesh" contype="0" conaffinity="0" group="3" rgba="0.9373 0.2667 0.2667 1" mesh="revo2_left_hand_left_ring_distal_link" />
                                <body name="revo2_left_hand_left_ring_tip_link" pos="0.0071824 0 0.040734" quat="0.984807 0 0.17365 0" />
                                <body name="revo2_left_hand_left_ring_touch_link" pos="0.012028 0 0.027796" quat="0.984807 0 0.17365 0">
                                  <inertial pos="-0.0030235 0 0.0030408" quat="0.986252 0 -0.16525 0" mass="0.002" diaginertia="8.82062e-09 6.6e-09 2.97938e-09" />
                                  <geom name="z2_geom_101" type="mesh" contype="0" conaffinity="0" group="1" material="revo2_left_hand_left_ring_touch_link_mat" mesh="revo2_left_hand_left_ring_touch_link" />
                                  <geom name="revo2_left_hand_left_ring_touch_link_collision_0" type="mesh" contype="0" conaffinity="0" group="3" rgba="0.9373 0.2667 0.2667 1" mesh="revo2_left_hand_left_ring_touch_link" />
                                </body>
                              </body>
                            </body>
                            <body name="revo2_left_hand_left_pinky_proximal_link" pos="-0.0023733 0.029356 0.078694" quat="0.992245 -0.052387 0.0771065 -0.0822136">
                              <inertial pos="-0.0021327 -7e-06 0.016068" quat="0.999802 -0.000497084 0.0198874 0.000135892" mass="0.009" diaginertia="1.97783e-07 1.82e-07 8.20168e-08" />
                              <joint name="revo2_left_hand_left_pinky_proximal_joint" pos="0 0 0" axis="0 1 0" limited="true" range="0 1.41" />
                              <geom name="z2_geom_103" type="mesh" contype="0" conaffinity="0" group="1" material="revo2_left_hand_left_pinky_proximal_link_mat" mesh="revo2_left_hand_left_pinky_proximal_link" />
                              <geom name="revo2_left_hand_left_pinky_proximal_link_collision_0" type="mesh" contype="0" conaffinity="0" group="3" rgba="0.9373 0.2667 0.2667 1" mesh="revo2_left_hand_left_pinky_proximal_link" />
                              <body name="revo2_left_hand_left_pinky_distal_link" pos="0 0 0.029">
                                <inertial pos="0.0030795 -1e-07 0.0130239" quat="0.988291 0 0.152583 0" mass="0.009" diaginertia="2.91225e-07 2.852e-07 5.78748e-08" />
                                <joint name="revo2_left_hand_left_pinky_distal_joint" pos="0 0 0" axis="0 1 0" limited="true" range="0 1.63" />
                                <geom name="z2_geom_105" type="mesh" contype="0" conaffinity="0" group="1" material="revo2_left_hand_left_pinky_distal_link_mat" mesh="revo2_left_hand_left_pinky_distal_link" />
                                <geom name="revo2_left_hand_left_pinky_distal_link_collision_0" type="mesh" contype="0" conaffinity="0" group="3" rgba="0.9373 0.2667 0.2667 1" mesh="revo2_left_hand_left_pinky_distal_link" />
                                <body name="revo2_left_hand_left_pinky_tip_link" pos="0.010221 0 0.032918" quat="0.971859 0 0.235565 0" />
                                <body name="revo2_left_hand_left_pinky_touch_link" pos="0.01401 0 0.021124" quat="0.971859 0 0.235565 0">
                                  <inertial pos="-0.0028914 -2e-07 0.0016539" quat="0.986375 0 -0.16451 0" mass="0.002" diaginertia="7.38035e-09 5.3e-09 2.81965e-09" />
                                  <geom name="z2_geom_107" type="mesh" contype="0" conaffinity="0" group="1" material="revo2_left_hand_left_pinky_touch_link_mat" mesh="revo2_left_hand_left_pinky_touch_link" />
                                  <geom name="revo2_left_hand_left_pinky_touch_link_collision_0" type="mesh" contype="0" conaffinity="0" group="3" rgba="0.9373 0.2667 0.2667 1" mesh="revo2_left_hand_left_pinky_touch_link" />
                                </body>
                              </body>
                            </body>
                          </body>
                        </body>
                      </body>
                    </body>
                  </body>
                </body>
              </body>
            </body>
          </body>
        </body>
      </body>
      <body name="Z2_0_Lite_description_0429_1_R_hip_pitch_Link" pos="0 -0.067132 -0.017988" quat="0.991445 0.130527 0 0">
        <inertial pos="-0.0067414 -0.049854 -0.027824" quat="0.960303 0.233226 -0.0546073 0.142978" mass="1.5226" diaginertia="0.00248447 0.00229229 0.00168814" />
        <joint name="Z2_0_Lite_description_0429_1_R_hip_pitch_joint" pos="0 0 0" axis="0 1 0" ref="-0.0293766" limited="true" range="-2.35 2.35" armature="0.0251019" />
        <geom name="z2_geom_109" type="mesh" contype="0" conaffinity="0" group="1" material="Z2_0_Lite_description_0429_1_R_hip_pitch_Link_mat" mesh="R_hip_pitch_Link" />
        <geom name="R_hip_pitch_Link_collision_0" type="mesh" contype="0" conaffinity="0" group="3" rgba="0.9373 0.2667 0.2667 1" mesh="R_hip_pitch_Link" />
        <body name="Z2_0_Lite_description_0429_1_R_hip_roll_Link" pos="0 -0.053575 -0.034315" quat="0.991445 -0.130527 0 0">
          <inertial pos="0.0059886 0 -0.081347" quat="0.972518 0 -0.232827 0" mass="1.4044" diaginertia="0.00299871 0.0027879 0.00154509" />
          <joint name="Z2_0_Lite_description_0429_1_R_hip_roll_joint" pos="0 0 0" axis="1 0 0" ref="-0.138434" limited="true" range="-1.74 0.52" armature="0.0251019" />
          <geom name="z2_geom_111" type="mesh" contype="0" conaffinity="0" group="1" material="Z2_0_Lite_description_0429_1_R_hip_roll_Link_mat" mesh="R_hip_roll_Link" />
          <geom name="R_hip_roll_Link_collision_0" type="mesh" contype="0" conaffinity="0" group="3" rgba="0.9373 0.2667 0.2667 1" mesh="R_hip_roll_Link" />
          <body name="Z2_0_Lite_description_0429_1_R_hip_yaw_Link" pos="0 0 -0.124">
            <inertial pos="-0.0050752 -0.0080176 -0.11921" quat="0.735291 -0.00489923 -0.057611 0.67528" mass="1.7683" diaginertia="0.00706211 0.00631656 0.00221833" />
            <joint name="Z2_0_Lite_description_0429_1_R_hip_yaw_joint" pos="0 0 0" axis="0 0 1" ref="-0.117629" limited="true" range="-3.14 3.14" armature="0.0101775" />
            <geom name="z2_geom_113" type="mesh" contype="0" conaffinity="0" group="1" material="Z2_0_Lite_description_0429_1_R_hip_yaw_Link_mat" mesh="R_hip_yaw_Link" />
            <geom name="R_hip_yaw_Link_collision_0" type="mesh" contype="0" conaffinity="0" group="3" rgba="0.9373 0.2667 0.2667 1" mesh="R_hip_yaw_Link" />
            <body name="Z2_0_Lite_description_0429_1_R_knee_Link" pos="-0.008 0 -0.146">
              <inertial pos="0.0058511 0.0036171 -0.12267" quat="0.648507 0.0325349 -0.0334909 0.759775" mass="2.2355" diaginertia="0.0124813 0.012099 0.00199448" />
              <joint name="Z2_0_Lite_description_0429_1_R_knee_joint" pos="0 0 0" axis="0 1 0" ref="0.0642885" limited="true" range="-0.5236 2.1817" armature="0.0251019" />
              <geom name="z2_geom_115" type="mesh" contype="0" conaffinity="0" group="1" material="Z2_0_Lite_description_0429_1_R_knee_Link_mat" mesh="R_knee_Link" />
              <geom name="R_knee_Link_collision_0" type="mesh" contype="0" conaffinity="0" group="3" rgba="0.9373 0.2667 0.2667 1" mesh="R_knee_Link" />
              <body name="Z2_0_Lite_description_0429_1_R_ankle_pitch_Link" pos="0 0 -0.32">
                <inertial pos="0 0 0" mass="0.07638" diaginertia="7.24e-06 9e-06 1.458e-05" />
                <joint name="Z2_0_Lite_description_0429_1_R_ankle_pitch_joint" pos="0 0 0" axis="0 1 0" ref="-0.18206" limited="true" range="-0.78 0.29" armature="0.00721945" />
                <geom name="z2_geom_117" type="mesh" contype="0" conaffinity="0" group="1" material="Z2_0_Lite_description_0429_1_R_ankle_pitch_Link_mat" mesh="R_ankle_pitch_Link" />
                <geom name="R_ankle_pitch_Link_collision_0" type="mesh" contype="0" conaffinity="0" group="3" rgba="0.9373 0.2667 0.2667 1" mesh="R_ankle_pitch_Link" />
                <body name="Z2_0_Lite_description_0429_1_R_ankle_roll_Link">
                  <inertial pos="0.034219 -1.57e-05 -0.026454" quat="-0.000793919 0.692172 -0.000745227 0.721732" mass="0.54579" diaginertia="0.002184 0.0020607 0.000293628" />
                  <joint name="Z2_0_Lite_description_0429_1_R_ankle_roll_joint" pos="0 0 0" axis="1 0 0" ref="0.0760932" limited="true" range="-0.36 0.36" armature="0.00721945" />
                  <geom name="z2_geom_119" type="mesh" contype="0" conaffinity="0" group="1" material="Z2_0_Lite_description_0429_1_R_ankle_roll_Link_mat" mesh="R_ankle_roll_Link" />
                  <geom name="right_foot_contact" type="mesh" contype="0" conaffinity="0" condim="1" group="3" rgba="0.9373 0.2667 0.2667 1" mesh="R_ankle_roll_Link" />
                  <geom name="right_foot_contact_0" size="0.0065 0.07" pos="0.04 -0.03 -0.035" quat="0.707107 0 -0.707107 0" type="capsule" contype="0" group="4" priority="1" friction="0.6" rgba="0.2 0.6 0.2 0.3" />
                  <geom name="right_foot_contact_1" size="0.0065 0.10" pos="0.04 0 -0.035" quat="0.707107 0 -0.707107 0" type="capsule" contype="0" group="4" priority="1" friction="0.6" rgba="0.2 0.6 0.2 0.3" />
                  <geom name="right_foot_contact_2" size="0.0065 0.07" pos="0.04 0.03 -0.035" quat="0.707107 0 -0.707107 0" type="capsule" contype="0" group="4" priority="1" friction="0.6" rgba="0.2 0.6 0.2 0.3" />
                </body>
              </body>
            </body>
          </body>
        </body>
      </body>
      <body name="Z2_0_Lite_description_0429_1_L_hip_pitch_Link" pos="0 0.067132 -0.017988" quat="0.991445 -0.130527 0 0">
        <inertial pos="-0.0067102 0.049727 -0.027898" quat="0.964761 -0.223469 -0.0519362 -0.128844" mass="1.5226" diaginertia="0.00248443 0.00228958 0.00169519" />
        <joint name="Z2_0_Lite_description_0429_1_L_hip_pitch_joint" pos="0 0 0" axis="0 1 0" ref="0.0205669" limited="true" range="-2.35 2.35" armature="0.0251019" />
        <geom name="z2_geom_121" type="mesh" contype="0" conaffinity="0" group="1" material="Z2_0_Lite_description_0429_1_L_hip_pitch_Link_mat" mesh="L_hip_pitch_Link" />
        <geom name="L_hip_pitch_Link_collision_0" type="mesh" contype="0" conaffinity="0" group="3" rgba="0.9373 0.2667 0.2667 1" mesh="L_hip_pitch_Link" />
        <body name="Z2_0_Lite_description_0429_1_L_hip_roll_Link" pos="0 0.053575 -0.034315" quat="0.991445 0.130527 0 0">
          <inertial pos="0.0059886 0 -0.081347" quat="0.972518 0 -0.232827 0" mass="1.4044" diaginertia="0.00299871 0.0027879 0.00154509" />
          <joint name="Z2_0_Lite_description_0429_1_L_hip_roll_joint" pos="0 0 0" axis="1 0 0" ref="0.0447451" limited="true" range="-0.52 1.74" armature="0.0251019" />
          <geom name="z2_geom_123" type="mesh" contype="0" conaffinity="0" group="1" material="Z2_0_Lite_description_0429_1_L_hip_roll_Link_mat" mesh="L_hip_roll_Link" />
          <geom name="L_hip_roll_Link_collision_0" type="mesh" contype="0" conaffinity="0" group="3" rgba="0.9373 0.2667 0.2667 1" mesh="L_hip_roll_Link" />
          <body name="Z2_0_Lite_description_0429_1_L_hip_yaw_Link" pos="0 0 -0.124">
            <inertial pos="-0.0051001 0.0080164 -0.11922" quat="0.67466 -0.0576703 -0.0048155 0.735856" mass="1.7683" diaginertia="0.00706384 0.00631594 0.00221992" />
            <joint name="Z2_0_Lite_description_0429_1_L_hip_yaw_joint" pos="0 0 0" axis="0 0 1" ref="0.135776" limited="true" range="-3.14 3.14" armature="0.0101775" />
            <geom name="z2_geom_125" type="mesh" contype="0" conaffinity="0" group="1" material="Z2_0_Lite_description_0429_1_L_hip_yaw_Link_mat" mesh="L_hip_yaw_Link" />
            <geom name="L_hip_yaw_Link_collision_0" type="mesh" contype="0" conaffinity="0" group="3" rgba="0.9373 0.2667 0.2667 1" mesh="L_hip_yaw_Link" />
            <body name="Z2_0_Lite_description_0429_1_L_knee_Link" pos="-0.008 0 -0.146">
              <inertial pos="0.0058894 -0.0036117 -0.12257" quat="0.759596 -0.0335775 0.0323336 0.648723" mass="2.23548" diaginertia="0.012493 0.0121107 0.00199569" />
              <joint name="Z2_0_Lite_description_0429_1_L_knee_joint" pos="0 0 0" axis="0 1 0" ref="0.0415459" limited="true" range="-0.5236 2.1817" armature="0.0251019" />
              <geom name="z2_geom_127" type="mesh" contype="0" conaffinity="0" group="1" material="Z2_0_Lite_description_0429_1_L_knee_Link_mat" mesh="L_knee_Link" />
              <geom name="L_knee_Link_collision_0" type="mesh" contype="0" conaffinity="0" group="3" rgba="0.9373 0.2667 0.2667 1" mesh="L_knee_Link" />
              <body name="Z2_0_Lite_description_0429_1_L_ankle_pitch_Link" pos="0 0 -0.32">
                <inertial pos="0 0 0" mass="0.07638" diaginertia="7.24e-06 9e-06 1.458e-05" />
                <joint name="Z2_0_Lite_description_0429_1_L_ankle_pitch_joint" pos="0 0 0" axis="0 1 0" ref="-0.196165" limited="true" range="-0.78 0.29" armature="0.00721945" />
                <geom name="z2_geom_129" type="mesh" contype="0" conaffinity="0" group="1" material="Z2_0_Lite_description_0429_1_L_ankle_pitch_Link_mat" mesh="L_ankle_pitch_Link" />
                <geom name="L_ankle_pitch_Link_collision_0" type="mesh" contype="0" conaffinity="0" group="3" rgba="0.9373 0.2667 0.2667 1" mesh="L_ankle_pitch_Link" />
                <body name="Z2_0_Lite_description_0429_1_L_ankle_roll_Link">
                  <inertial pos="0.034219 -1.57e-05 -0.026454" quat="-0.000793919 0.692172 -0.000745227 0.721732" mass="0.54579" diaginertia="0.002184 0.0020607 0.000293628" />
                  <joint name="Z2_0_Lite_description_0429_1_L_ankle_roll_joint" pos="0 0 0" axis="1 0 0" ref="-0.0503984" limited="true" range="-0.36 0.36" armature="0.00721945" />
                  <geom name="z2_geom_131" type="mesh" contype="0" conaffinity="0" group="1" material="Z2_0_Lite_description_0429_1_L_ankle_roll_Link_mat" mesh="L_ankle_roll_Link" />
                  <geom name="left_foot_contact" type="mesh" contype="0" conaffinity="0" condim="1" group="3" rgba="0.9373 0.2667 0.2667 1" mesh="L_ankle_roll_Link" />
                  <geom name="left_foot_contact_0" size="0.0065 0.07" pos="0.04 -0.03 -0.035" quat="0.707107 0 -0.707107 0" type="capsule" contype="0" group="4" priority="1" friction="0.6" rgba="0.2 0.6 0.2 0.3" />
                  <geom name="left_foot_contact_1" size="0.0065 0.10" pos="0.04 0 -0.035" quat="0.707107 0 -0.707107 0" type="capsule" contype="0" group="4" priority="1" friction="0.6" rgba="0.2 0.6 0.2 0.3" />
                  <geom name="left_foot_contact_2" size="0.0065 0.07" pos="0.04 0.03 -0.035" quat="0.707107 0 -0.707107 0" type="capsule" contype="0" group="4" priority="1" friction="0.6" rgba="0.2 0.6 0.2 0.3" />
                </body>
              </body>
            </body>
          </body>
        </body>
      </body>
    </body>
  </worldbody>
  <equality>
    <joint name="revo2_left_hand_left_thumb_distal_joint_mimic" joint1="revo2_left_hand_left_thumb_distal_joint" joint2="revo2_left_hand_left_thumb_proximal_joint" polycoef="0 1 0 0 0" />
    <joint name="revo2_left_hand_left_index_distal_joint_mimic" joint1="revo2_left_hand_left_index_distal_joint" joint2="revo2_left_hand_left_index_proximal_joint" polycoef="0 1.155 0 0 0" />
    <joint name="revo2_left_hand_left_middle_distal_joint_mimic" joint1="revo2_left_hand_left_middle_distal_joint" joint2="revo2_left_hand_left_middle_proximal_joint" polycoef="0 1.155 0 0 0" />
    <joint name="revo2_left_hand_left_ring_distal_joint_mimic" joint1="revo2_left_hand_left_ring_distal_joint" joint2="revo2_left_hand_left_ring_proximal_joint" polycoef="0 1.155 0 0 0" />
    <joint name="revo2_left_hand_left_pinky_distal_joint_mimic" joint1="revo2_left_hand_left_pinky_distal_joint" joint2="revo2_left_hand_left_pinky_proximal_joint" polycoef="0 1.155 0 0 0" />
    <joint name="revo2_right_hand_right_thumb_distal_joint_mimic" joint1="revo2_right_hand_right_thumb_distal_joint" joint2="revo2_right_hand_right_thumb_proximal_joint" polycoef="0 1 0 0 0" />
    <joint name="revo2_right_hand_right_index_distal_joint_mimic" joint1="revo2_right_hand_right_index_distal_joint" joint2="revo2_right_hand_right_index_proximal_joint" polycoef="0 1.155 0 0 0" />
    <joint name="revo2_right_hand_right_middle_distal_joint_mimic" joint1="revo2_right_hand_right_middle_distal_joint" joint2="revo2_right_hand_right_middle_proximal_joint" polycoef="0 1.155 0 0 0" />
    <joint name="revo2_right_hand_right_ring_distal_joint_mimic" joint1="revo2_right_hand_right_ring_distal_joint" joint2="revo2_right_hand_right_ring_proximal_joint" polycoef="0 1.155 0 0 0" />
    <joint name="revo2_right_hand_right_pinky_distal_joint_mimic" joint1="revo2_right_hand_right_pinky_distal_joint" joint2="revo2_right_hand_right_pinky_proximal_joint" polycoef="0 1.155 0 0 0" />
  </equality>
  <actuator>
    <general name="Z2_0_Lite_description_0429_1_R_shoulder_pitch_joint" joint="Z2_0_Lite_description_0429_1_R_shoulder_pitch_joint" ctrllimited="false" ctrlrange="-4.89431 4.89431" forcelimited="true" forcerange="-25 25" biastype="affine" gainprm="14.2506" biasprm="0 -14.2506 -0.907223" />
    <general name="Z2_0_Lite_description_0429_1_R_shoulder_roll_joint" joint="Z2_0_Lite_description_0429_1_R_shoulder_roll_joint" ctrllimited="false" ctrlrange="-3.84431 2.01431" forcelimited="true" forcerange="-25 25" biastype="affine" gainprm="14.2506" biasprm="0 -14.2506 -0.907223" />
    <general name="Z2_0_Lite_description_0429_1_R_shoulder_yaw_joint" joint="Z2_0_Lite_description_0429_1_R_shoulder_yaw_joint" ctrllimited="false" ctrlrange="-4.89431 4.89431" forcelimited="true" forcerange="-25 25" biastype="affine" gainprm="14.2506" biasprm="0 -14.2506 -0.907223" />
    <general name="Z2_0_Lite_description_0429_1_R_elbow_joint" joint="Z2_0_Lite_description_0429_1_R_elbow_joint" ctrllimited="false" ctrlrange="-2.27431 4.89431" forcelimited="true" forcerange="-25 25" biastype="affine" gainprm="14.2506" biasprm="0 -14.2506 -0.907223" />
    <general name="Z2_0_Lite_description_0429_1_R_wrist_roll_joint" joint="Z2_0_Lite_description_0429_1_R_wrist_roll_joint" ctrllimited="false" ctrlrange="-4.89431 4.89431" forcelimited="true" forcerange="-25 25" biastype="affine" gainprm="14.2506" biasprm="0 -14.2506 -0.907223" />
    <general name="Z2_0_Lite_description_0429_1_L_shoulder_pitch_joint" joint="Z2_0_Lite_description_0429_1_L_shoulder_pitch_joint" ctrllimited="false" ctrlrange="-4.89431 4.89431" forcelimited="true" forcerange="-25 25" biastype="affine" gainprm="14.2506" biasprm="0 -14.2506 -0.907223" />
    <general name="Z2_0_Lite_description_0429_1_L_shoulder_roll_joint" joint="Z2_0_Lite_description_0429_1_L_shoulder_roll_joint" ctrllimited="false" ctrlrange="-2.01431 3.84431" forcelimited="true" forcerange="-25 25" biastype="affine" gainprm="14.2506" biasprm="0 -14.2506 -0.907223" />
    <general name="Z2_0_Lite_description_0429_1_L_shoulder_yaw_joint" joint="Z2_0_Lite_description_0429_1_L_shoulder_yaw_joint" ctrllimited="false" ctrlrange="-4.89431 4.89431" forcelimited="true" forcerange="-25 25" biastype="affine" gainprm="14.2506" biasprm="0 -14.2506 -0.907223" />
    <general name="Z2_0_Lite_description_0429_1_L_elbow_joint" joint="Z2_0_Lite_description_0429_1_L_elbow_joint" ctrllimited="false" ctrlrange="-2.27431 4.89431" forcelimited="true" forcerange="-25 25" biastype="affine" gainprm="14.2506" biasprm="0 -14.2506 -0.907223" />
    <general name="Z2_0_Lite_description_0429_1_L_wrist_roll_joint" joint="Z2_0_Lite_description_0429_1_L_wrist_roll_joint" ctrllimited="false" ctrlrange="-4.89431 4.89431" forcelimited="true" forcerange="-25 25" biastype="affine" gainprm="14.2506" biasprm="0 -14.2506 -0.907223" />
    <general name="Z2_0_Lite_description_0429_1_waist_yaw_joint" joint="Z2_0_Lite_description_0429_1_waist_yaw_joint" ctrllimited="false" ctrlrange="-5.33019 5.33019" forcelimited="true" forcerange="-88 88" biastype="affine" gainprm="40.1792" biasprm="0 -40.1792 -2.55789" />
    <general name="Z2_0_Lite_description_0429_1_R_hip_yaw_joint" joint="Z2_0_Lite_description_0429_1_R_hip_yaw_joint" ctrllimited="false" ctrlrange="-5.33019 5.33019" forcelimited="true" forcerange="-88 88" biastype="affine" gainprm="40.1792" biasprm="0 -40.1792 -2.55789" />
    <general name="Z2_0_Lite_description_0429_1_L_hip_yaw_joint" joint="Z2_0_Lite_description_0429_1_L_hip_yaw_joint" ctrllimited="false" ctrlrange="-5.33019 5.33019" forcelimited="true" forcerange="-88 88" biastype="affine" gainprm="40.1792" biasprm="0 -40.1792 -2.55789" />
    <general name="Z2_0_Lite_description_0429_1_R_hip_pitch_joint" joint="Z2_0_Lite_description_0429_1_R_hip_pitch_joint" ctrllimited="false" ctrlrange="-3.75265 3.75265" forcelimited="true" forcerange="-139 139" biastype="affine" gainprm="99.0984" biasprm="0 -99.0984 -6.3088" />
    <general name="Z2_0_Lite_description_0429_1_R_hip_roll_joint" joint="Z2_0_Lite_description_0429_1_R_hip_roll_joint" ctrllimited="false" ctrlrange="-3.14265 1.92265" forcelimited="true" forcerange="-139 139" biastype="affine" gainprm="99.0984" biasprm="0 -99.0984 -6.3088" />
    <general name="Z2_0_Lite_description_0429_1_R_knee_joint" joint="Z2_0_Lite_description_0429_1_R_knee_joint" ctrllimited="false" ctrlrange="-1.92625 3.58435" forcelimited="true" forcerange="-139 139" biastype="affine" gainprm="99.0984" biasprm="0 -99.0984 -6.3088" />
    <general name="Z2_0_Lite_description_0429_1_L_hip_pitch_joint" joint="Z2_0_Lite_description_0429_1_L_hip_pitch_joint" ctrllimited="false" ctrlrange="-3.75265 3.75265" forcelimited="true" forcerange="-139 139" biastype="affine" gainprm="99.0984" biasprm="0 -99.0984 -6.3088" />
    <general name="Z2_0_Lite_description_0429_1_L_hip_roll_joint" joint="Z2_0_Lite_description_0429_1_L_hip_roll_joint" ctrllimited="false" ctrlrange="-1.92265 3.14265" forcelimited="true" forcerange="-139 139" biastype="affine" gainprm="99.0984" biasprm="0 -99.0984 -6.3088" />
    <general name="Z2_0_Lite_description_0429_1_L_knee_joint" joint="Z2_0_Lite_description_0429_1_L_knee_joint" ctrllimited="false" ctrlrange="-1.92625 3.58435" forcelimited="true" forcerange="-139 139" biastype="affine" gainprm="99.0984" biasprm="0 -99.0984 -6.3088" />
    <general name="Z2_0_Lite_description_0429_1_R_wrist_pitch_joint" joint="Z2_0_Lite_description_0429_1_R_wrist_pitch_joint" ctrllimited="false" ctrlrange="-2.36865 2.36865" forcelimited="true" forcerange="-13.4 13.4" biastype="affine" gainprm="16.7783" biasprm="0 -16.7783 -1.06814" />
    <general name="Z2_0_Lite_description_0429_1_R_wrist_yaw_joint" joint="Z2_0_Lite_description_0429_1_R_wrist_yaw_joint" ctrllimited="false" ctrlrange="-2.36865 2.36865" forcelimited="true" forcerange="-13.4 13.4" biastype="affine" gainprm="16.7783" biasprm="0 -16.7783 -1.06814" />
    <general name="Z2_0_Lite_description_0429_1_L_wrist_pitch_joint" joint="Z2_0_Lite_description_0429_1_L_wrist_pitch_joint" ctrllimited="false" ctrlrange="-2.36865 2.36865" forcelimited="true" forcerange="-13.4 13.4" biastype="affine" gainprm="16.7783" biasprm="0 -16.7783 -1.06814" />
    <general name="Z2_0_Lite_description_0429_1_L_wrist_yaw_joint" joint="Z2_0_Lite_description_0429_1_L_wrist_yaw_joint" ctrllimited="false" ctrlrange="-2.36865 2.36865" forcelimited="true" forcerange="-13.4 13.4" biastype="affine" gainprm="16.7783" biasprm="0 -16.7783 -1.06814" />
    <general name="Z2_0_Lite_description_0429_1_waist_pitch_joint" joint="Z2_0_Lite_description_0429_1_waist_pitch_joint" ctrllimited="false" ctrlrange="-1.48802 1.65802" forcelimited="true" forcerange="-35 35" biastype="affine" gainprm="28.5012" biasprm="0 -28.5012 -1.81445" />
    <general name="Z2_0_Lite_description_0429_1_waist_roll_joint" joint="Z2_0_Lite_description_0429_1_waist_roll_joint" ctrllimited="false" ctrlrange="-1.74802 1.74802" forcelimited="true" forcerange="-35 35" biastype="affine" gainprm="28.5012" biasprm="0 -28.5012 -1.81445" />
    <general name="Z2_0_Lite_description_0429_1_R_ankle_pitch_joint" joint="Z2_0_Lite_description_0429_1_R_ankle_pitch_joint" ctrllimited="false" ctrlrange="-2.00802 1.51802" forcelimited="true" forcerange="-35 35" biastype="affine" gainprm="28.5012" biasprm="0 -28.5012 -1.81445" />
    <general name="Z2_0_Lite_description_0429_1_R_ankle_roll_joint" joint="Z2_0_Lite_description_0429_1_R_ankle_roll_joint" ctrllimited="false" ctrlrange="-1.58802 1.58802" forcelimited="true" forcerange="-35 35" biastype="affine" gainprm="28.5012" biasprm="0 -28.5012 -1.81445" />
    <general name="Z2_0_Lite_description_0429_1_L_ankle_pitch_joint" joint="Z2_0_Lite_description_0429_1_L_ankle_pitch_joint" ctrllimited="false" ctrlrange="-2.00802 1.51802" forcelimited="true" forcerange="-35 35" biastype="affine" gainprm="28.5012" biasprm="0 -28.5012 -1.81445" />
    <general name="Z2_0_Lite_description_0429_1_L_ankle_roll_joint" joint="Z2_0_Lite_description_0429_1_L_ankle_roll_joint" ctrllimited="false" ctrlrange="-1.58802 1.58802" forcelimited="true" forcerange="-35 35" biastype="affine" gainprm="28.5012" biasprm="0 -28.5012 -1.81445" />
  </actuator>
  <sensor>
    <gyro site="imu_in_base" name="imu_ang_vel" />
    <velocimeter site="imu_in_base" name="imu_lin_vel" />
  </sensor>
  <keyframe>
    <key name="init_state" qpos="0 0 0.80 1 0 0 0 0 0 0 0.2 -0.2 0 0.6 0 0 0 0 0 0 0 0 0 0 0 0 0 0 0.2 0.2 0 0.6 0 0 0 0 0 0 0 0 0 0 0 0 0 0 -0.312 0 0 0.669 -0.363 0 -0.312 0 0 0.669 -0.363 0" ctrl="0.2 -0.2 0 0.6 0 0.2 0.2 0 0.6 0 0 0 0 -0.312 0 0.669 -0.312 0 0.669 0 0 0 0 0 0 -0.363 0 -0.363 0" />
  </keyframe>
</mujoco>
