<?xml version="1.0"?>
<robot name="assembly">

    <link name="Z2_0_Lite_description_0429_1">
      <visual>
        <origin xyz="0 0 0" rpy="0 0 0" />
        <geometry>
          <mesh filename="meshes/base_link.STL" />
        </geometry>
        <material>
          <color rgba="0.79216078 0.81961176 0.92941569 1.00000000"/>
        </material>
      </visual>
      <collision>
        <origin xyz="0 0 0" rpy="0 0 0" />
        <geometry>
          <mesh filename="meshes/base_link.STL" />
        </geometry>
      </collision>
      <inertial>
        <origin xyz="0.000026 0 0.015586" rpy="0 0 0" />
        <mass value="3.6595" />
        <inertia ixx="0.013371" ixy="0" ixz="-0.0000043" iyy="0.010889" iyz="0" izz="0.00862" />
      </inertial>
    </link>

    <link name="Z2_0_Lite_description_0429_1_waist_yaw_Link">
      <visual>
        <origin xyz="0 0 0" rpy="0 0 0" />
        <geometry>
          <mesh filename="meshes/waist_yaw_Link.STL" />
        </geometry>
        <material>
          <color rgba="0.79216078 0.81961176 0.92941569 1.00000000"/>
        </material>
      </visual>
      <collision>
        <origin xyz="0 0 0" rpy="0 0 0" />
        <geometry>
          <mesh filename="meshes/waist_yaw_Link.STL" />
        </geometry>
      </collision>
      <inertial>
        <origin xyz="0.0000986 0 0.010913" rpy="0 0 0" />
        <mass value="0.19414" />
        <inertia ixx="0.0001308" ixy="0" ixz="-0.0000025" iyy="0.000112" iyz="0" izz="0.000183" />
      </inertial>
    </link>

    <link name="Z2_0_Lite_description_0429_1_waist_pitch_Link">
      <visual>
        <origin xyz="0 0 0" rpy="0 0 0" />
        <geometry>
          <mesh filename="meshes/waist_pitch_Link.STL" />
        </geometry>
        <material>
          <color rgba="0.58823922 0.58823922 0.62745490 1.00000000"/>
        </material>
      </visual>
      <collision>
        <origin xyz="0 0 0" rpy="0 0 0" />
        <geometry>
          <mesh filename="meshes/waist_pitch_Link.STL" />
        </geometry>
      </collision>
      <inertial>
        <origin xyz="0 0 0" rpy="0 0 0" />
        <mass value="0.084721" />
        <inertia ixx="0.0000155" ixy="0" ixz="0" iyy="0.0000087" iyz="0" izz="0.0000224" />
      </inertial>
    </link>

    <link name="Z2_0_Lite_description_0429_1_waist_roll_Link">
      <visual>
        <origin xyz="0 0 0" rpy="0 0 0" />
        <geometry>
          <mesh filename="meshes/waist_roll_Link.STL" />
        </geometry>
        <material>
          <color rgba="0.79216078 0.81961176 0.92941569 1.00000000"/>
        </material>
      </visual>
      <collision>
        <origin xyz="0 0 0" rpy="0 0 0" />
        <geometry>
          <mesh filename="meshes/waist_roll_Link.STL" />
        </geometry>
      </collision>
      <inertial>
        <origin xyz="0.00440484 -0.00006599 0.15286233" rpy="0 0 0" />
        <mass value="11.22951" />
        <inertia ixx="0.09031602" ixy="0.00000483" ixz="-0.00142947" iyy="0.06346741" iyz="0.00002369" izz="0.05915892" />
      </inertial>
    </link>

    <link name="Z2_0_Lite_description_0429_1_neck_Link">
      <visual>
        <origin xyz="0 0 0" rpy="0 0 0" />
        <geometry>
          <mesh filename="meshes/neck_Link.STL" />
        </geometry>
        <material>
          <color rgba="0.79216078 0.81961176 0.92941569 1.00000000"/>
        </material>
      </visual>
      <collision>
        <origin xyz="0 0 0" rpy="0 0 0" />
        <geometry>
          <mesh filename="meshes/neck_Link.STL" />
        </geometry>
      </collision>
      <inertial>
        <origin xyz="0.00361611 -0.00038273 0.06378993" rpy="0 0 0" />
        <mass value="1.0284" />
        <inertia ixx="0.00367063" ixy="0.00000140" ixz="0.00012567" iyy="0.00366270" iyz="0.00000084" izz="0.00241872" />
      </inertial>
    </link>

    <link name="Z2_0_Lite_description_0429_1_R_shoulder_pitch_Link">
      <visual>
        <origin xyz="0 0 0" rpy="0 0 0" />
        <geometry>
          <mesh filename="meshes/R_shoulder_pitch_Link.STL" />
        </geometry>
        <material>
          <color rgba="0.79216078 0.81961176 0.92941569 1.00000000"/>
        </material>
      </visual>
      <collision>
        <origin xyz="0 0 0" rpy="0 0 0" />
        <geometry>
          <mesh filename="meshes/R_shoulder_pitch_Link.STL" />
        </geometry>
      </collision>
      <inertial>
        <origin xyz="0.0030433 -0.046415 -0.0078645" rpy="0 0 0" />
        <mass value="0.61036" />
        <inertia ixx="0.0004853" ixy="-0.0000103" ixz="-0.0000055" iyy="0.0004097" iyz="0.0000315" izz="0.0004792" />
      </inertial>
    </link>

    <link name="Z2_0_Lite_description_0429_1_R_shoulder_roll_Link">
      <visual>
        <origin xyz="0 0 0" rpy="0 0 0" />
        <geometry>
          <mesh filename="meshes/R_shoulder_roll_Link.STL" />
        </geometry>
        <material>
          <color rgba="0.79216078 0.81961176 0.92941569 1.00000000"/>
        </material>
      </visual>
      <collision>
        <origin xyz="0 0 0" rpy="0 0 0" />
        <geometry>
          <mesh filename="meshes/R_shoulder_roll_Link.STL" />
        </geometry>
      </collision>
      <inertial>
        <origin xyz="0.0003492 -0.0028489 -0.038097" rpy="0 0 0" />
        <mass value="0.22592" />
        <inertia ixx="0.000288" ixy="0.0000002" ixz="-0.0000002" iyy="0.0003812" iyz="-0.0000006" izz="0.0002448" />
      </inertial>
    </link>

    <link name="Z2_0_Lite_description_0429_1_R_shoulder_yaw_Link">
      <visual>
        <origin xyz="0 0 0" rpy="0 0 0" />
        <geometry>
          <mesh filename="meshes/R_shoulder_yaw_Link.STL" />
        </geometry>
        <material>
          <color rgba="0.79216078 0.81961176 0.92941569 1.00000000"/>
        </material>
      </visual>
      <collision>
        <origin xyz="0 0 0" rpy="0 0 0" />
        <geometry>
          <mesh filename="meshes/R_shoulder_yaw_Link.STL" />
        </geometry>
      </collision>
      <inertial>
        <origin xyz="0.0046034 -0.000625 -0.075726" rpy="0 0 0" />
        <mass value="1.0841" />
        <inertia ixx="0.0029008" ixy="-0.0000035" ixz="-0.0002439" iyy="0.0029286" iyz="0.0000317" izz="0.0006307" />
      </inertial>
    </link>

    <link name="Z2_0_Lite_description_0429_1_R_elbow_Link">
      <visual>
        <origin xyz="0 0 0" rpy="0 0 0" />
        <geometry>
          <mesh filename="meshes/R_elbow_Link.STL" />
        </geometry>
        <material>
          <color rgba="0.79216078 0.81961176 0.92941569 1.00000000"/>
        </material>
      </visual>
      <collision>
        <origin xyz="0 0 0" rpy="0 0 0" />
        <geometry>
          <mesh filename="meshes/R_elbow_Link.STL" />
        </geometry>
      </collision>
      <inertial>
        <origin xyz="0.063477 -0.0003999 0" rpy="0 0 0" />
        <mass value="0.61836" />
        <inertia ixx="0.0004054" ixy="0.0000158" ixz="0" iyy="0.0005948" iyz="0" izz="0.000662" />
      </inertial>
    </link>

    <link name="Z2_0_Lite_description_0429_1_R_wrist_roll_Link">
      <visual>
        <origin xyz="0 0 0" rpy="0 0 0" />
        <geometry>
          <mesh filename="meshes/R_wrist_roll_Link.STL" />
        </geometry>
        <material>
          <color rgba="0.58823922 0.58823922 0.62745490 1.00000000"/>
        </material>
      </visual>
      <collision>
        <origin xyz="0 0 0" rpy="0 0 0" />
        <geometry>
          <mesh filename="meshes/R_wrist_roll_Link.STL" />
        </geometry>
      </collision>
      <inertial>
        <origin xyz="0.015815 0.0015672 0" rpy="0 0 0" />
        <mass value="0.07414" />
        <inertia ixx="0.0000558" ixy="0.0000018" ixz="0" iyy="0.0000321" iyz="0" izz="0.0000576" />
      </inertial>
    </link>

    <link name="Z2_0_Lite_description_0429_1_R_wrist_pitch_Link">
      <visual>
        <origin xyz="0 0 0" rpy="0 0 0" />
        <geometry>
          <mesh filename="meshes/R_wrist_pitch_Link.STL" />
        </geometry>
        <material>
          <color rgba="0.79216078 0.81961176 0.92941569 1.00000000"/>
        </material>
      </visual>
      <collision>
        <origin xyz="0 0 0" rpy="0 0 0" />
        <geometry>
          <mesh filename="meshes/R_wrist_pitch_Link.STL" />
        </geometry>
      </collision>
      <inertial>
        <origin xyz="0.023091 0.0008013 0.0007039" rpy="0 0 0" />
        <mass value="0.47133" />
        <inertia ixx="0.0001837" ixy="-0.0000087" ixz="0.0000076" iyy="0.0004175" iyz="-0.0000003" izz="0.0004166" />
      </inertial>
    </link>

    <link name="Z2_0_Lite_description_0429_1_R_wrist_yaw_Link">
      <visual>
        <origin xyz="0 0 0" rpy="0 0 0" />
        <geometry>
          <mesh filename="meshes/R_wrist_yaw_Link.STL" />
        </geometry>
        <material>
          <color rgba="1.00000000 1.00000000 1.00000000 1.00000000"/>
        </material>
      </visual>
      <collision>
        <origin xyz="0 0 0" rpy="0 0 0" />
        <geometry>
          <mesh filename="meshes/R_wrist_yaw_Link.STL" />
        </geometry>
      </collision>
      <inertial>
        <origin xyz="0.018433 0 -0.0005558" rpy="0 0 0" />
        <mass value="0.05797" />
        <inertia ixx="0.0000428" ixy="0" ixz="0" iyy="0.0000491" iyz="0" izz="0.0000226" />
      </inertial>
    </link>

    <link name="Z2_0_Lite_description_0429_1_L_shoulder_pitch_Link">
      <visual>
        <origin xyz="0 0 0" rpy="0 0 0" />
        <geometry>
          <mesh filename="meshes/L_shoulder_pitch_Link.STL" />
        </geometry>
        <material>
          <color rgba="0.79216078 0.81961176 0.92941569 1.00000000"/>
        </material>
      </visual>
      <collision>
        <origin xyz="0 0 0" rpy="0 0 0" />
        <geometry>
          <mesh filename="meshes/L_shoulder_pitch_Link.STL" />
        </geometry>
      </collision>
      <inertial>
        <origin xyz="0.0030433 0.046415 -0.0078645" rpy="0 0 0" />
        <mass value="0.61036" />
        <inertia ixx="0.0004853" ixy="0.0000103" ixz="-0.0000055" iyy="0.0004098" iyz="-0.0000315" izz="0.0004792" />
      </inertial>
    </link>

    <link name="Z2_0_Lite_description_0429_1_L_shoulder_roll_Link">
      <visual>
        <origin xyz="0 0 0" rpy="0 0 0" />
        <geometry>
          <mesh filename="meshes/L_shoulder_roll_Link.STL" />
        </geometry>
        <material>
          <color rgba="0.79216078 0.81961176 0.92941569 1.00000000"/>
        </material>
      </visual>
      <collision>
        <origin xyz="0 0 0" rpy="0 0 0" />
        <geometry>
          <mesh filename="meshes/L_shoulder_roll_Link.STL" />
        </geometry>
      </collision>
      <inertial>
        <origin xyz="0.0003486 0.0028486 -0.038097" rpy="0 0 0" />
        <mass value="0.22592" />
        <inertia ixx="0.000288" ixy="-0.0000002" ixz="-0.0000002" iyy="0.0003812" iyz="0.0000006" izz="0.0002448" />
      </inertial>
    </link>

    <link name="Z2_0_Lite_description_0429_1_L_shoulder_yaw_Link">
      <visual>
        <origin xyz="0 0 0" rpy="0 0 0" />
        <geometry>
          <mesh filename="meshes/L_shoulder_yaw_Link.STL" />
        </geometry>
        <material>
          <color rgba="0.79216078 0.81961176 0.92941569 1.00000000"/>
        </material>
      </visual>
      <collision>
        <origin xyz="0 0 0" rpy="0 0 0" />
        <geometry>
          <mesh filename="meshes/L_shoulder_yaw_Link.STL" />
        </geometry>
      </collision>
      <inertial>
        <origin xyz="0.0045614 0.0005825 -0.075662" rpy="0 0 0" />
        <mass value="1.08409" />
        <inertia ixx="0.0029011" ixy="0.0000023" ixz="-0.0002424" iyy="0.0029291" iyz="-0.0000298" izz="0.0006293" />
      </inertial>
    </link>

    <link name="Z2_0_Lite_description_0429_1_L_elbow_Link">
      <visual>
        <origin xyz="0 0 0" rpy="0 0 0" />
        <geometry>
          <mesh filename="meshes/L_elbow_Link.STL" />
        </geometry>
        <material>
          <color rgba="0.79216078 0.81961176 0.92941569 1.00000000"/>
        </material>
      </visual>
      <collision>
        <origin xyz="0 0 0" rpy="0 0 0" />
        <geometry>
          <mesh filename="meshes/L_elbow_Link.STL" />
        </geometry>
      </collision>
      <inertial>
        <origin xyz="0.063477 0.0003999 0" rpy="0 0 0" />
        <mass value="0.61836" />
        <inertia ixx="0.0004054" ixy="-0.0000158" ixz="0" iyy="0.0005948" iyz="0" izz="0.000662" />
      </inertial>
    </link>

    <link name="Z2_0_Lite_description_0429_1_L_wrist_roll_Link">
      <visual>
        <origin xyz="0 0 0" rpy="0 0 0" />
        <geometry>
          <mesh filename="meshes/L_wrist_roll_Link.STL" />
        </geometry>
        <material>
          <color rgba="0.58823922 0.58823922 0.62745490 1.00000000"/>
        </material>
      </visual>
      <collision>
        <origin xyz="0 0 0" rpy="0 0 0" />
        <geometry>
          <mesh filename="meshes/L_wrist_roll_Link.STL" />
        </geometry>
      </collision>
      <inertial>
        <origin xyz="0.015815 -0.0015672 0" rpy="0 0 0" />
        <mass value="0.07414" />
        <inertia ixx="0.0000558" ixy="-0.0000018" ixz="0" iyy="0.0000321" iyz="0" izz="0.0000576" />
      </inertial>
    </link>

    <link name="Z2_0_Lite_description_0429_1_L_wrist_pitch_Link">
      <visual>
        <origin xyz="0 0 0" rpy="0 0 0" />
        <geometry>
          <mesh filename="meshes/L_wrist_pitch_Link.STL" />
        </geometry>
        <material>
          <color rgba="0.79216078 0.81961176 0.92941569 1.00000000"/>
        </material>
      </visual>
      <collision>
        <origin xyz="0 0 0" rpy="0 0 0" />
        <geometry>
          <mesh filename="meshes/L_wrist_pitch_Link.STL" />
        </geometry>
      </collision>
      <inertial>
        <origin xyz="0.023083 -0.0007916 0.0007035" rpy="0 0 0" />
        <mass value="0.47133" />
        <inertia ixx="0.0001838" ixy="0.0000086" ixz="0.0000076" iyy="0.0004175" iyz="0.0000003" izz="0.0004166" />
      </inertial>
    </link>

    <link name="Z2_0_Lite_description_0429_1_L_wrist_yaw_Link">
      <visual>
        <origin xyz="0 0 0" rpy="0 0 0" />
        <geometry>
          <mesh filename="meshes/L_wrist_yaw_Link.STL" />
        </geometry>
        <material>
          <color rgba="1.00000000 1.00000000 1.00000000 1.00000000"/>
        </material>
      </visual>
      <collision>
        <origin xyz="0 0 0" rpy="0 0 0" />
        <geometry>
          <mesh filename="meshes/L_wrist_yaw_Link.STL" />
        </geometry>
      </collision>
      <inertial>
        <origin xyz="0.018433 0 -0.0005558" rpy="0 0 0" />
        <mass value="0.05797" />
        <inertia ixx="0.0000428" ixy="0" ixz="0" iyy="0.0000491" iyz="0" izz="0.0000226" />
      </inertial>
    </link>

    <link name="Z2_0_Lite_description_0429_1_R_hip_pitch_Link">
      <visual>
        <origin xyz="0 0 0" rpy="0 0 0" />
        <geometry>
          <mesh filename="meshes/R_hip_pitch_Link.STL" />
        </geometry>
        <material>
          <color rgba="0.79216078 0.81961176 0.92941569 1.00000000"/>
        </material>
      </visual>
      <collision>
        <origin xyz="0 0 0" rpy="0 0 0" />
        <geometry>
          <mesh filename="meshes/R_hip_pitch_Link.STL" />
        </geometry>
      </collision>
      <inertial>
        <origin xyz="-0.0067414 -0.049854 -0.027824" rpy="0 0 0" />
        <mass value="1.5226" />
        <inertia ixx="0.002466" ixy="0.0000349" ixz="0.0000518" iyy="0.0021744" iyz="0.0002561" izz="0.0018245" />
      </inertial>
    </link>

    <link name="Z2_0_Lite_description_0429_1_R_hip_roll_Link">
      <visual>
        <origin xyz="0 0 0" rpy="0 0 0" />
        <geometry>
          <mesh filename="meshes/R_hip_roll_Link.STL" />
        </geometry>
        <material>
          <color rgba="0.79216078 0.81961176 0.92941569 1.00000000"/>
        </material>
      </visual>
      <collision>
        <origin xyz="0 0 0" rpy="0 0 0" />
        <geometry>
          <mesh filename="meshes/R_hip_roll_Link.STL" />
        </geometry>
      </collision>
      <inertial>
        <origin xyz="0.0059886 0 -0.081347" rpy="0 0 0" />
        <mass value="1.4044" />
        <inertia ixx="0.0027006" ixy="0" ixz="0.0005869" iyy="0.0027879" iyz="0" izz="0.0018432" />
      </inertial>
    </link>

    <link name="Z2_0_Lite_description_0429_1_R_hip_yaw_Link">
      <visual>
        <origin xyz="0 0 0" rpy="0 0 0" />
        <geometry>
          <mesh filename="meshes/R_hip_yaw_Link.STL" />
        </geometry>
        <material>
          <color rgba="0.79216078 0.81961176 0.92941569 1.00000000"/>
        </material>
      </visual>
      <collision>
        <origin xyz="0 0 0" rpy="0 0 0" />
        <geometry>
          <mesh filename="meshes/R_hip_yaw_Link.STL" />
        </geometry>
      </collision>
      <inertial>
        <origin xyz="-0.0050752 -0.0080176 -0.11921" rpy="0 0 0" />
        <mass value="1.7683" />
        <inertia ixx="0.0062873" ixy="0.0000338" ixz="0.0003766" iyy="0.0070322" iyz="0.0003453" izz="0.0022775" />
      </inertial>
    </link>

    <link name="Z2_0_Lite_description_0429_1_R_knee_Link">
      <visual>
        <origin xyz="0 0 0" rpy="0 0 0" />
        <geometry>
          <mesh filename="meshes/R_knee_Link.STL" />
        </geometry>
        <material>
          <color rgba="0.79216078 0.81961176 0.92941569 1.00000000"/>
        </material>
      </visual>
      <collision>
        <origin xyz="0 0 0" rpy="0 0 0" />
        <geometry>
          <mesh filename="meshes/R_knee_Link.STL" />
        </geometry>
      </collision>
      <inertial>
        <origin xyz="0.0058511 0.0036171 -0.12267" rpy="0 0 0" />
        <mass value="2.2355" />
        <inertia ixx="0.012108" ixy="-0.0000533" ixz="-0.0000659" iyy="0.012381" iyz="0.0009714" izz="0.0020857" />
      </inertial>
    </link>

    <link name="Z2_0_Lite_description_0429_1_R_ankle_pitch_Link">
      <visual>
        <origin xyz="0 0 0" rpy="0 0 0" />
        <geometry>
          <mesh filename="meshes/R_ankle_pitch_Link.STL" />
        </geometry>
        <material>
          <color rgba="0.58823922 0.58823922 0.62745490 1.00000000"/>
        </material>
      </visual>
      <collision>
        <origin xyz="0 0 0" rpy="0 0 0" />
        <geometry>
          <mesh filename="meshes/R_ankle_pitch_Link.STL" />
        </geometry>
      </collision>
      <inertial>
        <origin xyz="0 0 0" rpy="0 0 0" />
        <mass value="0.07638" />
        <inertia ixx="0.0000072" ixy="0" ixz="0" iyy="0.000009" iyz="0" izz="0.0000146" />
      </inertial>
    </link>

    <link name="Z2_0_Lite_description_0429_1_R_ankle_roll_Link">
      <visual>
        <origin xyz="0 0 0" rpy="0 0 0" />
        <geometry>
          <mesh filename="meshes/R_ankle_roll_Link.STL" />
        </geometry>
        <material>
          <color rgba="0.79216078 0.81961176 0.92941569 1.00000000"/>
        </material>
      </visual>
      <collision>
        <origin xyz="0 0 0" rpy="0 0 0" />
        <geometry>
          <mesh filename="meshes/R_ankle_roll_Link.STL" />
        </geometry>
      </collision>
      <inertial>
        <origin xyz="0.034219 -0.0000157 -0.026454" rpy="0 0 0" />
        <mass value="0.54579" />
        <inertia ixx="0.0002969" ixy="0" ixz="-0.0000789" iyy="0.0020607" iyz="-0.0000003" izz="0.0021807" />
      </inertial>
    </link>

    <link name="Z2_0_Lite_description_0429_1_L_hip_pitch_Link">
      <visual>
        <origin xyz="0 0 0" rpy="0 0 0" />
        <geometry>
          <mesh filename="meshes/L_hip_pitch_Link.STL" />
        </geometry>
        <material>
          <color rgba="0.79216078 0.81961176 0.92941569 1.00000000"/>
        </material>
      </visual>
      <collision>
        <origin xyz="0 0 0" rpy="0 0 0" />
        <geometry>
          <mesh filename="meshes/L_hip_pitch_Link.STL" />
        </geometry>
      </collision>
      <inertial>
        <origin xyz="-0.0067102 0.049727 -0.027898" rpy="0 0 0" />
        <mass value="1.5226" />
        <inertia ixx="0.0024686" ixy="-0.000031" ixz="0.0000522" iyy="0.002182" iyz="-0.0002434" izz="0.0018186" />
      </inertial>
    </link>

    <link name="Z2_0_Lite_description_0429_1_L_hip_roll_Link">
      <visual>
        <origin xyz="0 0 0" rpy="0 0 0" />
        <geometry>
          <mesh filename="meshes/L_hip_roll_Link.STL" />
        </geometry>
        <material>
          <color rgba="0.79216078 0.81961176 0.92941569 1.00000000"/>
        </material>
      </visual>
      <collision>
        <origin xyz="0 0 0" rpy="0 0 0" />
        <geometry>
          <mesh filename="meshes/L_hip_roll_Link.STL" />
        </geometry>
      </collision>
      <inertial>
        <origin xyz="0.0059886 0 -0.081347" rpy="0 0 0" />
        <mass value="1.4044" />
        <inertia ixx="0.0027006" ixy="0" ixz="0.0005869" iyy="0.0027879" iyz="0" izz="0.0018432" />
      </inertial>
    </link>

    <link name="Z2_0_Lite_description_0429_1_L_hip_yaw_Link">
      <visual>
        <origin xyz="0 0 0" rpy="0 0 0" />
        <geometry>
          <mesh filename="meshes/L_hip_yaw_Link.STL" />
        </geometry>
        <material>
          <color rgba="0.79216078 0.81961176 0.92941569 1.00000000"/>
        </material>
      </visual>
      <collision>
        <origin xyz="0 0 0" rpy="0 0 0" />
        <geometry>
          <mesh filename="meshes/L_hip_yaw_Link.STL" />
        </geometry>
      </collision>
      <inertial>
        <origin xyz="-0.0051001 0.0080164 -0.11922" rpy="0 0 0" />
        <mass value="1.7683" />
        <inertia ixx="0.0062869" ixy="-0.0000352" ixz="0.0003766" iyy="0.0070336" iyz="-0.000346" izz="0.0022792" />
      </inertial>
    </link>

    <link name="Z2_0_Lite_description_0429_1_L_knee_Link">
      <visual>
        <origin xyz="0 0 0" rpy="0 0 0" />
        <geometry>
          <mesh filename="meshes/L_knee_Link.STL" />
        </geometry>
        <material>
          <color rgba="0.79216078 0.81961176 0.92941569 1.00000000"/>
        </material>
      </visual>
      <collision>
        <origin xyz="0 0 0" rpy="0 0 0" />
        <geometry>
          <mesh filename="meshes/L_knee_Link.STL" />
        </geometry>
      </collision>
      <inertial>
        <origin xyz="0.0058894 -0.0036117 -0.12257" rpy="0 0 0" />
        <mass value="2.23548" />
        <inertia ixx="0.0121197" ixy="0.0000535" ixz="-0.0000615" iyy="0.012393" iyz="-0.0009711" izz="0.0020867" />
      </inertial>
    </link>

    <link name="Z2_0_Lite_description_0429_1_L_ankle_pitch_Link">
      <visual>
        <origin xyz="0 0 0" rpy="0 0 0" />
        <geometry>
          <mesh filename="meshes/L_ankle_pitch_Link.STL" />
        </geometry>
        <material>
          <color rgba="0.58823922 0.58823922 0.62745490 1.00000000"/>
        </material>
      </visual>
      <collision>
        <origin xyz="0 0 0" rpy="0 0 0" />
        <geometry>
          <mesh filename="meshes/L_ankle_pitch_Link.STL" />
        </geometry>
      </collision>
      <inertial>
        <origin xyz="0 0 0" rpy="0 0 0" />
        <mass value="0.07638" />
        <inertia ixx="0.0000072" ixy="0" ixz="0" iyy="0.000009" iyz="0" izz="0.0000146" />
      </inertial>
    </link>

    <link name="Z2_0_Lite_description_0429_1_L_ankle_roll_Link">
      <visual>
        <origin xyz="0 0 0" rpy="0 0 0" />
        <geometry>
          <mesh filename="meshes/L_ankle_roll_Link.STL" />
        </geometry>
        <material>
          <color rgba="0.79216078 0.81961176 0.92941569 1.00000000"/>
        </material>
      </visual>
      <collision>
        <origin xyz="0 0 0" rpy="0 0 0" />
        <geometry>
          <mesh filename="meshes/L_ankle_roll_Link.STL" />
        </geometry>
      </collision>
      <inertial>
        <origin xyz="0.034219 -0.0000157 -0.026454" rpy="0 0 0" />
        <mass value="0.54579" />
        <inertia ixx="0.0002969" ixy="0" ixz="-0.0000789" iyy="0.0020607" iyz="-0.0000003" izz="0.0021807" />
      </inertial>
    </link>

    <link name="revo2_left_hand">
      <visual>
        <origin xyz="0 0 0" rpy="0 0 0" />
        <geometry>
          <mesh filename="meshes/revo2_left_hand/left_base_link.STL" />
        </geometry>
        <material>
          <color rgba="1.00000000 1.00000000 1.00000000 1.00000000"/>
        </material>
      </visual>
      <visual>
        <origin xyz="0 0 0" rpy="0 0 0" />
        <geometry>
          <mesh filename="meshes/revo2_left_hand/left_base_visual_link.STL" />
        </geometry>
        <material>
          <color rgba="1.00000000 1.00000000 1.00000000 1.00000000"/>
        </material>
      </visual>
      <collision>
        <origin xyz="0 0 0" rpy="0 0 0" />
        <geometry>
          <mesh filename="meshes/revo2_left_hand/left_base_link.STL" />
        </geometry>
      </collision>
      <inertial>
        <origin xyz="-0.0052625 0.0033926 0.0521379" rpy="0 0 0" />
        <mass value="0.238" />
        <inertia ixx="0.0000211" ixy="0" ixz="0.0000001" iyy="0.0000145" iyz="0.0000011" izz="0.000008" />
      </inertial>
    </link>

    <link name="revo2_left_hand_left_thumb_metacarpal_link">
      <visual>
        <origin xyz="0 0 0" rpy="0 0 0" />
        <geometry>
          <mesh filename="meshes/revo2_left_hand/left_thumb_metacarpal_link.STL" />
        </geometry>
        <material>
          <color rgba="1.00000000 1.00000000 1.00000000 1.00000000"/>
        </material>
      </visual>
      <collision>
        <origin xyz="0 0 0" rpy="0 0 0" />
        <geometry>
          <mesh filename="meshes/revo2_left_hand/left_thumb_metacarpal_link.STL" />
        </geometry>
      </collision>
      <inertial>
        <origin xyz="0.0000152 -0.0070724 -0.0042084" rpy="0 0 0" />
        <mass value="0.01" />
        <inertia ixx="0.0000002" ixy="0" ixz="0" iyy="0.0000002" iyz="0" izz="0.0000001" />
      </inertial>
    </link>

    <link name="revo2_left_hand_left_thumb_proximal_link">
      <visual>
        <origin xyz="0 0 0" rpy="0 0 0" />
        <geometry>
          <mesh filename="meshes/revo2_left_hand/left_thumb_proximal_link.STL" />
        </geometry>
        <material>
          <color rgba="1.00000000 1.00000000 1.00000000 1.00000000"/>
        </material>
      </visual>
      <visual>
        <origin xyz="0 0 0" rpy="0 0 0" />
        <geometry>
          <mesh filename="meshes/revo2_left_hand/left_thumb_proximal_visual_link.STL" />
        </geometry>
        <material>
          <color rgba="1.00000000 1.00000000 1.00000000 1.00000000"/>
        </material>
      </visual>
      <collision>
        <origin xyz="0 0 0" rpy="0 0 0" />
        <geometry>
          <mesh filename="meshes/revo2_left_hand/left_thumb_proximal_link.STL" />
        </geometry>
      </collision>
      <inertial>
        <origin xyz="-0.0000004 -0.0277016 -0.0020267" rpy="0 0 0" />
        <mass value="0.05" />
        <inertia ixx="0.0000024" ixy="0" ixz="0" iyy="0.0000005" iyz="0" izz="0.0000026" />
      </inertial>
    </link>

    <link name="revo2_left_hand_left_thumb_distal_link">
      <visual>
        <origin xyz="0 0 0" rpy="0 0 0" />
        <geometry>
          <mesh filename="meshes/revo2_left_hand/left_thumb_distal_link.STL" />
        </geometry>
        <material>
          <color rgba="1.00000000 1.00000000 1.00000000 1.00000000"/>
        </material>
      </visual>
      <collision>
        <origin xyz="0 0 0" rpy="0 0 0" />
        <geometry>
          <mesh filename="meshes/revo2_left_hand/left_thumb_distal_link.STL" />
        </geometry>
      </collision>
      <inertial>
        <origin xyz="0.0000002 -0.0117551 0.0000114" rpy="0 0 0" />
        <mass value="0.01" />
        <inertia ixx="0.0000002" ixy="0" ixz="0" iyy="0.0000001" iyz="0" izz="0.0000002" />
      </inertial>
    </link>

  <link name="revo2_left_hand_left_thumb_tip_link">
  </link>

    <link name="revo2_left_hand_left_thumb_touch_link">
      <visual>
        <origin xyz="0 0 0" rpy="0 0 0" />
        <geometry>
          <mesh filename="meshes/revo2_left_hand/left_thumb_touch_link.STL" />
        </geometry>
        <material>
          <color rgba="1.00000000 1.00000000 1.00000000 1.00000000"/>
        </material>
      </visual>
      <collision>
        <origin xyz="0 0 0" rpy="0 0 0" />
        <geometry>
          <mesh filename="meshes/revo2_left_hand/left_thumb_touch_link.STL" />
        </geometry>
      </collision>
      <inertial>
        <origin xyz="0.0000001 0.0007172 -0.0079025" rpy="0 0 0" />
        <mass value="0.002" />
        <inertia ixx="0.0000002" ixy="0" ixz="0" iyy="0.0000001" iyz="0" izz="0.0000002" />
      </inertial>
    </link>

    <link name="revo2_left_hand_left_index_proximal_link">
      <visual>
        <origin xyz="0 0 0" rpy="0 0 0" />
        <geometry>
          <mesh filename="meshes/revo2_left_hand/left_index_proximal_link.STL" />
        </geometry>
        <material>
          <color rgba="1.00000000 1.00000000 1.00000000 1.00000000"/>
        </material>
      </visual>
      <collision>
        <origin xyz="0 0 0" rpy="0 0 0" />
        <geometry>
          <mesh filename="meshes/revo2_left_hand/left_index_proximal_link.STL" />
        </geometry>
      </collision>
      <inertial>
        <origin xyz="-0.0022354 -0.0000038 0.0176439" rpy="0 0 0" />
        <mass value="0.009" />
        <inertia ixx="0.0000003" ixy="0" ixz="0" iyy="0.0000002" iyz="0" izz="0.0000001" />
      </inertial>
    </link>

    <link name="revo2_left_hand_left_index_distal_link">
      <visual>
        <origin xyz="0 0 0" rpy="0 0 0" />
        <geometry>
          <mesh filename="meshes/revo2_left_hand/left_index_distal_link.STL" />
        </geometry>
        <material>
          <color rgba="1.00000000 1.00000000 1.00000000 1.00000000"/>
        </material>
      </visual>
      <collision>
        <origin xyz="0 0 0" rpy="0 0 0" />
        <geometry>
          <mesh filename="meshes/revo2_left_hand/left_index_distal_link.STL" />
        </geometry>
      </collision>
      <inertial>
        <origin xyz="0.0033017 0.0000001 0.0142076" rpy="0 0 0" />
        <mass value="0.009" />
        <inertia ixx="0.0000003" ixy="0" ixz="-0.0000001" iyy="0.0000004" iyz="0" izz="0.0000001" />
      </inertial>
    </link>

  <link name="revo2_left_hand_left_index_tip_link">
  </link>

    <link name="revo2_left_hand_left_index_touch_link">
      <visual>
        <origin xyz="0 0 0" rpy="0 0 0" />
        <geometry>
          <mesh filename="meshes/revo2_left_hand/left_index_touch_link.STL" />
        </geometry>
        <material>
          <color rgba="1.00000000 1.00000000 1.00000000 1.00000000"/>
        </material>
      </visual>
      <collision>
        <origin xyz="0 0 0" rpy="0 0 0" />
        <geometry>
          <mesh filename="meshes/revo2_left_hand/left_index_touch_link.STL" />
        </geometry>
      </collision>
      <inertial>
        <origin xyz="-0.0029992 0 0.0025237" rpy="0 0 0" />
        <mass value="0.002" />
        <inertia ixx="0" ixy="0" ixz="0" iyy="0" iyz="0" izz="0" />
      </inertial>
    </link>

    <link name="revo2_left_hand_left_middle_proximal_link">
      <visual>
        <origin xyz="0 0 0" rpy="0 0 0" />
        <geometry>
          <mesh filename="meshes/revo2_left_hand/left_middle_proximal_link.STL" />
        </geometry>
        <material>
          <color rgba="1.00000000 1.00000000 1.00000000 1.00000000"/>
        </material>
      </visual>
      <collision>
        <origin xyz="0 0 0" rpy="0 0 0" />
        <geometry>
          <mesh filename="meshes/revo2_left_hand/left_middle_proximal_link.STL" />
        </geometry>
      </collision>
      <inertial>
        <origin xyz="-0.0022242 -0.0000036 0.020305" rpy="0 0 0" />
        <mass value="0.009" />
        <inertia ixx="0.0000004" ixy="0" ixz="0" iyy="0.0000004" iyz="0" izz="0.0000001" />
      </inertial>
    </link>

    <link name="revo2_left_hand_left_middle_distal_link">
      <visual>
        <origin xyz="0 0 0" rpy="0 0 0" />
        <geometry>
          <mesh filename="meshes/revo2_left_hand/left_middle_distal_link.STL" />
        </geometry>
        <material>
          <color rgba="1.00000000 1.00000000 1.00000000 1.00000000"/>
        </material>
      </visual>
      <collision>
        <origin xyz="0 0 0" rpy="0 0 0" />
        <geometry>
          <mesh filename="meshes/revo2_left_hand/left_middle_distal_link.STL" />
        </geometry>
      </collision>
      <inertial>
        <origin xyz="0.0018942 0 0.0168711" rpy="0 0 0" />
        <mass value="0.009" />
        <inertia ixx="0.0000005" ixy="0" ixz="-0.0000001" iyy="0.0000005" iyz="0" izz="0.0000001" />
      </inertial>
    </link>

  <link name="revo2_left_hand_left_middle_tip_link">
  </link>

    <link name="revo2_left_hand_left_middle_touch_link">
      <visual>
        <origin xyz="0 0 0" rpy="0 0 0" />
        <geometry>
          <mesh filename="meshes/revo2_left_hand/left_middle_touch_link.STL" />
        </geometry>
        <material>
          <color rgba="1.00000000 1.00000000 1.00000000 1.00000000"/>
        </material>
      </visual>
      <collision>
        <origin xyz="0 0 0" rpy="0 0 0" />
        <geometry>
          <mesh filename="meshes/revo2_left_hand/left_middle_touch_link.STL" />
        </geometry>
      </collision>
      <inertial>
        <origin xyz="-0.0031929 0 0.0029786" rpy="0 0 0" />
        <mass value="0.002" />
        <inertia ixx="0" ixy="0" ixz="0" iyy="0" iyz="0" izz="0" />
      </inertial>
    </link>

    <link name="revo2_left_hand_left_ring_proximal_link">
      <visual>
        <origin xyz="0 0 0" rpy="0 0 0" />
        <geometry>
          <mesh filename="meshes/revo2_left_hand/left_ring_proximal_link.STL" />
        </geometry>
        <material>
          <color rgba="1.00000000 1.00000000 1.00000000 1.00000000"/>
        </material>
      </visual>
      <collision>
        <origin xyz="0 0 0" rpy="0 0 0" />
        <geometry>
          <mesh filename="meshes/revo2_left_hand/left_ring_proximal_link.STL" />
        </geometry>
      </collision>
      <inertial>
        <origin xyz="-0.0023446 -0.0000053 0.0191786" rpy="0 0 0" />
        <mass value="0.009" />
        <inertia ixx="0.0000003" ixy="0" ixz="0" iyy="0.0000003" iyz="0" izz="0.0000001" />
      </inertial>
    </link>

    <link name="revo2_left_hand_left_ring_distal_link">
      <visual>
        <origin xyz="0 0 0" rpy="0 0 0" />
        <geometry>
          <mesh filename="meshes/revo2_left_hand/left_ring_distal_link.STL" />
        </geometry>
        <material>
          <color rgba="1.00000000 1.00000000 1.00000000 1.00000000"/>
        </material>
      </visual>
      <collision>
        <origin xyz="0 0 0" rpy="0 0 0" />
        <geometry>
          <mesh filename="meshes/revo2_left_hand/left_ring_distal_link.STL" />
        </geometry>
      </collision>
      <inertial>
        <origin xyz="0.0017705 0.0000001 0.016389" rpy="0 0 0" />
        <mass value="0.009" />
        <inertia ixx="0.0000005" ixy="0" ixz="-0.0000001" iyy="0.0000005" iyz="0" izz="0.0000001" />
      </inertial>
    </link>

  <link name="revo2_left_hand_left_ring_tip_link">
  </link>

    <link name="revo2_left_hand_left_ring_touch_link">
      <visual>
        <origin xyz="0 0 0" rpy="0 0 0" />
        <geometry>
          <mesh filename="meshes/revo2_left_hand/left_ring_touch_link.STL" />
        </geometry>
        <material>
          <color rgba="1.00000000 1.00000000 1.00000000 1.00000000"/>
        </material>
      </visual>
      <collision>
        <origin xyz="0 0 0" rpy="0 0 0" />
        <geometry>
          <mesh filename="meshes/revo2_left_hand/left_ring_touch_link.STL" />
        </geometry>
      </collision>
      <inertial>
        <origin xyz="-0.0030235 0 0.0030408" rpy="0 0 0" />
        <mass value="0.002" />
        <inertia ixx="0" ixy="0" ixz="0" iyy="0" iyz="0" izz="0" />
      </inertial>
    </link>

    <link name="revo2_left_hand_left_pinky_proximal_link">
      <visual>
        <origin xyz="0 0 0" rpy="0 0 0" />
        <geometry>
          <mesh filename="meshes/revo2_left_hand/left_pinky_proximal_link.STL" />
        </geometry>
        <material>
          <color rgba="1.00000000 1.00000000 1.00000000 1.00000000"/>
        </material>
      </visual>
      <collision>
        <origin xyz="0 0 0" rpy="0 0 0" />
        <geometry>
          <mesh filename="meshes/revo2_left_hand/left_pinky_proximal_link.STL" />
        </geometry>
      </collision>
      <inertial>
        <origin xyz="-0.0021327 -0.000007 0.016068" rpy="0 0 0" />
        <mass value="0.009" />
        <inertia ixx="0.0000002" ixy="0" ixz="0" iyy="0.0000002" iyz="0" izz="0.0000001" />
      </inertial>
    </link>

    <link name="revo2_left_hand_left_pinky_distal_link">
      <visual>
        <origin xyz="0 0 0" rpy="0 0 0" />
        <geometry>
          <mesh filename="meshes/revo2_left_hand/left_pinky_distal_link.STL" />
        </geometry>
        <material>
          <color rgba="1.00000000 1.00000000 1.00000000 1.00000000"/>
        </material>
      </visual>
      <collision>
        <origin xyz="0 0 0" rpy="0 0 0" />
        <geometry>
          <mesh filename="meshes/revo2_left_hand/left_pinky_distal_link.STL" />
        </geometry>
      </collision>
      <inertial>
        <origin xyz="0.0030795 -0.0000001 0.0130239" rpy="0 0 0" />
        <mass value="0.009" />
        <inertia ixx="0.0000003" ixy="0" ixz="-0.0000001" iyy="0.0000003" iyz="0" izz="0.0000001" />
      </inertial>
    </link>

  <link name="revo2_left_hand_left_pinky_tip_link">
  </link>

    <link name="revo2_left_hand_left_pinky_touch_link">
      <visual>
        <origin xyz="0 0 0" rpy="0 0 0" />
        <geometry>
          <mesh filename="meshes/revo2_left_hand/left_pinky_touch_link.STL" />
        </geometry>
        <material>
          <color rgba="1.00000000 1.00000000 1.00000000 1.00000000"/>
        </material>
      </visual>
      <collision>
        <origin xyz="0 0 0" rpy="0 0 0" />
        <geometry>
          <mesh filename="meshes/revo2_left_hand/left_pinky_touch_link.STL" />
        </geometry>
      </collision>
      <inertial>
        <origin xyz="-0.0028914 -0.0000002 0.0016539" rpy="0 0 0" />
        <mass value="0.002" />
        <inertia ixx="0" ixy="0" ixz="0" iyy="0" iyz="0" izz="0" />
      </inertial>
    </link>

    <link name="revo2_right_hand">
      <visual>
        <origin xyz="0 0 0" rpy="0 0 0" />
        <geometry>
          <mesh filename="meshes/revo2_right_hand/right_base_link.STL" />
        </geometry>
        <material>
          <color rgba="1.00000000 1.00000000 1.00000000 1.00000000"/>
        </material>
      </visual>
      <visual>
        <origin xyz="0 0 0" rpy="0 0 0" />
        <geometry>
          <mesh filename="meshes/revo2_right_hand/right_base_visual_link.STL" />
        </geometry>
        <material>
          <color rgba="1.00000000 1.00000000 1.00000000 1.00000000"/>
        </material>
      </visual>
      <collision>
        <origin xyz="0 0 0" rpy="0 0 0" />
        <geometry>
          <mesh filename="meshes/revo2_right_hand/right_base_link.STL" />
        </geometry>
      </collision>
      <inertial>
        <origin xyz="-0.0052438 -0.0034038 0.0521267" rpy="0 0 0" />
        <mass value="0.238" />
        <inertia ixx="0.0000211" ixy="0" ixz="0.0000001" iyy="0.0000145" iyz="-0.0000011" izz="0.000008" />
      </inertial>
    </link>

    <link name="revo2_right_hand_right_thumb_metacarpal_link">
      <visual>
        <origin xyz="0 0 0" rpy="0 0 0" />
        <geometry>
          <mesh filename="meshes/revo2_right_hand/right_thumb_metacarpal_link.STL" />
        </geometry>
        <material>
          <color rgba="1.00000000 1.00000000 1.00000000 1.00000000"/>
        </material>
      </visual>
      <collision>
        <origin xyz="0 0 0" rpy="0 0 0" />
        <geometry>
          <mesh filename="meshes/revo2_right_hand/right_thumb_metacarpal_link.STL" />
        </geometry>
      </collision>
      <inertial>
        <origin xyz="0.0000151 0.0070724 -0.0042085" rpy="0 0 0" />
        <mass value="0.01" />
        <inertia ixx="0.0000002" ixy="0" ixz="0" iyy="0.0000002" iyz="0" izz="0.0000001" />
      </inertial>
    </link>

    <link name="revo2_right_hand_right_thumb_proximal_link">
      <visual>
        <origin xyz="0 0 0" rpy="0 0 0" />
        <geometry>
          <mesh filename="meshes/revo2_right_hand/right_thumb_proximal_visual_link.STL" />
        </geometry>
        <material>
          <color rgba="1.00000000 1.00000000 1.00000000 1.00000000"/>
        </material>
      </visual>
      <collision>
        <origin xyz="0 0 0" rpy="0 0 0" />
        <geometry>
          <mesh filename="meshes/revo2_right_hand/right_thumb_proximal_link.STL" />
        </geometry>
      </collision>
      <inertial>
        <origin xyz="-0.0000005 0.0277015 -0.0020266" rpy="0 0 0" />
        <mass value="0.05" />
        <inertia ixx="0.0000024" ixy="0" ixz="0" iyy="0.0000005" iyz="0" izz="0.0000026" />
      </inertial>
    </link>

    <link name="revo2_right_hand_right_thumb_distal_link">
      <visual>
        <origin xyz="0 0 0" rpy="0 0 0" />
        <geometry>
          <mesh filename="meshes/revo2_right_hand/right_thumb_distal_link.STL" />
        </geometry>
        <material>
          <color rgba="1.00000000 1.00000000 1.00000000 1.00000000"/>
        </material>
      </visual>
      <collision>
        <origin xyz="0 0 0" rpy="0 0 0" />
        <geometry>
          <mesh filename="meshes/revo2_right_hand/right_thumb_distal_link.STL" />
        </geometry>
      </collision>
      <inertial>
        <origin xyz="0 0.0117545 0.0000113" rpy="0 0 0" />
        <mass value="0.01" />
        <inertia ixx="0.0000002" ixy="0" ixz="0" iyy="0.0000001" iyz="0" izz="0.0000002" />
      </inertial>
    </link>

  <link name="revo2_right_hand_right_thumb_tip_link">
  </link>

    <link name="revo2_right_hand_right_thumb_touch_link">
      <visual>
        <origin xyz="0 0 0" rpy="0 0 0" />
        <geometry>
          <mesh filename="meshes/revo2_right_hand/right_thumb_touch_link.STL" />
        </geometry>
        <material>
          <color rgba="1.00000000 1.00000000 1.00000000 1.00000000"/>
        </material>
      </visual>
      <collision>
        <origin xyz="0 0 0" rpy="0 0 0" />
        <geometry>
          <mesh filename="meshes/revo2_right_hand/right_thumb_touch_link.STL" />
        </geometry>
      </collision>
      <inertial>
        <origin xyz="0 -0.0015225 -0.0077842" rpy="0 0 0" />
        <mass value="0.002" />
        <inertia ixx="0.0000002" ixy="0" ixz="0" iyy="0.0000001" iyz="0" izz="0.0000002" />
      </inertial>
    </link>

    <link name="revo2_right_hand_right_index_proximal_link">
      <visual>
        <origin xyz="0 0 0" rpy="0 0 0" />
        <geometry>
          <mesh filename="meshes/revo2_right_hand/right_index_proximal_link.STL" />
        </geometry>
        <material>
          <color rgba="1.00000000 1.00000000 1.00000000 1.00000000"/>
        </material>
      </visual>
      <collision>
        <origin xyz="0 0 0" rpy="0 0 0" />
        <geometry>
          <mesh filename="meshes/revo2_right_hand/right_index_proximal_link.STL" />
        </geometry>
      </collision>
      <inertial>
        <origin xyz="-0.002235 0.0000032 0.0176402" rpy="0 0 0" />
        <mass value="0.009" />
        <inertia ixx="0.0000003" ixy="0" ixz="0" iyy="0.0000002" iyz="0" izz="0.0000001" />
      </inertial>
    </link>

    <link name="revo2_right_hand_right_index_distal_link">
      <visual>
        <origin xyz="0 0 0" rpy="0 0 0" />
        <geometry>
          <mesh filename="meshes/revo2_right_hand/right_index_distal_link.STL" />
        </geometry>
        <material>
          <color rgba="1.00000000 1.00000000 1.00000000 1.00000000"/>
        </material>
      </visual>
      <collision>
        <origin xyz="0 0 0" rpy="0 0 0" />
        <geometry>
          <mesh filename="meshes/revo2_right_hand/right_index_distal_link.STL" />
        </geometry>
      </collision>
      <inertial>
        <origin xyz="0.0033017 0.0000002 0.0142077" rpy="0 0 0" />
        <mass value="0.009" />
        <inertia ixx="0.0000003" ixy="0" ixz="-0.0000001" iyy="0.0000004" iyz="0" izz="0.0000001" />
      </inertial>
    </link>

  <link name="revo2_right_hand_right_index_tip_link">
  </link>

    <link name="revo2_right_hand_right_index_touch_link">
      <visual>
        <origin xyz="0 0 0" rpy="0 0 0" />
        <geometry>
          <mesh filename="meshes/revo2_right_hand/right_index_touch_link.STL" />
        </geometry>
        <material>
          <color rgba="1.00000000 1.00000000 1.00000000 1.00000000"/>
        </material>
      </visual>
      <collision>
        <origin xyz="0 0 0" rpy="0 0 0" />
        <geometry>
          <mesh filename="meshes/revo2_right_hand/right_index_touch_link.STL" />
        </geometry>
      </collision>
      <inertial>
        <origin xyz="-0.0029991 0.0024974 -0.0003615" rpy="0 0 0" />
        <mass value="0.002" />
        <inertia ixx="0" ixy="0" ixz="0" iyy="0" iyz="0" izz="0" />
      </inertial>
    </link>

    <link name="revo2_right_hand_right_middle_proximal_link">
      <visual>
        <origin xyz="0 0 0" rpy="0 0 0" />
        <geometry>
          <mesh filename="meshes/revo2_right_hand/right_middle_proximal_link.STL" />
        </geometry>
        <material>
          <color rgba="1.00000000 1.00000000 1.00000000 1.00000000"/>
        </material>
      </visual>
      <collision>
        <origin xyz="0 0 0" rpy="0 0 0" />
        <geometry>
          <mesh filename="meshes/revo2_right_hand/right_middle_proximal_link.STL" />
        </geometry>
      </collision>
      <inertial>
        <origin xyz="-0.0022251 0.0000053 0.0203008" rpy="0 0 0" />
        <mass value="0.009" />
        <inertia ixx="0.0000004" ixy="0" ixz="0" iyy="0.0000004" iyz="0" izz="0.0000001" />
      </inertial>
    </link>

    <link name="revo2_right_hand_right_middle_distal_link">
      <visual>
        <origin xyz="0 0 0" rpy="0 0 0" />
        <geometry>
          <mesh filename="meshes/revo2_right_hand/right_middle_distal_link.STL" />
        </geometry>
        <material>
          <color rgba="1.00000000 1.00000000 1.00000000 1.00000000"/>
        </material>
      </visual>
      <collision>
        <origin xyz="0 0 0" rpy="0 0 0" />
        <geometry>
          <mesh filename="meshes/revo2_right_hand/right_middle_distal_link.STL" />
        </geometry>
      </collision>
      <inertial>
        <origin xyz="0.0040082 0 0.0164974" rpy="0 0 0" />
        <mass value="0.009" />
        <inertia ixx="0.0000005" ixy="0" ixz="-0.0000001" iyy="0.0000005" iyz="0" izz="0.0000001" />
      </inertial>
    </link>

  <link name="revo2_right_hand_right_middle_tip_link">
  </link>

    <link name="revo2_right_hand_right_middle_touch_link">
      <visual>
        <origin xyz="0 0 0" rpy="0 0 0" />
        <geometry>
          <mesh filename="meshes/revo2_right_hand/right_middle_touch_link.STL" />
        </geometry>
        <material>
          <color rgba="1.00000000 1.00000000 1.00000000 1.00000000"/>
        </material>
      </visual>
      <collision>
        <origin xyz="0 0 0" rpy="0 0 0" />
        <geometry>
          <mesh filename="meshes/revo2_right_hand/right_middle_touch_link.STL" />
        </geometry>
      </collision>
      <inertial>
        <origin xyz="-0.0031929 0 0.0029786" rpy="0 0 0" />
        <mass value="0.002" />
        <inertia ixx="0" ixy="0" ixz="0" iyy="0" iyz="0" izz="0" />
      </inertial>
    </link>

    <link name="revo2_right_hand_right_ring_proximal_link">
      <visual>
        <origin xyz="0 0 0" rpy="0 0 0" />
        <geometry>
          <mesh filename="meshes/revo2_right_hand/right_ring_proximal_link.STL" />
        </geometry>
        <material>
          <color rgba="1.00000000 1.00000000 1.00000000 1.00000000"/>
        </material>
      </visual>
      <collision>
        <origin xyz="0 0 0" rpy="0 0 0" />
        <geometry>
          <mesh filename="meshes/revo2_right_hand/right_ring_proximal_link.STL" />
        </geometry>
      </collision>
      <inertial>
        <origin xyz="-0.0023449 0.0000059 0.0191774" rpy="0 0 0" />
        <mass value="0.009" />
        <inertia ixx="0.0000003" ixy="0" ixz="0" iyy="0.0000003" iyz="0" izz="0.0000001" />
      </inertial>
    </link>

    <link name="revo2_right_hand_right_ring_distal_link">
      <visual>
        <origin xyz="0 0 0" rpy="0 0 0" />
        <geometry>
          <mesh filename="meshes/revo2_right_hand/right_ring_distal_link.STL" />
        </geometry>
        <material>
          <color rgba="1.00000000 1.00000000 1.00000000 1.00000000"/>
        </material>
      </visual>
      <collision>
        <origin xyz="0 0 0" rpy="0 0 0" />
        <geometry>
          <mesh filename="meshes/revo2_right_hand/right_ring_distal_link.STL" />
        </geometry>
      </collision>
      <inertial>
        <origin xyz="0.0038246 0.0000001 0.0160344" rpy="0 0 0" />
        <mass value="0.009" />
        <inertia ixx="0.0000005" ixy="0" ixz="-0.0000001" iyy="0.0000005" iyz="0" izz="0.0000001" />
      </inertial>
    </link>

  <link name="revo2_right_hand_right_ring_tip_link">
  </link>

    <link name="revo2_right_hand_right_ring_touch_link">
      <visual>
        <origin xyz="0 0 0" rpy="0 0 0" />
        <geometry>
          <mesh filename="meshes/revo2_right_hand/right_ring_touch_link.STL" />
        </geometry>
        <material>
          <color rgba="1.00000000 1.00000000 1.00000000 1.00000000"/>
        </material>
      </visual>
      <collision>
        <origin xyz="0 0 0" rpy="0 0 0" />
        <geometry>
          <mesh filename="meshes/revo2_right_hand/right_ring_touch_link.STL" />
        </geometry>
      </collision>
      <inertial>
        <origin xyz="-0.0030235 0 0.0030408" rpy="0 0 0" />
        <mass value="0.002" />
        <inertia ixx="0" ixy="0" ixz="0" iyy="0" iyz="0" izz="0" />
      </inertial>
    </link>

    <link name="revo2_right_hand_right_pinky_proximal_link">
      <visual>
        <origin xyz="0 0 0" rpy="0 0 0" />
        <geometry>
          <mesh filename="meshes/revo2_right_hand/right_pinky_proximal_link.STL" />
        </geometry>
        <material>
          <color rgba="1.00000000 1.00000000 1.00000000 1.00000000"/>
        </material>
      </visual>
      <collision>
        <origin xyz="0 0 0" rpy="0 0 0" />
        <geometry>
          <mesh filename="meshes/revo2_right_hand/right_pinky_proximal_link.STL" />
        </geometry>
      </collision>
      <inertial>
        <origin xyz="-0.0021321 0.0000078 0.0160672" rpy="0 0 0" />
        <mass value="0.009" />
        <inertia ixx="0.0000002" ixy="0" ixz="0" iyy="0.0000002" iyz="0" izz="0.0000001" />
      </inertial>
    </link>

    <link name="revo2_right_hand_right_pinky_distal_link">
      <visual>
        <origin xyz="0 0 0" rpy="0 0 0" />
        <geometry>
          <mesh filename="meshes/revo2_right_hand/right_pinky_distal_link.STL" />
        </geometry>
        <material>
          <color rgba="1.00000000 1.00000000 1.00000000 1.00000000"/>
        </material>
      </visual>
      <collision>
        <origin xyz="0 0 0" rpy="0 0 0" />
        <geometry>
          <mesh filename="meshes/revo2_right_hand/right_pinky_distal_link.STL" />
        </geometry>
      </collision>
      <inertial>
        <origin xyz="0.0030797 -0.0000002 0.0130247" rpy="0 0 0" />
        <mass value="0.009" />
        <inertia ixx="0.0000003" ixy="0" ixz="-0.0000001" iyy="0.0000003" iyz="0" izz="0.0000001" />
      </inertial>
    </link>

  <link name="revo2_right_hand_right_pinky_tip_link">
  </link>

    <link name="revo2_right_hand_right_pinky_touch_link">
      <visual>
        <origin xyz="0 0 0" rpy="0 0 0" />
        <geometry>
          <mesh filename="meshes/revo2_right_hand/right_pinky_touch_link.STL" />
        </geometry>
        <material>
          <color rgba="1.00000000 1.00000000 1.00000000 1.00000000"/>
        </material>
      </visual>
      <collision>
        <origin xyz="0 0 0" rpy="0 0 0" />
        <geometry>
          <mesh filename="meshes/revo2_right_hand/right_pinky_touch_link.STL" />
        </geometry>
      </collision>
      <inertial>
        <origin xyz="-0.0028914 -0.0000002 0.0016539" rpy="0 0 0" />
        <mass value="0.002" />
        <inertia ixx="0" ixy="0" ixz="0" iyy="0" iyz="0" izz="0" />
      </inertial>
    </link>

  <joint name="Z2_0_Lite_description_0429_1_waist_yaw_joint" type="revolute">
    <parent link="Z2_0_Lite_description_0429_1" />
    <child link="Z2_0_Lite_description_0429_1_waist_yaw_Link" />
    <origin xyz="0 0 0.0995" rpy="0 0 0" />
    <axis xyz="0 0 1" />
    <limit lower="-3.14" upper="3.14" effort="0" velocity="0" />
  </joint>

  <joint name="Z2_0_Lite_description_0429_1_waist_pitch_joint" type="revolute">
    <parent link="Z2_0_Lite_description_0429_1_waist_yaw_Link" />
    <child link="Z2_0_Lite_description_0429_1_waist_pitch_Link" />
    <origin xyz="0 0 0.0325" rpy="0 0 0" />
    <axis xyz="0 1 0" />
    <limit lower="-0.26" upper="0.43" effort="0" velocity="0" />
  </joint>

  <joint name="Z2_0_Lite_description_0429_1_waist_roll_joint" type="revolute">
    <parent link="Z2_0_Lite_description_0429_1_waist_pitch_Link" />
    <child link="Z2_0_Lite_description_0429_1_waist_roll_Link" />
    <origin xyz="0 0 0" rpy="0 0 0" />
    <axis xyz="1 0 0" />
    <limit lower="-0.52" upper="0.52" effort="0" velocity="0" />
  </joint>

  <joint name="Z2_0_Lite_description_0429_1_neck_fixed" type="fixed">
    <parent link="Z2_0_Lite_description_0429_1_waist_roll_Link" />
    <child link="Z2_0_Lite_description_0429_1_neck_Link" />
    <origin xyz="0 0 0.329" rpy="0 0 0" />
  </joint>

  <joint name="Z2_0_Lite_description_0429_1_R_shoulder_pitch_joint" type="revolute">
    <parent link="Z2_0_Lite_description_0429_1_waist_roll_Link" />
    <child link="Z2_0_Lite_description_0429_1_R_shoulder_pitch_Link" />
    <origin xyz="0 -0.12262 0.22437" rpy="-0.2618 0 0" />
    <axis xyz="0 1 0" />
    <limit lower="-3.14" upper="3.14" effort="0" velocity="0" />
  </joint>

  <joint name="Z2_0_Lite_description_0429_1_R_shoulder_roll_joint" type="revolute">
    <parent link="Z2_0_Lite_description_0429_1_R_shoulder_pitch_Link" />
    <child link="Z2_0_Lite_description_0429_1_R_shoulder_roll_Link" />
    <origin xyz="0 -0.052 -0.01" rpy="0.2618 0 0" />
    <axis xyz="1 0 0" />
    <limit lower="-2.09" upper="0.26" effort="0" velocity="0" />
  </joint>

  <joint name="Z2_0_Lite_description_0429_1_R_shoulder_yaw_joint" type="revolute">
    <parent link="Z2_0_Lite_description_0429_1_R_shoulder_roll_Link" />
    <child link="Z2_0_Lite_description_0429_1_R_shoulder_yaw_Link" />
    <origin xyz="0 0 -0.075" rpy="0 0 0" />
    <axis xyz="0 0 1" />
    <limit lower="-3.14" upper="3.14" effort="0" velocity="0" />
  </joint>

  <joint name="Z2_0_Lite_description_0429_1_R_elbow_joint" type="revolute">
    <parent link="Z2_0_Lite_description_0429_1_R_shoulder_yaw_Link" />
    <child link="Z2_0_Lite_description_0429_1_R_elbow_Link" />
    <origin xyz="0.01 0 -0.123" rpy="0 0 0" />
    <axis xyz="0 1 0" />
    <limit lower="-0.52" upper="3.14" effort="0" velocity="0" />
  </joint>

  <joint name="Z2_0_Lite_description_0429_1_R_wrist_roll_joint" type="revolute">
    <parent link="Z2_0_Lite_description_0429_1_R_elbow_Link" />
    <child link="Z2_0_Lite_description_0429_1_R_wrist_roll_Link" />
    <origin xyz="0.1 0 0" rpy="0 0 0" />
    <axis xyz="1 0 0" />
    <limit lower="-3.14" upper="3.14" effort="0" velocity="0" />
  </joint>

  <joint name="Z2_0_Lite_description_0429_1_R_wrist_pitch_joint" type="revolute">
    <parent link="Z2_0_Lite_description_0429_1_R_wrist_roll_Link" />
    <child link="Z2_0_Lite_description_0429_1_R_wrist_pitch_Link" />
    <origin xyz="0.035 0 0" rpy="0 0 0" />
    <axis xyz="0 1 0" />
    <limit lower="-1.57" upper="1.57" effort="0" velocity="0" />
  </joint>

  <joint name="Z2_0_Lite_description_0429_1_R_wrist_yaw_joint" type="revolute">
    <parent link="Z2_0_Lite_description_0429_1_R_wrist_pitch_Link" />
    <child link="Z2_0_Lite_description_0429_1_R_wrist_yaw_Link" />
    <origin xyz="0.046 0 0" rpy="0 0 0" />
    <axis xyz="0 0 1" />
    <limit lower="-1.57" upper="1.57" effort="0" velocity="0" />
  </joint>

  <joint name="Z2_0_Lite_description_0429_1_L_shoulder_pitch_joint" type="revolute">
    <parent link="Z2_0_Lite_description_0429_1_waist_roll_Link" />
    <child link="Z2_0_Lite_description_0429_1_L_shoulder_pitch_Link" />
    <origin xyz="0 0.12262 0.22437" rpy="0.2618 0 0" />
    <axis xyz="0 1 0" />
    <limit lower="-3.14" upper="3.14" effort="0" velocity="0" />
  </joint>

  <joint name="Z2_0_Lite_description_0429_1_L_shoulder_roll_joint" type="revolute">
    <parent link="Z2_0_Lite_description_0429_1_L_shoulder_pitch_Link" />
    <child link="Z2_0_Lite_description_0429_1_L_shoulder_roll_Link" />
    <origin xyz="0 0.052 -0.01" rpy="-0.2618 0 0" />
    <axis xyz="1 0 0" />
    <limit lower="-0.26" upper="2.09" effort="0" velocity="0" />
  </joint>

  <joint name="Z2_0_Lite_description_0429_1_L_shoulder_yaw_joint" type="revolute">
    <parent link="Z2_0_Lite_description_0429_1_L_shoulder_roll_Link" />
    <child link="Z2_0_Lite_description_0429_1_L_shoulder_yaw_Link" />
    <origin xyz="0 0 -0.075" rpy="0 0 0" />
    <axis xyz="0 0 1" />
    <limit lower="-3.14" upper="3.14" effort="0" velocity="0" />
  </joint>

  <joint name="Z2_0_Lite_description_0429_1_L_elbow_joint" type="revolute">
    <parent link="Z2_0_Lite_description_0429_1_L_shoulder_yaw_Link" />
    <child link="Z2_0_Lite_description_0429_1_L_elbow_Link" />
    <origin xyz="0.01 0 -0.123" rpy="0 0 0" />
    <axis xyz="0 1 0" />
    <limit lower="-0.52" upper="3.14" effort="0" velocity="0" />
  </joint>

  <joint name="Z2_0_Lite_description_0429_1_L_wrist_roll_joint" type="revolute">
    <parent link="Z2_0_Lite_description_0429_1_L_elbow_Link" />
    <child link="Z2_0_Lite_description_0429_1_L_wrist_roll_Link" />
    <origin xyz="0.1 0 0" rpy="0 0 0" />
    <axis xyz="1 0 0" />
    <limit lower="-3.14" upper="3.14" effort="0" velocity="0" />
  </joint>

  <joint name="Z2_0_Lite_description_0429_1_L_wrist_pitch_joint" type="revolute">
    <parent link="Z2_0_Lite_description_0429_1_L_wrist_roll_Link" />
    <child link="Z2_0_Lite_description_0429_1_L_wrist_pitch_Link" />
    <origin xyz="0.035 0 0" rpy="0 0 0" />
    <axis xyz="0 1 0" />
    <limit lower="-1.57" upper="1.57" effort="0" velocity="0" />
  </joint>

  <joint name="Z2_0_Lite_description_0429_1_L_wrist_yaw_joint" type="revolute">
    <parent link="Z2_0_Lite_description_0429_1_L_wrist_pitch_Link" />
    <child link="Z2_0_Lite_description_0429_1_L_wrist_yaw_Link" />
    <origin xyz="0.046 0 0" rpy="0 0 0" />
    <axis xyz="0 0 1" />
    <limit lower="-1.57" upper="1.57" effort="0" velocity="0" />
  </joint>

  <joint name="Z2_0_Lite_description_0429_1_R_hip_pitch_joint" type="revolute">
    <parent link="Z2_0_Lite_description_0429_1" />
    <child link="Z2_0_Lite_description_0429_1_R_hip_pitch_Link" />
    <origin xyz="0 -0.067132 -0.017988" rpy="0.2618 0 0" />
    <axis xyz="0 1 0" />
    <limit lower="-2.35" upper="2.35" effort="0" velocity="0" />
  </joint>

  <joint name="Z2_0_Lite_description_0429_1_R_hip_roll_joint" type="revolute">
    <parent link="Z2_0_Lite_description_0429_1_R_hip_pitch_Link" />
    <child link="Z2_0_Lite_description_0429_1_R_hip_roll_Link" />
    <origin xyz="0 -0.053575 -0.034315" rpy="-0.2618 0 0" />
    <axis xyz="1 0 0" />
    <limit lower="-1.74" upper="0.52" effort="0" velocity="0" />
  </joint>

  <joint name="Z2_0_Lite_description_0429_1_R_hip_yaw_joint" type="revolute">
    <parent link="Z2_0_Lite_description_0429_1_R_hip_roll_Link" />
    <child link="Z2_0_Lite_description_0429_1_R_hip_yaw_Link" />
    <origin xyz="0 0 -0.124" rpy="0 0 0" />
    <axis xyz="0 0 1" />
    <limit lower="-3.14" upper="3.14" effort="0" velocity="0" />
  </joint>

  <joint name="Z2_0_Lite_description_0429_1_R_knee_joint" type="revolute">
    <parent link="Z2_0_Lite_description_0429_1_R_hip_yaw_Link" />
    <child link="Z2_0_Lite_description_0429_1_R_knee_Link" />
    <origin xyz="-0.008 0 -0.146" rpy="0 0 0" />
    <axis xyz="0 1 0" />
    <limit lower="-0.5236" upper="2.1817" effort="0" velocity="0" />
  </joint>

  <joint name="Z2_0_Lite_description_0429_1_R_ankle_pitch_joint" type="revolute">
    <parent link="Z2_0_Lite_description_0429_1_R_knee_Link" />
    <child link="Z2_0_Lite_description_0429_1_R_ankle_pitch_Link" />
    <origin xyz="0 0 -0.32" rpy="0 0 0" />
    <axis xyz="0 1 0" />
    <limit lower="-0.78" upper="0.29" effort="0" velocity="0" />
  </joint>

  <joint name="Z2_0_Lite_description_0429_1_R_ankle_roll_joint" type="revolute">
    <parent link="Z2_0_Lite_description_0429_1_R_ankle_pitch_Link" />
    <child link="Z2_0_Lite_description_0429_1_R_ankle_roll_Link" />
    <origin xyz="0 0 0" rpy="0 0 0" />
    <axis xyz="1 0 0" />
    <limit lower="-0.36" upper="0.36" effort="0" velocity="0" />
  </joint>

  <joint name="Z2_0_Lite_description_0429_1_L_hip_pitch_joint" type="revolute">
    <parent link="Z2_0_Lite_description_0429_1" />
    <child link="Z2_0_Lite_description_0429_1_L_hip_pitch_Link" />
    <origin xyz="0 0.067132 -0.017988" rpy="-0.2618 0 0" />
    <axis xyz="0 1 0" />
    <limit lower="-2.35" upper="2.35" effort="0" velocity="0" />
  </joint>

  <joint name="Z2_0_Lite_description_0429_1_L_hip_roll_joint" type="revolute">
    <parent link="Z2_0_Lite_description_0429_1_L_hip_pitch_Link" />
    <child link="Z2_0_Lite_description_0429_1_L_hip_roll_Link" />
    <origin xyz="0 0.053575 -0.034315" rpy="0.2618 0 0" />
    <axis xyz="1 0 0" />
    <limit lower="-0.52" upper="1.74" effort="0" velocity="0" />
  </joint>

  <joint name="Z2_0_Lite_description_0429_1_L_hip_yaw_joint" type="revolute">
    <parent link="Z2_0_Lite_description_0429_1_L_hip_roll_Link" />
    <child link="Z2_0_Lite_description_0429_1_L_hip_yaw_Link" />
    <origin xyz="0 0 -0.124" rpy="0 0 0" />
    <axis xyz="0 0 1" />
    <limit lower="-3.14" upper="3.14" effort="0" velocity="0" />
  </joint>

  <joint name="Z2_0_Lite_description_0429_1_L_knee_joint" type="revolute">
    <parent link="Z2_0_Lite_description_0429_1_L_hip_yaw_Link" />
    <child link="Z2_0_Lite_description_0429_1_L_knee_Link" />
    <origin xyz="-0.008 0 -0.146" rpy="0 0 0" />
    <axis xyz="0 1 0" />
    <limit lower="-0.5236" upper="2.1817" effort="0" velocity="0" />
  </joint>

  <joint name="Z2_0_Lite_description_0429_1_L_ankle_pitch_joint" type="revolute">
    <parent link="Z2_0_Lite_description_0429_1_L_knee_Link" />
    <child link="Z2_0_Lite_description_0429_1_L_ankle_pitch_Link" />
    <origin xyz="0 0 -0.32" rpy="0 0 0" />
    <axis xyz="0 1 0" />
    <limit lower="-0.78" upper="0.29" effort="0" velocity="0" />
  </joint>

  <joint name="Z2_0_Lite_description_0429_1_L_ankle_roll_joint" type="revolute">
    <parent link="Z2_0_Lite_description_0429_1_L_ankle_pitch_Link" />
    <child link="Z2_0_Lite_description_0429_1_L_ankle_roll_Link" />
    <origin xyz="0 0 0" rpy="0 0 0" />
    <axis xyz="1 0 0" />
    <limit lower="-0.36" upper="0.36" effort="0" velocity="0" />
  </joint>

  <joint name="revo2_left_hand_left_thumb_metacarpal_joint" type="revolute">
    <parent link="revo2_left_hand" />
    <child link="revo2_left_hand_left_thumb_metacarpal_link" />
    <origin xyz="0.0045 -0.019 0.027825" rpy="0 0 0.16787" />
    <axis xyz="0 0 1" />
    <limit lower="0" upper="1.57" effort="0.5" velocity="2.6175" />
  </joint>

  <joint name="revo2_left_hand_left_thumb_proximal_joint" type="revolute">
    <parent link="revo2_left_hand_left_thumb_metacarpal_link" />
    <child link="revo2_left_hand_left_thumb_proximal_link" />
    <origin xyz="0 -0.014227 0" rpy="-0.17488 0.23736 -0.16787" />
    <axis xyz="-1 0 0" />
    <limit lower="0" upper="1.03" effort="1.1" velocity="2.5303" />
  </joint>

  <joint name="revo2_left_hand_left_thumb_distal_joint" type="revolute">
    <parent link="revo2_left_hand_left_thumb_proximal_link" />
    <child link="revo2_left_hand_left_thumb_distal_link" />
    <origin xyz="0 -0.052 0" rpy="0 0 0" />
    <axis xyz="-1 0 0" />
    <limit lower="0" upper="1.03" effort="1.1" velocity="2.5303" />
    <mimic joint="revo2_left_hand_left_thumb_proximal_joint" multiplier="1" offset="0" />
  </joint>

  <joint name="revo2_left_hand_left_thumb_tip_joint" type="fixed">
    <parent link="revo2_left_hand_left_thumb_distal_link" />
    <child link="revo2_left_hand_left_thumb_tip_link" />
    <origin xyz="0 -0.026529 -0.0017734" rpy="0.06675 0 0" />
  </joint>

  <joint name="revo2_left_hand_left_thumb_touch_joint" type="fixed">
    <parent link="revo2_left_hand_left_thumb_distal_link" />
    <child link="revo2_left_hand_left_thumb_touch_link" />
    <origin xyz="0 -0.013836 0.0076686" rpy="0.17488 0 0" />
  </joint>

  <joint name="revo2_left_hand_left_index_proximal_joint" type="revolute">
    <parent link="revo2_left_hand" />
    <child link="revo2_left_hand_left_index_proximal_link" />
    <origin xyz="-0.0021349 -0.029578 0.080876" rpy="0.11819 0.14743 0.17422" />
    <axis xyz="0 1 0" />
    <limit lower="0" upper="1.41" effort="2" velocity="2.2685" />
  </joint>

  <joint name="revo2_left_hand_left_index_distal_joint" type="revolute">
    <parent link="revo2_left_hand_left_index_proximal_link" />
    <child link="revo2_left_hand_left_index_distal_link" />
    <origin xyz="0 0 0.032" rpy="0 0 0" />
    <axis xyz="0 1 0" />
    <limit lower="0" upper="1.63" effort="2" velocity="2.2685" />
    <mimic joint="revo2_left_hand_left_index_proximal_joint" multiplier="1.155" offset="0" />
  </joint>

  <joint name="revo2_left_hand_left_index_tip_joint" type="fixed">
    <parent link="revo2_left_hand_left_index_distal_link" />
    <child link="revo2_left_hand_left_index_tip_link" />
    <origin xyz="0.011097 0 0.035739" rpy="0 0.48723 0" />
  </joint>

  <joint name="revo2_left_hand_left_index_touch_joint" type="fixed">
    <parent link="revo2_left_hand_left_index_distal_link" />
    <child link="revo2_left_hand_left_index_touch_link" />
    <origin xyz="0.014497 0 0.023303" rpy="0 0.4756 0" />
  </joint>

  <joint name="revo2_left_hand_left_middle_proximal_joint" type="revolute">
    <parent link="revo2_left_hand" />
    <child link="revo2_left_hand_left_middle_proximal_link" />
    <origin xyz="-0.0045935 -0.010061 0.084993" rpy="0.039468 0.1483 0.057975" />
    <axis xyz="0 1 0" />
    <limit lower="0" upper="1.41" effort="2" velocity="2.2685" />
  </joint>

  <joint name="revo2_left_hand_left_middle_distal_joint" type="revolute">
    <parent link="revo2_left_hand_left_middle_proximal_link" />
    <child link="revo2_left_hand_left_middle_distal_link" />
    <origin xyz="0 0 0.037" rpy="0 0.12654 0" />
    <axis xyz="0 1 0" />
    <limit lower="0" upper="1.63" effort="2" velocity="2.2685" />
    <mimic joint="revo2_left_hand_left_middle_proximal_joint" multiplier="1.155" offset="0" />
  </joint>

  <joint name="revo2_left_hand_left_middle_tip_joint" type="fixed">
    <parent link="revo2_left_hand_left_middle_distal_link" />
    <child link="revo2_left_hand_left_middle_tip_link" />
    <origin xyz="0.0073534 0 0.041703" rpy="0 0.34907 0" />
  </joint>

  <joint name="revo2_left_hand_left_middle_touch_joint" type="fixed">
    <parent link="revo2_left_hand_left_middle_distal_link" />
    <child link="revo2_left_hand_left_middle_touch_link" />
    <origin xyz="0.012493 0 0.028393" rpy="0 0.34907 0" />
  </joint>

  <joint name="revo2_left_hand_left_ring_proximal_joint" type="revolute">
    <parent link="revo2_left_hand" />
    <child link="revo2_left_hand_left_ring_proximal_link" />
    <origin xyz="-0.0046877 0.010026 0.083982" rpy="-0.039462 0.14721 -0.057932" />
    <axis xyz="0 1 0" />
    <limit lower="0" upper="1.41" effort="2" velocity="2.2685" />
  </joint>

  <joint name="revo2_left_hand_left_ring_distal_joint" type="revolute">
    <parent link="revo2_left_hand_left_ring_proximal_link" />
    <child link="revo2_left_hand_left_ring_distal_link" />
    <origin xyz="0 0 0.035" rpy="0 0.12654 0" />
    <axis xyz="0 1 0" />
    <limit lower="0" upper="1.63" effort="2" velocity="2.2685" />
    <mimic joint="revo2_left_hand_left_ring_proximal_joint" multiplier="1.155" offset="0" />
  </joint>

  <joint name="revo2_left_hand_left_ring_tip_joint" type="fixed">
    <parent link="revo2_left_hand_left_ring_distal_link" />
    <child link="revo2_left_hand_left_ring_tip_link" />
    <origin xyz="0.0071824 0 0.040734" rpy="0 0.34907 0" />
  </joint>

  <joint name="revo2_left_hand_left_ring_touch_joint" type="fixed">
    <parent link="revo2_left_hand_left_ring_distal_link" />
    <child link="revo2_left_hand_left_ring_touch_link" />
    <origin xyz="0.012028 0 0.027796" rpy="0 0.34907 0" />
  </joint>

  <joint name="revo2_left_hand_left_pinky_proximal_joint" type="revolute">
    <parent link="revo2_left_hand" />
    <child link="revo2_left_hand_left_pinky_proximal_link" />
    <origin xyz="-0.0023733 0.029356 0.078694" rpy="-0.11815 0.14491 -0.17392" />
    <axis xyz="0 1 0" />
    <limit lower="0" upper="1.41" effort="2" velocity="2.2685" />
  </joint>

  <joint name="revo2_left_hand_left_pinky_distal_joint" type="revolute">
    <parent link="revo2_left_hand_left_pinky_proximal_link" />
    <child link="revo2_left_hand_left_pinky_distal_link" />
    <origin xyz="0 0 0.029" rpy="0 0 0" />
    <axis xyz="0 1 0" />
    <limit lower="0" upper="1.63" effort="2" velocity="2.2685" />
    <mimic joint="revo2_left_hand_left_pinky_proximal_joint" multiplier="1.155" offset="0" />
  </joint>

  <joint name="revo2_left_hand_left_pinky_tip_joint" type="fixed">
    <parent link="revo2_left_hand_left_pinky_distal_link" />
    <child link="revo2_left_hand_left_pinky_tip_link" />
    <origin xyz="0.010221 0 0.032918" rpy="0 0.4756 0" />
  </joint>

  <joint name="revo2_left_hand_left_pinky_touch_joint" type="fixed">
    <parent link="revo2_left_hand_left_pinky_distal_link" />
    <child link="revo2_left_hand_left_pinky_touch_link" />
    <origin xyz="0.01401 0 0.021124" rpy="0 0.4756 0" />
  </joint>

  <joint name="revo2_right_hand_right_thumb_metacarpal_joint" type="revolute">
    <parent link="revo2_right_hand" />
    <child link="revo2_right_hand_right_thumb_metacarpal_link" />
    <origin xyz="0.005619 0.019867 0.027825" rpy="0 0 -0.16787" />
    <axis xyz="0 0 -1" />
    <limit lower="0" upper="1.57" effort="0.5" velocity="2.6175" />
  </joint>

  <joint name="revo2_right_hand_right_thumb_proximal_joint" type="revolute">
    <parent link="revo2_right_hand_right_thumb_metacarpal_link" />
    <child link="revo2_right_hand_right_thumb_proximal_link" />
    <origin xyz="0 0.014227 0" rpy="0.17488 0.23736 0.16787" />
    <axis xyz="1 0 0" />
    <limit lower="0" upper="1.03" effort="1.1" velocity="2.5303" />
  </joint>

  <joint name="revo2_right_hand_right_thumb_distal_joint" type="revolute">
    <parent link="revo2_right_hand_right_thumb_proximal_link" />
    <child link="revo2_right_hand_right_thumb_distal_link" />
    <origin xyz="0 0.052 0" rpy="0 0 0" />
    <axis xyz="1 0 0" />
    <limit lower="0" upper="1.03" effort="1.1" velocity="2.5303" />
    <mimic joint="revo2_right_hand_right_thumb_proximal_joint" multiplier="1" offset="0" />
  </joint>

  <joint name="revo2_right_hand_right_thumb_tip_joint" type="fixed">
    <parent link="revo2_right_hand_right_thumb_distal_link" />
    <child link="revo2_right_hand_right_thumb_tip_link" />
    <origin xyz="0 0.0265288 -0.0017734" rpy="-0.0667505 0 0" />
  </joint>

  <joint name="revo2_right_hand_right_thumb_touch_joint" type="fixed">
    <parent link="revo2_right_hand_right_thumb_distal_link" />
    <child link="revo2_right_hand_right_thumb_touch_link" />
    <origin xyz="0 0.0137928 0.0076766" rpy="-0.0667505 0 0" />
  </joint>

  <joint name="revo2_right_hand_right_index_proximal_joint" type="revolute">
    <parent link="revo2_right_hand" />
    <child link="revo2_right_hand_right_index_proximal_link" />
    <origin xyz="-0.0021181 0.029568 0.080876" rpy="-0.11819 0.14743 -0.17422" />
    <axis xyz="0 1 0" />
    <limit lower="0" upper="1.41" effort="2" velocity="2.2685" />
  </joint>

  <joint name="revo2_right_hand_right_index_distal_joint" type="revolute">
    <parent link="revo2_right_hand_right_index_proximal_link" />
    <child link="revo2_right_hand_right_index_distal_link" />
    <origin xyz="0 0 0.032" rpy="0 0 0" />
    <axis xyz="0 1 0" />
    <limit lower="0" upper="1.63" effort="2" velocity="2.2685" />
    <mimic joint="revo2_right_hand_right_index_proximal_joint" multiplier="1.155" offset="0" />
  </joint>

  <joint name="revo2_right_hand_right_index_tip_joint" type="fixed">
    <parent link="revo2_right_hand_right_index_distal_link" />
    <child link="revo2_right_hand_right_index_tip_link" />
    <origin xyz="0.011097 0 0.035739" rpy="0 0.4756 0" />
  </joint>

  <joint name="revo2_right_hand_right_index_touch_joint" type="fixed">
    <parent link="revo2_right_hand_right_index_distal_link" />
    <child link="revo2_right_hand_right_index_touch_link" />
    <origin xyz="0.014497 0 0.023303" rpy="1.7145 0.4756 0" />
  </joint>

  <joint name="revo2_right_hand_right_middle_proximal_joint" type="revolute">
    <parent link="revo2_right_hand" />
    <child link="revo2_right_hand_right_middle_proximal_link" />
    <origin xyz="-0.0045767 0.010051 0.084993" rpy="-0.039468 0.1483 -0.057975" />
    <axis xyz="0 1 0" />
    <limit lower="0" upper="1.41" effort="2" velocity="2.2685" />
  </joint>

  <joint name="revo2_right_hand_right_middle_distal_joint" type="revolute">
    <parent link="revo2_right_hand_right_middle_proximal_link" />
    <child link="revo2_right_hand_right_middle_distal_link" />
    <origin xyz="0 0 0.037" rpy="0 0 0" />
    <axis xyz="0 1 0" />
    <limit lower="0" upper="1.63" effort="2" velocity="2.2685" />
    <mimic joint="revo2_right_hand_right_middle_proximal_joint" multiplier="1.155" offset="0" />
  </joint>

  <joint name="revo2_right_hand_right_middle_tip_joint" type="fixed">
    <parent link="revo2_right_hand_right_middle_distal_link" />
    <child link="revo2_right_hand_right_middle_tip_link" />
    <origin xyz="0.012558 0 0.040442" rpy="0 0.4756 0" />
  </joint>

  <joint name="revo2_right_hand_right_middle_touch_joint" type="fixed">
    <parent link="revo2_right_hand_right_middle_distal_link" />
    <child link="revo2_right_hand_right_middle_touch_link" />
    <origin xyz="0.0159759 0 0.0265894" rpy="0 0.4756022 0" />
  </joint>

  <joint name="revo2_right_hand_right_ring_proximal_joint" type="revolute">
    <parent link="revo2_right_hand" />
    <child link="revo2_right_hand_right_ring_proximal_link" />
    <origin xyz="-0.0046709 -0.010037 0.083982" rpy="0.039462 0.14721 0.057932" />
    <axis xyz="0 1 0" />
    <limit lower="0" upper="1.41" effort="2" velocity="2.2685" />
  </joint>

  <joint name="revo2_right_hand_right_ring_distal_joint" type="revolute">
    <parent link="revo2_right_hand_right_ring_proximal_link" />
    <child link="revo2_right_hand_right_ring_distal_link" />
    <origin xyz="0 0 0.035" rpy="0 0 0" />
    <axis xyz="0 1 0" />
    <limit lower="0" upper="1.63" effort="2" velocity="2.2685" />
    <mimic joint="revo2_right_hand_right_ring_proximal_joint" multiplier="1.155" offset="0" />
  </joint>

  <joint name="revo2_right_hand_right_ring_tip_joint" type="fixed">
    <parent link="revo2_right_hand_right_ring_distal_link" />
    <child link="revo2_right_hand_right_ring_tip_link" />
    <origin xyz="0.012266 0 0.039501" rpy="0 0.4756 0" />
  </joint>

  <joint name="revo2_right_hand_right_ring_touch_joint" type="fixed">
    <parent link="revo2_right_hand_right_ring_distal_link" />
    <child link="revo2_right_hand_right_ring_touch_link" />
    <origin xyz="0.0154392 0 0.0260561" rpy="0 0.4756022 0" />
  </joint>

  <joint name="revo2_right_hand_right_pinky_proximal_joint" type="revolute">
    <parent link="revo2_right_hand" />
    <child link="revo2_right_hand_right_pinky_proximal_link" />
    <origin xyz="-0.0023566 -0.029366 0.078694" rpy="0.11815 0.14491 0.17392" />
    <axis xyz="0 1 0" />
    <limit lower="0" upper="1.41" effort="2" velocity="2.2685" />
  </joint>

  <joint name="revo2_right_hand_right_pinky_distal_joint" type="revolute">
    <parent link="revo2_right_hand_right_pinky_proximal_link" />
    <child link="revo2_right_hand_right_pinky_distal_link" />
    <origin xyz="0 0 0.029" rpy="0 0 0" />
    <axis xyz="0 1 0" />
    <limit lower="0" upper="1.63" effort="2" velocity="2.2685" />
    <mimic joint="revo2_right_hand_right_pinky_proximal_joint" multiplier="1.155" offset="0" />
  </joint>

  <joint name="revo2_right_hand_right_pinky_tip_joint" type="fixed">
    <parent link="revo2_right_hand_right_pinky_distal_link" />
    <child link="revo2_right_hand_right_pinky_tip_link" />
    <origin xyz="0.010221 0 0.032918" rpy="0 0.4756 0" />
  </joint>

  <joint name="revo2_right_hand_right_pinky_touch_joint" type="fixed">
    <parent link="revo2_right_hand_right_pinky_distal_link" />
    <child link="revo2_right_hand_right_pinky_touch_link" />
    <origin xyz="0.01401 0 0.021124" rpy="0 0.4756 0" />
  </joint>

  <joint name="Z2_0_Lite_description_0429_1-revo2_right_hand" type="fixed">
    <parent link="Z2_0_Lite_description_0429_1_R_wrist_yaw_Link" />
    <child link="revo2_right_hand" />
    <origin xyz="0.045 0 0" rpy="1.5707963 0 1.5707963" quat_xyzw="0.5 0.5 0.5 0.5" />
  </joint>

  <joint name="Z2_0_Lite_description_0429_1-revo2_left_hand" type="fixed">
    <parent link="Z2_0_Lite_description_0429_1_L_wrist_yaw_Link" />
    <child link="revo2_left_hand" />
    <origin xyz="0.045 0 0" rpy="-1.5707963 0 -1.5707963" quat_xyzw="-0.5 0.5 -0.5 0.5" />
  </joint>

</robot>